Workbook

Sheet 01, JAN 2026
A3: KAS BANK MANDIRI
A4: TAHUN 2026
A5: KOPKAR BANDAR BANTEN | D5: BULAN : JANUARI 2026
A7: NO | B7: TGL | C7: KODE | D7: URAIAN | E7: KREDIT | F7: DEBET | G7: SALDO
C8: REK.
D9: SALDO PINDAHAN | E9: 0 | F9: 0 | G9: =+'[1]DESEMBER 2025'!$G$286 -> 4.619115e+08
B10: 03-01-2026 | D10: Pinjaman Uang Koperasi dan Pelunasan an Nahdi | E10: =+F10-2490000 -> 510000 | F10: 3000000 | G10: =+G9+E10-F10 -> 4.594215e+08
B11: 03-01-2026 | D11: Biaya Honor Pengurus Periode November an Rajab Agus | F11: 3000000 | G11: =+G10+E11-F11 -> 4.564215e+08
B12: 03-01-2026 | D12: Pinjaman Barang Koperasi an Atik Salasih | E12: =+F12-3425000 -> 1575000 | F12: 5000000 | G12: =+G11+E12-F12 -> 4.529965e+08
B13: 03-01-2026 | D13: Pengambilan Simpanan Sukarela an Fahmi Rapsanjani | F13: 4000000 | G13: =+G12+E13-F13 -> 4.489965e+08
B14: 03-01-2026 | D14: Biaya Gaji TKHL Bulan Desember 2025 an Angga Putra Permana | F14: 5616182 | G14: =+G13+E14-F14 -> 4.4338032e+08
B15: 03-01-2026 | D15: Biaya Gaji TKHL Bulan Desember 2025 an Galiztan EQ Gunanditya | F15: 5360901 | G15: =+G14+E15-F15 -> 4.3801942e+08
B16: 03-01-2026 | D16: Utip BPJS Kesehatan TKHL PTP Banten | E16: 55384 | G16: =+G15+E16-F16 -> 4.380748e+08
B17: 03-01-2026 | D17: Utip BPJS Ketenagakerjaan TKHL PTP Banten | E17: 523064 | G17: =+G16+E17-F17 -> 4.3859786e+08
B18: 03-01-2026 | D18: Pengambilan Simpanan Pokok dan Wajib an Soleman Tkk | F18: 8100000 | G18: =+G17+E18-F18 -> 4.3049786e+08
B19: 03-01-2026 | D19: Pengambilan Simpanan Pokok dan Wajib an Mu'min Tkk | F19: 11040000 | G19: =+G18+E19-F19 -> 4.1945786e+08
B20: 03-01-2026 | D20: Biaya Administrasi | F20: 2500 | G20: =+G19+E20-F20 -> 4.1945536e+08
B21: 04-01-2026 | D21: Biaya Exfood Pembelian Duren Keuangan & SDM an Lukman Salamudin | F21: 2750000 | G21: =+G20+E21-F21 -> 4.1670536e+08
B22: 04-04-2026 | D22: Biaya Administrasi | F22: 2500 | G22: =+G21+E22-F22 -> 4.1670286e+08
B23: 04-01-2026 | D23: Biaya Pembayaran Paket Bak an Den Cahyadi | F23: 10322000 | G23: =+G22+E23-F23 -> 4.0638086e+08
B24: 04-01-2026 | D24: Biaya Dana Bantuan TJSL Pelindo an Lukman Salamudin | F24: 60000000 | G24: =+G23+E24-F24 -> 3.4638086e+08
B25: 04-01-2026 | D25: Biaya Administrasi | F25: 2500 | G25: =+G24+E25-F25 -> 3.4637836e+08
B26: 05-01-2026 | D26: Pendapatan Pelunasan Pinjaman Management KepBis an M Agus Alfian | E26: 15000000 | G26: =+G25+E26-F26 -> 3.6137836e+08
B27: 05-01-2026 | D27: Simpanan Wajib an Evalin Bernadetha S | E27: 330000 | G27: =+G26+E27-F27 -> 3.6170836e+08
B28: 05-01-2026 | D28: Arisan an Evalin Bernadetha S | G28: =+G27+E28-F28 -> 3.6170836e+08
B29: 05-01-2026 | D29: Transfer BPJS Kesehatan Pegawai Koperasi | F29: 1914472 | G29: =+G28+E29-F29 -> 3.5979389e+08
B30: 05-01-2026 | D30: Pembayaran PPH 23 periode Desember 2025 | F30: 2128134 | G30: =+G29+E30-F30 -> 3.5766576e+08
B31: 05-01-2026 | D31: Pembayaran SPT masa PPH 25 Badan periode Desember 2025 | F31: 5278654 | G31: =+G30+E31-F31 -> 3.523871e+08
B32: 05-01-2026 | D32: Transfer BPJS Kesehatan Karyawan Cs dan Tkhl PTP | F32: 9845856 | G32: =+G31+E32-F32 -> 3.4254125e+08
B33: 05-01-2026 | D33: Pembayaran SPT PPN periode Desember 2025 | F33: 60951595 | G33: =+G32+E33-F33 -> 2.8158965e+08
B34: 05-01-2026 | D34: Pinjaman Barang dan Pelunasan Potongan Gaji 13 an Haryono | E34: =+F34-3109000 -> 11891000 | F34: 15000000 | G34: =+G33+E34-F34 -> 2.7848065e+08
B35: 05-01-2026 | D35: Biaya Dana Bantuan TJSL Pelindo ke 2 an Lukman Salamudin | F35: 30000000 | G35: =+G34+E35-F35 -> 2.4848065e+08
B36: 05-01-2026 | D36: Biaya Administrasi | F36: 2500 | G36: =+G35+E36-F36 -> 2.4847815e+08 | J36: =+F30+F31-E32-E33 -> 7406788
B37: 05-01-2026 | D37: Transfer BPJS Ketenagakerjaan Karyawan Cleaning Service | F37: 16142158 | G37: =+G36+E37-F37 -> 2.3233599e+08
B38: 05-01-2026 | D38: Transfer BPJS Ketenagakerjaan Karyawan Koperasi | F38: 3353804 | G38: =+G37+E38-F38 -> 2.2898219e+08
B39: 05-01-2026 | D39: Biaya Pembelian Kebutuhan Rumah Dinas Gm an Lia Meliawati | F39: 7540000 | G39: =+G38+E39-F39 -> 2.2144219e+08
B40: 05-01-2026 | D40: Pengambilan Simpanan Pokok dan Wajib an M Maulana Fathi | F40: 2700000 | G40: =+G39+E40-F40 -> 2.1874219e+08
B41: 05-01-2026 | D41: Pengambilan Simpanan Pokok dan Wajib an Safroni | F41: 8200000 | G41: =+G40+E41-F41 -> 2.1054219e+08
B42: 05-01-2026 | D42: Pinjaman Uang Koperasi an Haryono | F42: 10000000 | G42: =+G41+E42-F42 -> 2.0054219e+08
B43: 05-01-2026 | D43: Utip Arisan Karyawan PTP Banten an Asep Kosasih | F43: 2875000 | G43: =+G42+E43-F43 -> 1.9766719e+08
...

Sheet 02, FEB 2026
A3: KAS BANK MANDIRI
A4: TAHUN 2026
A5: KOPKAR BANDAR BANTEN | D5: BULAN : FEBRUARI 2026
A7: NO | B7: TGL | C7: KODE | D7: URAIAN | E7: KREDIT | F7: DEBET | G7: SALDO
C8: REK.
D9: SALDO PINDAHAN | E9: 0 | F9: 0 | G9: =+'01, JAN 2026'!G264 -> 1.0616681e+08
B10: 02 Feb 2026 | D10: Pendapatan Sewa Tenan Kantin Jus periode Februari an Lukman Salamudin | E10: 1000000 | G10: =+G9+E10-F10 -> 1.0716681e+08
B11: 02 Feb 2026 | D11: Biaya Service Kendaraan Roda 2 PTP an Ahmad Kurniawan | F11: 2530000 | G11: =+G10+E11-F11 -> 1.0463681e+08
B12: 02 Feb 2026 | D12: Pendapatan Pph 23 Padi Umkm | E12: 42274 | G12: =+G11+E12-F12 -> 1.0467908e+08
B13: 03 Feb 2026 | D13: Biaya Kebutuhan Rumah Tangga dan Umum PTP an Misar Ardiyanto | F13: 8890000 | G13: =+G12+E13-F13 -> 95789085
B14: 03 Feb 2026 | D14: Pembelian Lee Mineral Kantin an Humasiyah | F14: 2414000 | G14: =+G13+E14-F14 -> 93375085
B15: 03 Feb 2026 | D15: Pelunasan Pinjaman BS Cuti an Muadi | E15: 3500000 | G15: =+G14+E15-F15 -> 96875085
B16: 04 Feb 2026 | D16: Biaya Gaji TKHL Bulan Januari 2026 an Angga Putra Permana | F16: 5861213 | G16: =+G15+E16-F16 -> 91013872
B17: 04 Feb 2026 | D17: Biaya Gaji TKHL Bulan Januari 2026 an Galiztan EQ Gunanditya | F17: 5861213 | G17: =+G16+E17-F17 -> 85152659
B18: 04 Feb 2026 | D18: Utip BPJS Kesehatan TKHL PTP Banten | E18: 546992 | G18: =+G17+E18-F18 -> 85699651
B19: 4 Feb 2026 | D19: Utip BPJS Ketenagakerjaan TKHL PTP Banten | E19: 60552 | G19: =+G18+E19-F19 -> 85760203
B20: 05 Feb 2026 | D20: Pendapatan Pekerjaan Rekapitulasi Lembur TKHL periode Desember 2025 | E20: 9592664 | G20: =+G19+E20-F20 -> 95352867
B21: 05 Feb 2026 | D21: Pendapatan Pekerjaan Kebersihan Halaman Gedung Kantor dan Workshop PTP periode Des 2025 | E21: 44907018 | G21: =+G20+E21-F21 -> 1.4025988e+08
B22: 05 Feb 2026 | D22: Pendapatan Pekerjaan Kebersihan Toilet Container periode Desember 2025 | E22: 4894117 | G22: =+G21+E22-F22 -> 1.45154e+08
B23: 05 Feb 2026 | D23: Pendapatan Pekerjaan Kebersihan Zonasi Lini 1 Periode Desember 2025 | E23: 155238259 | G23: =+G22+E23-F23 -> 3.0039226e+08
B24: 05 Feb 2026 | D24: Pendapatan Pekerjaan Kebersihan Zonasi Lini 2 periode Desember 2025 | E24: 49775685 | G24: =+G23+E24-F24 -> 3.5016795e+08
B25: 05 Feb 2026 | D25: Pembayaran Potongan PDS Periode Februari 2026 | G25: =+G24+E25-F25 -> 3.5016795e+08
B26: 05 Feb 2026 | D26: Simpanan Wajib Tno Cabang dan PTP Gaji Januari 2026 | E26: 8100000 | G26: =+G25+E26-F26 -> 3.5826795e+08
B27: 05 Feb 2026 | D27: Simpanan Sukarela Tno Cabang dan PTP Gaji Januari 2026 | E27: 4300000 | G27: =+G26+E27-F27 -> 3.6256795e+08
B28: 05 Feb 2026 | D28: Pendapatan Potongan Piutang Uang Tno Cabang dan Ptp Gaji Januari 2026 | E28: 18565000 | G28: =+G27+E28-F28 -> 3.8113295e+08
B29: 05 Feb 2026 | D29: Pendapatan Potongan Piutang Barang Tno Cabang dan PTP Gaji Januari 2026 | E29: 2093750 | G29: =+G28+E29-F29 -> 3.832267e+08
B30: 05 Feb 2026 | D30: Pendapatan Potongan Kantin Tno Cabang Gaji Januari 2026 | E30: 3056000 | G30: =+G29+E30-F30 -> 3.862827e+08
B31: 05 Feb 2026 | D31: Pendapatan Potongan Kantin Tno PTP Gaji Januari 2026 | E31: 5018000 | G31: =+G30+E31-F31 -> 3.913007e+08
B32: 05 Feb 2026 | D32: Utip Arisan PIP Banten & PTP | E32: 920000 | G32: =+G31+E32-F32 -> 3.922207e+08
B33: 05 Feb 2026 | D33: Pendapatan Potongan BJB Tno Cabang | E33: =2875000+3450000 -> 6325000 | G33: =+G32+E33-F33 -> 3.985457e+08
B34: 05 Feb 2026 | D34: Pendapatan Potongan BJB Tno PTP Banten | E34: 26450000 | G34: =+G33+E34-F34 -> 4.249957e+08
B35: 05 Feb 2026 | D35: Simpanan Wajib Security Cabang dan PTP | E35: 2350000 | G35: =+G34+E35-F35 -> 4.273457e+08
B36: 05 Feb 2026 | D36: Simpanan Sukarela Security Cabang dan PTP | E36: 3500000 | G36: =+G35+E36-F36 -> 4.308457e+08
B37: 05 Feb 2026 | D37: Pendapatan Potongan Piutang Uang dan Security Januari 2026 | E37: =1816667+560000 -> 2376667 | G37: =+G36+E37-F37 -> 4.3322236e+08
B38: 05 Feb 2026 | D38: Pendapatan Potongan Kantin Security Cabang Banten | E38: 1931000 | G38: =+G37+E38-F38 -> 4.3515336e+08
B39: 05 Feb 2026 | D39: Pendapatan Potongan Kantin Security PTP Banten | E39: 3355000 | G39: =+G38+E39-F39 -> 4.3850836e+08
B40: 05 Feb 2026 | D40: Utip Piutang Yusuf Irsyad ke Dikdik Sofyan ke 5 & 6 | E40: 1840000 | G40: =+G39+E40-F40 -> 4.4034836e+08
B41: 05 Feb 2026 | D41: Pendapatan Pekerjaan Cleaning Service Cabang periode November 2025 | E41: 175975333 | G41: =+G40+E41-F41 -> 6.163237e+08
B42: 05 Feb 2026 | D42: Biaya Pembelian TV Samsung an Elektronic City Indonesia | F42: 14399000 | G42: =+G41+E42-F42 -> 6.019247e+08
B43: 05 Feb 2026 | D43: Transfer BPJS Kesehatan Pegawai Koperasi | F43: 1914472 | G43: =+G42+E43-F43 -> 6.0001022e+08
...

Sheet 03, MAR 26
A3: KAS BANK MANDIRI
A4: TAHUN 2026
A5: KOPKAR BANDAR BANTEN | D5: BULAN : MARET 2026
A7: NO | B7: TGL | C7: KODE | D7: URAIAN | E7: KREDIT | F7: DEBET | G7: SALDO
C8: REK.
D9: SALDO PINDAHAN | E9: 0 | F9: 0 | G9: =+'02, FEB 2026'!G199 -> 4.7066636e+08
B10: 02 Mar 2026 | D10: Pembayaran BPJS Ketenagakerjaan TKHL PTP Banten | F10: 60552 | G10: =+G9+E10-F10 -> 4.7060581e+08
B11: 02 Mar 2026 | D11: Transfer BPJS Kesehatan Pegawai Koperasi | F11: 1915954 | G11: =+G10+E11-F11 -> 4.6868986e+08
B12: 02 Mar 2026 | D12: Transfer BPJS Ketenagakerjaan Karyawan Cleaning Service | F12: 16142158 | G12: =+G11+E12-F12 -> 4.525477e+08
B13: 02 Mar 2026 | D13: Pembayaran PPH 23 periode Februari 2026 | F13: 2182004 | G13: =+G12+E13-F13 -> 4.5036569e+08
B14: 02 Mar 2026 | D14: Transfer BPJS Ketenagakerjaan Karyawan Koperasi | F14: 3353804 | G14: =+G13+E14-F14 -> 4.4701189e+08
B15: 02 Mar 2026 | D15: Pembayaran SPT masa PPH 25 Badan periode Februari 2026 | F15: 5278654 | G15: =+G14+E15-F15 -> 4.4173324e+08
B16: 02 Mar 2026 | D16: Pembayaran SPT PPN periode Februari 2026 | F16: 27101569 | G16: =+G15+E16-F16 -> 4.1463167e+08
B17: 02 Mar 2026 | D17: Biaya Gaji TKHL Bulan Februari 2026 an Angga Putra Permana | F17: 5060260 | G17: =+G16+E17-F17 -> 4.0957141e+08
B18: 02 Mar 2026 | D18: Biaya Gaji TKHL Bulan Februari 2026 an Galiztan EQ Gunanditya | F18: 5060260 | G18: =+G17+E18-F18 -> 4.0451115e+08
B19: 02 Mar 2026 | D19: Utip BPJS Kesehatan TKHL PTP Banten | E19: 549956 | G19: =+G18+E19-F19 -> 4.050611e+08
B20: 02 Mar 2026 | D20: Utip BPJS Ketenagakerjaan TKHL PTP Banten | E20: 60552 | G20: =+G19+E20-F20 -> 4.0512165e+08
B21: 02 Mar 2026 | D21: Biaya Transport an Tuti Suimroh | F21: 500000 | G21: =+G20+E21-F21 -> 4.0462165e+08
B22: 02 Mar 2026 | D22: Transfer Angsuran BJB Anggota Koperasi | F22: 63765278 | G22: =+G21+E22-F22 -> 3.4085638e+08
B23: 02 Mar 2026 | D23: Biaya Administrasi | F23: 2500 | G23: =+G22+E23-F23 -> 3.4085388e+08
B24: 02 Mar 2026 | D24: Pembayaran Honor Pengurus periode Januari s/d Maret 2026 an Rajab Agus | F24: 9000000 | G24: =+G23+E24-F24 -> 3.3185388e+08
B25: 02 Mar 2026 | D25: Biaya Administrasi | F25: 2500 | G25: =+G24+E25-F25 -> 3.3185138e+08
B26: 02 Mar 2026 | D26: Pelunasan dan Pinjaman Uang Koperasi an M Agus Alfian | E26: 1220000 | F26: 5000000 | G26: =+G25+E26-F26 -> 3.2807138e+08
B27: 02 Mar 2026 | D27: DP ke 2 Pekerjaan Las Tiang Umbul-umbul an Ahmad Hobis | F27: 2500000 | G27: =+G26+E27-F27 -> 3.2557138e+08
B28: 02 Mar 2026 | D28: Biaya Administrasi | F28: 2500 | G28: =+G27+E28-F28 -> 3.2556888e+08
B29: 02 Mar 2026 | D29: Pengambilan Simpanan Sukarela an Taufik Hidayat | F29: 3000000 | G29: =+G28+E29-F29 -> 3.2256888e+08
B30: 02 Mar 2026 | D30: Utip Transfer Piutang Yusuf Irsyad Ke 7 & 8 an Dikdik Sofyan | F30: 1840000 | G30: =+G29+E30-F30 -> 3.2072888e+08
B31: 02 Mar 2026 | D31: Pinjaman Uang Koperasi an Melyawati | F31: 10000000 | G31: =+G30+E31-F31 -> 3.1072888e+08
B32: 02 Mar 2026 | D32: Pengambilan Simpanan Wajib dan Pelunasan Piutang Barang an Atik Salasih | E32: 2000000 | F32: 10000000 | G32: =+G31+E32-F32 -> 3.0272888e+08 | H32: 302728876
B33: 02 Mar 2026 | D33: Utip Transfer Arisan Pengurus Cabang Banten an Ari Mulyasih | F33: 2000000 | G33: =+G32+E33-F33 -> 3.0072888e+08
B34: 02 Mar 2026 | D34: Pengambilan Simpanan Sukarela an Anis Rahmatullah | F34: 900000 | G34: =+G33+E34-F34 -> 2.9982888e+08
B35: 02 Mar 2026 | D35: Utip Transfer Arisan Anggota PTP an Asep Kosasih | F35: 2645000 | G35: =+G34+E35-F35 -> 2.9718388e+08
B36: 02 Mar 2026 | D36: Pengembalian Kelebihan Transfer Pinjaman an Purwaji | F36: 2575000 | G36: =+G35+E36-F36 -> 2.9460888e+08
B37: 02 Mar 2026 | D37: Pembayaran Honor Pengurus periode Januari s/d Maret 2026 an Jimmy Greei Ganap | F37: 3000000 | G37: =+G36+E37-F37 -> 2.9160888e+08
B38: 02 Mar 2026 | D38: Biaya Rumah Tangga PTP Periode Maret an Misar Ardiyanto | F38: 7615000 | G38: =+G37+E38-F38 -> 2.8399388e+08
B39: 02 Mar 2026 | D39: Pendapatan Angkutan Lebaran an Christiawan | E39: 10000000 | G39: =+G38+E39-F39 -> 2.9399388e+08
B40: 03 Maret 2026 | D40: Pendapatan Simpanan Wajib dan Sukarela periode Juli sd Des 25 dan Jan sd Des 26 an M Fajar | E40: 1800000 | G40: =+G39+E40-F40 -> 2.9579388e+08
B41: 03 Maret 2026 | D41: Pendapatan Simpanan Wajib an Hayati Nufus | E41: 200000 | G41: =+G40+E41-F41 -> 2.9599388e+08
B42: 03 Maret 2026 | D42: Pendapatan Simpanan wajib an Oman Rahayu | E42: 100000 | G42: =+G41+E42-F42 -> 2.9609388e+08
B43: 03 Maret 2026 | D43: Pendapatan Pph 23 Padi UMKM | E43: 53870 | G43: =+G42+E43-F43 -> 2.9614775e+08
...

Sheet 04, APRIL 26
A3: KAS BANK MANDIRI
A4: TAHUN 2026
A5: KOPKAR BANDAR BANTEN | D5: BULAN : APRIL 2026
A7: NO | B7: TGL | C7: KODE | D7: URAIAN | E7: KREDIT | F7: DEBET | G7: SALDO
C8: REK.
D9: SALDO PINDAHAN | E9: 0 | F9: 0 | G9: =+'03, MAR 26'!G291 -> 17425269
B10: 02 April 2026 | D10: Pembayaran Potongan Koperasi PDS Periode April 2026 | G10: =+G9+E10-F10 -> 17425269
B11: 02 April 2026 | D11: Simpanan Wajib Tno Cabang dan PTP Gaji Maret 2026 | E11: 8050000 | G11: =+G10+E11-F11 -> 25475269
B12: 02 April 2026 | D12: Simpanan Sukarela Tno Cabang dan PTP Gaji Maret 2026 | E12: 4650000 | G12: =+G11+E12-F12 -> 30125269
B13: 02 April 2026 | D13: Pendapatan Potongan Piutang Uang Tno Cabang dan Ptp Gaji MAret 2026 | E13: 16250000 | G13: =+G12+E13-F13 -> 46375269
B14: 02 April 2026 | D14: Pendapatan Jasa Uang Tno Cabang dan Tno PTP | E14: 2175000 | G14: =+G13+E14-F14 -> 48550269
B15: 02 April 2026 | D15: Pendapatan Potongan Piutang Barang Tno Cabang dan PTP Gaji Maret 2026 | E15: 1400000 | G15: =+G14+E15-F15 -> 49950269
B16: 02 April 2026 | D16: Pendapatan Jasa Barang Tno Cabang dan Tno PTP | E16: 185750 | G16: =+G15+E16-F16 -> 50136019
B17: 02 April 2026 | D17: Pendapatan Potongan Kantin Tno Cabang Gaji Maret 2026 | E17: 272000 | G17: =+G16+E17-F17 -> 50408019
B18: 02 April 2026 | D18: Pendapatan Potongan Kantin Tno PTP Gaji Maret 2026 | E18: 181000 | G18: =+G17+E18-F18 -> 50589019
B19: 02 April 2026 | D19: Utip Arisan PIP Banten & PTP | E19: 920000 | G19: =+G18+E19-F19 -> 51509019
B20: 02 April 2026 | D20: Pendapatan Potongan BJB Tno Cabang | E20: 3450000 | G20: =+G19+E20-F20 -> 54959019
B21: 02 April 2026 | D21: Simpanan Wajib Security Cabang dan PTP | E21: 2300000 | G21: =+G20+E21-F21 -> 57259019
B22: 02 April 2026 | D22: Simpanan Sukarela Security Cabang dan PTP | E22: 3400000 | G22: =+G21+E22-F22 -> 60659019
B23: 02 April 2026 | D23: Pendapatan Potongan Piutang Uang dan Security Maret 2026 | E23: =1816667+560000 -> 2376667 | G23: =+G22+E23-F23 -> 63035686
B24: 02 April 2026 | D24: Pendapatan Potongan Kantin Security Cabang Banten | E24: 0 | G24: =+G23+E24-F24 -> 63035686
B25: 02 April 2026 | D25: Pendapatan Potongan Kantin Security PTP Banten | E25: 0 | G25: =+G24+E25-F25 -> 63035686
B26: 02 April 2026 | D26: Pendapatan Pph 23 Padi UMKM | E26: 35394 | G26: =+G25+E26-F26 -> 63071080
B27: 02 April 2026 | D27: Biaya Gaji TKHL Bulan Maret 2026 an Angga Putra Permana | F27: 4526292 | G27: =+G26+E27-F27 -> 58544788
B28: 02 April 2026 | D28: Biaya Gaji TKHL Bulan Maret 2026 an Galiztan EQ Gunanditya | F28: 4526292 | G28: =+G27+E28-F28 -> 54018496
B29: 02 April 2026 | D29: Utip BPJS Kesehatan TKHL PTP Banten | E29: 549956 | G29: =+G28+E29-F29 -> 54568452
B30: 02 April 2026 | D30: Utip BPJS Ketenagakerjaan TKHL PTP Banten | E30: 60552 | G30: =+G29+E30-F30 -> 54629004
B31: 02 April 2026 | D31: Pengambilan Simpanan Wajib an Dodi Ahmad Fauzi ke 2 | F31: 1500000 | G31: =+G30+E31-F31 -> 53129004
B32: 02 April 2026 | D32: Pinjaman Uang Koperasi an Rima Suteja (5 bulan) | F32: 1000000 | G32: =+G31+E32-F32 -> 52129004
B33: 03 April 2026 | D33: Transfer BPJS Kesehatan Karyawan Cleaning Service | F33: 9899208 | G33: =+G32+E33-F33 -> 42229796
B34: 03 April 2026 | D34: Pembayaran BPJS Ketenagakerjaan TKHL PTP Banten | F34: 60552 | G34: =+G33+E34-F34 -> 42169244
B35: 03 April 2026 | D35: Pembayaran SPT masa PPH 25 Badan periode Maret 2026 | F35: 5278654 | G35: =+G34+E35-F35 -> 36890590
B36: 03 April 2026 | D36: Transfer BPJS Ketenagakerjaan Karyawan Cleaning Service | F36: 15668323 | G36: =+G35+E36-F36 -> 21222267
B37: 03 April 2026 | D37: Pembayaran SPT PPN periode Maret 2026 | F37: 16514116 | G37: =+G36+E37-F37 -> 4708151.2
B38: 03 April 2026 | D38: Transfer BPJS Ketenagakerjaan Karyawan Koperasi | F38: 3353804 | G38: =+G37+E38-F38 -> 1354347.2
B39: 06 April 2026 | D39: Pendapatan Sewa Lahan Kantin Jus periode Maret dan April 2026 an Lukman Salamudin | E39: 1650000 | G39: =+G38+E39-F39 -> 3004347.2
B40: 06 April 2026 | D40: Pendapatan Pekerjaan Pelaksanaan Pengasapan Fogging dlm rangka Angleb 2026 | E40: 2450000 | G40: =+G39+E40-F40 -> 5454347.2
B41: 10 April 2026 | D41: Biaya Kebutuhan Galon Kantor Pelabuhan an Muadi | F41: 3477000 | G41: =+G40+E41-F41 -> 1977347.2
B42: 13 April 2026 | D42: Pendapatan Pekerjaan Pengadaan dan Pemasangan Dormakaba MDU ES 250 Pro Teknik | E42: 31274250 | G42: =+G41+E42-F42 -> 33251597
B43: 13 April 2026 | D43: Utip Transfer Arisan PTP Cabang Banten an Asep Kosasih | F43: 2645000 | G43: =+G42+E43-F43 -> 30606597
...

Sheet 05,MEI 26
A3: KAS BANK MANDIRI
A4: TAHUN 2026
A5: KOPKAR BANDAR BANTEN | D5: BULAN : MEI 2026
A7: NO | B7: TGL | C7: KODE | D7: URAIAN | E7: KREDIT | F7: DEBET | G7: SALDO
C8: REK.
D9: SALDO PINDAHAN | E9: 0 | F9: 0 | G9: =+'04, APRIL 26'!G200 -> 1.9727524e+08
B10: 01 Mei 2026 | D10: Biaya Gaji TKHL Bulan April 2026 an Angga Putra Permana | F10: 5594229 | G10: =+G9+E10-F10 -> 1.9168101e+08
D11: Biaya Gaji TKHL Bulan April 2026 an Galiztan EQ Gunanditya | F11: 5594229 | G11: =+G10+E11-F11 -> 1.8608678e+08
D12: Utip BPJS Kesehatan TKHL PTP Banten | E12: 549956 | G12: =+G11+E12-F12 -> 1.8663674e+08
D13: Utip BPJS Ketenagakerjaan TKHL PTP Banten | E13: 60552 | G13: =+G12+E13-F13 -> 1.8669729e+08
D14: Pengambilan Simpanan Wajib dan Pokok an Agus Fazri | F14: 3600000 | G14: =+G13+E14-F14 -> 1.8309729e+08
D15: Biaya Administrasi | F15: 2500 | G15: =+G14+E15-F15 -> 1.8309479e+08
D16: Biaya Kebutuhan RT Umum PTP Banten an Misar Ardiyanto | F16: 8745000 | G16: =+G15+E16-F16 -> 1.7434979e+08
D17: Utip Transfer Angsuran Bjb Anggota Koperasi | F17: 56276389 | G17: =+G16+E17-F17 -> 1.180734e+08
D18: Biaya Administrasi | F18: 2500 | G18: =+G17+E18-F18 -> 1.180709e+08
D19: Biaya Pekerjaan Pengadaan PH Air dan Labelling KepBis an Suherlina | F19: 1217986 | G19: =+G18+E19-F19 -> 1.1685292e+08
D20: Pengambilan Simpanan Wajib dan Pokok an Heri Firmansyah | F20: 874875 | G20: =+G19+E20-F20 -> 1.1597804e+08
D21: Biaya Cetak Spanduk dan Papan Simbolis Qurban Pelindo an Muadi | F21: 335000 | G21: =+G20+E21-F21 -> 1.1564304e+08
B22: 02 Mei 2026 | D22: Biaya Pekerjaan CCTV dan an Nugroho Widyo Laksono | F22: 19500000 | G22: =+G21+E22-F22 -> 96143041
B23: 04 Mei 2026 | D23: Pendapatan Sewa Lahan Kantin Jus periode Mei an Lukman Salamudin | E23: 1000000 | G23: =+G22+E23-F23 -> 97143041
B24: 05 Mei 2026 | D24: Pembayaran BPJS Ketenagakerjaan TKHL PTP Banten | E24: 0 | F24: 60552 | G24: =+G23+E24-F24 -> 97082489
D25: Pembayaran BPJS Kesehatan pegawai Koperasi | E25: 0 | F25: 1924846 | G25: =+G24+E25-F25 -> 95157643
D26: Pembayaran SPT PPH 23 Periode April 2026 | F26: 2453175 | G26: =+G25+E26-F26 -> 92704468
D27: Pembayaran SPT Masa PPH 25 Badan periode April 2026 | F27: 5315708 | G27: =+G26+E27-F27 -> 87388760
D28: Transfer BPJS Kesehatan Karyawan Cleaning Service | F28: 9899208 | G28: =+G27+E28-F28 -> 77489552
D29: Transfer BPJS Ketenagakerjaan Karyawan Cleaning Service | F29: 15194488 | G29: =+G28+E29-F29 -> 62295064
D30: Pembayaran SPT PPN Periode April 2026 | F30: 20289466 | G30: =+G29+E30-F30 -> 42005598
D31: Transfer BPJS Ketenagakerjaan Karyawan Koperasi | F31: 3353804 | G31: =+G30+E31-F31 -> 38651794
D32: Simpanan Wajib an Hayati Nufus | E32: 200000 | G32: =+G31+E32-F32 -> 38851794
D33: Simpanan Wajib an Oman Rahayu | E33: 100000 | G33: =+G32+E33-F33 -> 38951794
D34: Simpanan Wajib an Slamet Kiswountoro | E34: 100000 | G34: =+G33+E34-F34 -> 39051794
D35: Pendapatan Pekerjaan Kebersihan Zonasi Lini 1 Periode Maret 2026 | E35: 161863363 | G35: =+G34+E35-F35 -> 2.0091516e+08
D36: Pendapatan Pph 23 Padi UMKM | E36: 5041 | G36: =+G35+E36-F36 -> 2.009202e+08
D37: Pembayaran Potongan Koperasi PDS Periode Mei 2026 | E37: 0 | G37: =+G36+E37-F37 -> 2.009202e+08
D38: Simpanan Wajib Tno Cabang dan PTP Gaji April 2026 | E38: 8050000 | G38: =+G37+E38-F38 -> 2.089702e+08
D39: Simpanan Sukarela Tno Cabang dan PTP Gaji April 2026 | E39: 4400000 | G39: =+G38+E39-F39 -> 2.133702e+08
D40: Pendapatan Potongan Piutang Uang Tno Cabang dan Ptp Gaji April 2026 | E40: 13450000 | G40: =+G39+E40-F40 -> 2.268202e+08
D41: Pendapatan Jasa Uang Tno Cabang dan Tno PTP | E41: 1755000 | G41: =+G40+E41-F41 -> 2.285752e+08
D42: Pendapatan Potongan Piutang Barang Tno Cabang dan PTP Gaji April 2026 | E42: 1400000 | G42: =+G41+E42-F42 -> 2.299752e+08
D43: Pendapatan Jasa Barang Tno Cabang dan Tno PTP | E43: 185750 | G43: =+G42+E43-F43 -> 2.3016095e+08
...

Sheet 06, JUNI 26
A3: KAS BANK MANDIRI
A4: TAHUN 2026
A5: KOPKAR BANDAR BANTEN | D5: BULAN : JUNI 2026
A7: NO | B7: TGL | C7: KODE | D7: URAIAN | E7: KREDIT | F7: DEBET | G7: SALDO
C8: REK.
D9: SALDO PINDAHAN | E9: 0 | F9: 0 | G9: =+'05,MEI 26'!G268 -> 5847035
B10: 02 Juni 2026 | D10: Setor Tunai Pembayaran Lembur Karyawan Cleaning Service | E10: 10000000 | G10: =+G9+E10-F10 -> 15847035
D11: Pembayaran Potongan Koperasi PDS Periode Juni 2026 | G11: =+G10+E11-F11 -> 15847035
D12: Simpanan Wajib Tno Cabang dan PTP Gaji Mei 2026 | E12: 8050000 | G12: =+G11+E12-F12 -> 23897035
D13: Simpanan Sukarela Tno Cabang dan PTP Gaji Mei 2026 | E13: 4400000 | G13: =+G12+E13-F13 -> 28297035
D14: Pendapatan Potongan Piutang Uang Tno Cabang dan Ptp Gaji Mei 2026 | E14: 14700000 | G14: =+G13+E14-F14 -> 42997035
D15: Pendapatan Jasa Uang Tno Cabang dan Tno PTP | E15: 1780000 | G15: =+G14+E15-F15 -> 44777035
D16: Pendapatan Potongan Piutang Barang Tno Cabang dan PTP Gaji Mei 2026 | E16: 1400000 | G16: =+G15+E16-F16 -> 46177035
D17: Pendapatan Jasa Barang Tno Cabang dan Tno PTP | E17: 185750 | G17: =+G16+E17-F17 -> 46362785
D18: Pendapatan Potongan Kantin Tno Cabang Gaji Mei 2026 | E18: 437000 | G18: =+G17+E18-F18 -> 46799785
D19: Pendapatan Potongan Kantin Tno PTP Gaji Mei 2026 | E19: 431000 | G19: =+G18+E19-F19 -> 47230785
D20: Utip Arisan PIP Banten & PTP | E20: 1190000 | G20: =+G19+E20-F20 -> 48420785
D21: Simpanan Wajib Security Cabang dan PTP | E21: 2400000 | G21: =+G20+E21-F21 -> 50820785
D22: Simpanan Sukarela Security Cabang dan PTP | E22: 3150000 | G22: =+G21+E22-F22 -> 53970785
D23: Pendapatan Potongan Piutang Uang dan Security Mei 2026 | E23: 2456667 | G23: =+G22+E23-F23 -> 56427452
... D25: Pendapatan Potongan Kantin Security PTP Banten | E25: 0 | G25: =+G24+E25-F25 -> 56427452
D26: Pembayaran Lembur Cleaning Service Kantor Cabang | F26: 3090000 | G26: =+G25+E26-F26 -> 53337452
D27: Pembayaran Lembur Cleaning Service PTP | F27: 1680000 | G27: =+G26+E27-F27 -> 51657452
D28: Pembayaran Lembur Cleaning Service Zonasi | F28: 1560000 | G28: =+G27+E28-F28 -> 50097452
D29: Pembayaran Lembur Cleaning Service SPJM | F29: 2160000 | G29: =+G28+E29-F29 -> 47937452
D30: Biaya Gaji TKHL Bulan Mei 2026 an Angga Putra Permana | F30: 5861213 | G30: =+G29+E30-F30 -> 42076239
D31: Biaya Gaji TKHL Bulan Mei 2026 an Galiztan EQ Gunanditya | F31: 4793276 | G31: =+G30+E31-F31 -> 37282963
D32: Utip BPJS Kesehatan TKHL PTP Banten | E32: 549956 | G32: =+G31+E32-F32 -> 37832919
D33: Utip BPJS Ketenagakerjaan TKHL PTP Banten | E33: 60552 | G33: =+G32+E33-F33 -> 37893471
D34: Utip transfer Piutang Yohan ke Dimas Gusman | F34: 200000 | G34: =+G33+E34-F34 -> 37693471
B35: 03 Juni 2026 | D35: Pengambilan Simpanan Wajib an Ega Gan Gan | F35: 1500000 | G35: =+G34+E35-F35 -> 36193471
D36: Biaya Administrasi | F36: 2500 | G36: =+G35+E36-F36 -> 36190971
D37: Simpanan Sukarela an Jimmy Greei Ganap | E37: 10000000 | G37: =+G36+E37-F37 -> 46190971
D38: Biaya Pembelian Alat Kebersihan Cleaning Service Cabang an Mulyani | F38: 11204228 | G38: =+G37+E38-F38 -> 34986743
D39: Pendapatan Potongan Bonus Pegawai Pelabuhan Banten | E39: 106550000 | G39: =+G38+E39-F39 -> 1.4153674e+08
E40: 0 | G40: =+G39+E40-F40 -> 1.4153674e+08
E41: 0 | G41: =+G40+E41-F41 -> 1.4153674e+08
E42: 0 | G42: =+G41+E42-F42 -> 1.4153674e+08
E43: 0 | G43: =+G42+E43-F43 -> 1.4153674e+08
E44: 0 | G44: =+G43+E44-F44 -> 1.4153674e+08
...

Sheet Sheet1
