Workbook

Sheet Sheet1
B4: PENDAPATAN KONSOLIDASI
B5: Uraian | D5: Tahun 2023 | E5: Tahun 2024 | F5: Tahun 2025 | G5: RKAP 2026 | H5: RKAP | I5: REALISASI | J5: PROGNOSA 2026 | S5: Prognosa | W5: RKAP 2027 | AF5: RKAP 2027 | AG5: Perbandingan
D6: (Audited) | E6: (Audited) | F6: (Unaudited) | G6: 1 Tahun | H6: s.d. Maret 2026 | I6: s.d. Maret 2026 | J6: APRIL | K6: MAI | L6: JUN | M6: JULI | N6: AUG | O6: SEPT | P6: OCT | Q6: NOV | R6: DEC | S6: Tahun 2026 | T6: JAN | U6: FEB | V6: MRT | W6: APRIL | X6: MEI | Y6: JUN | Z6: JULI | AA6: AUG | AB6: SEPT | AC6: OCT | AD6: NOV | AE6: DEC | AF6: 1 Tahun
D7: [a] | E7: [b] | F7: [c] | G7: [d] | H7: [f] | I7: [h] | S7: [l] | AF7: [r] | AG7: [w] = l/c | AH7: [x] = l/d | AI7: [y] = r/l
C8: PENDAPATAN USAHA
B9: 4010200000 | C9: Pendapatan Pemanduan | D9: 3827230611 | E9: 5775542903 | F9: 5041541657 | G9: 5064214344 | H9: 1353153240 | I9: 1747843289 | J9: 517085124 | K9: 517085124 | L9: 516185124 | M9: 519085124 | N9: 518085124 | O9: 515085124 | P9: 527085124 | Q9: 525185124 | R9: 506085124 | S9: =SUM(I9:R9) -> 6408809405 | T9: 5.8925118e+08 | U9: 5.7208853e+08 | V9: 2.8604426e+08 | W9: 5.7208853e+08 | X9: 5.7208853e+08 | Y9: 5.7208853e+08 | Z9: 5.7208853e+08 | AA9: 5.7208853e+08 | AB9: 5.7208853e+08 | AC9: 5.7208853e+08 | AD9: 5.7208853e+08 | AE9: 5.7208853e+08 | AF9: =SUM(T9:AE9) -> 6.5961807e+09 | AG9: =S9/F9 -> 1.2712003 | AH9: =S9/G9 -> 1.2655091 | AI9: =AF9/S9 -> 1.0292365
B10: 4010300000 | C10: Pendapatan Penundaan | D10: 23959764403 | E10: 41905655605 | F10: 38777589997 | G10: 45802086031 | H10: 10940590218 | I10: 13027152416 | J10: 3859934358 | K10: 3839934358 | L10: 3839934358 | M10: 3899934358 | N10: 3899934358 | O10: 3829934358 | P10: 3869934358 | Q10: 3859834358 | R10: 3839934358 | S10: =SUM(I10:R10) -> 47766461638 | T10: 4.2639317e+09 | U10: 4.2639317e+09 | V10: 2.1319659e+09 | W10: 4.2639317e+09 | X10: 4.2639317e+09 | Y10: 4.2639317e+09 | Z10: 4.2639317e+09 | AA10: 4.2639317e+09 | AB10: 4.2639317e+09 | AC10: 4.2639317e+09 | AD10: 4.2639317e+09 | AE10: 4.2639317e+09 | AF10: =SUM(T10:AE10) -> 4.9035215e+10 | AG10: =S10/F10 -> 1.2318058 | AH10: =S10/G10 -> 1.0428883 | AI10: =AF10/S10 -> 1.0265616
B11: 4010400000 | C11: Pendapatan Penambatan | D11: 27302323050 | E11: 48026526364 | F11: 51229046721 | G11: 48074254664 | H11: 16887380133 | I11: 20352721620 | J11: 6205453777 | K11: 6005453777 | L11: 6005453777 | M11: 6005453777 | N11: 6005453777 | O11: 6005463777 | P11: 6018853777 | Q11: 6015453777 | R11: 6006853777 | S11: =SUM(I11:R11) -> 74626615613 | T11: 6.9950053e+09 | U11: 6.9950053e+09 | V11: 3.6641693e+09 | W11: 6.9950053e+09 | X11: 6.9950053e+09 | Y11: 6.9950053e+09 | Z11: 6.9950053e+09 | AA11: 6.9950053e+09 | AB11: 6.9950053e+09 | AC11: 6.9950053e+09 | AD11: 6.9950053e+09 | AE11: 6.9950053e+09 | AF11: =SUM(T11:AE11) -> 8.0609227e+10 | AG11: =S11/F11 -> 1.4567247 | AH11: =S11/G11 -> 1.5523198 | AI11: =AF11/S11 -> 1.0801673
B12: 4010000000 | C12: PELAYANAN KAPAL | D12: =SUM(D9:D11) -> 55089318064 | E12: =SUM(E9:E11) -> 95707724872 | F12: =SUM(F9:F11) -> 95048178375 | G12: =SUM(G9:G11) -> 98940555039 | H12: =SUM(H9:H11) -> 29181123591 | I12: =SUM(I9:I11) -> 35127717325 | R12: =SUM(R9:R11) -> 10352873259 | S12: =SUM(S9:S11) -> 128801886656 | AF12: =SUM(AF9:AF11) -> 1.3624062e+11 | AG12: =S12/F12 -> 1.3551221 | AH12: =S12/G12 -> 1.3018108 | AI12: =AF12/S12 -> 1.0577533
B14: PENDAPATAN CIWANDAN
B15: Uraian | D15: Tahun 2023 | E15: Tahun 2024 | F15: Tahun 2025 | G15: RKAP 2026 | H15: RKAP | I15: REALISASI | J15: PROGNOSA 2026 | S15: Prognosa | W15: RKAP 2027 | AF15: RKAP 2027 | AG15: Perbandingan
D16: (Audited) | E16: (Audited) | F16: (Unaudited) | G16: 1 Tahun | H16: s.d. Maret 2026 | I16: s.d. Maret 2026 | J16: APRIL | K16: MAI | L16: JUN | M16: JULI | N16: AUG | O16: SEPT | P16: OCT | Q16: NOV | R16: DEC | S16: Tahun 2026 | T16: JAN | U16: FEB | V16: MRT | W16: APRIL | X16: MEI | Y16: JUN | Z16: JULI | AA16: AUG | AB16: SEPT | AC16: OCT | AD16: NOV | AE16: DEC | AF16: 1 Tahun
D17: [a] | E17: [b] | F17: [c] | G17: [d] | H17: [f] | I17: [h] | S17: [l] | AF17: [r] | AG17: [w] = l/c | AH17: [x] = l/d | AI17: [y] = r/l
C18: PENDAPATAN USAHA
B19: 4010100000 | C19: Pendapatan Labuh
B20: 4010200000 | C20: Pendapatan Pemanduan | I20: =I9-(I31+I47) -> 9.5859943e+08 | J20: =J9-(J31+J47) -> 2.5400384e+08 | K20: =K9-(K31+K47) -> 2.5548769e+08 | L20: =L9-(L31+L47) -> 2.5211666e+08 | M20: =M9-(M31+M47) -> 2.5501666e+08 | N20: =N9-(N31+N47) -> 2.5401666e+08 | O20: =O9-(O31+O47) -> 2.5101666e+08 | P20: =P9-(P31+P47) -> 2.6301666e+08 | ... R20: =R9-(R31+R47) -> 2.4201666e+08 | S20: =SUM(I20:R20) -> 3246407572 | T20: =T9-(T31+T47) -> 3.1691741e+08 | U20: =U9-(U31+U47) -> 2.9692606e+08 | V20: =V9-(V31+V47) -> 17770541 | W20: =W9-(W31+W47) -> 3.0198293e+08 | X20: =X9-(X31+X47) -> 3.0064904e+08 | Y20: =Y9-(Y31+Y47) -> 3.0064904e+08 | Z20: =Z9-(Z31+Z47) -> 3.0054904e+08 | AA20: =AA9-(AA31+AA47) -> 3.0064904e+08 | ... AE20: =AE9-(AE31+AE47) -> 3.0079736e+08 | AF20: =SUM(T20:AE20) -> 3.3379433e+09 | AG20: =S20/F20 -> #DIV/0! | AH20: =S20/G20 -> #DIV/0! | AI20: =AF20/S20 -> 1.028196
B21: 4010300000 | C21: Pendapatan Penundaan | I21: =I10-(I32+I48) -> 7.4336258e+09 | J21: =J10-(J32+J48) -> 1.9954255e+09 | K21: =K10-(K32+K48) -> 1.9724519e+09 | L21: =L10-(L32+L48) -> 1.9469435e+09 | M21: =M10-(M32+M48) -> 2.0069435e+09 | N21: =N10-(N32+N48) -> 2.0069435e+09 | O21: =O10-(O32+O48) -> 1.9369435e+09 | P21: =P10-(P32+P48) -> 1.9769435e+09 | ... R21: =R10-(R32+R48) -> 1.9469435e+09 | S21: =SUM(I21:R21) -> 2.5190008e+10 | T21: =T10-(T32+T48) -> 2.3376815e+09 | U21: =U10-(U32+U48) -> 2.2979446e+09 | V21: =V10-(V32+V48) -> 2.1652174e+08 | W21: =W10-(W32+W48) -> 2.3403299e+09 | X21: =X10-(X32+X48) -> 2.3261195e+09 | Y21: =Y10-(Y32+Y48) -> 2.3183595e+09 | Z21: =Z10-(Z32+Z48) -> 2.3173195e+09 | AA21: =AA10-(AA32+AA48) -> 2.3260195e+09 | ... AE21: =AE10-(AE32+AE48) -> 2.328534e+09 | AF21: =SUM(T21:AE21) -> 2.577175e+10 | AG21: =S21/F21 -> #DIV/0! | AH21: =S21/G21 -> #DIV/0! | AI21: =AF21/S21 -> 1.0230942
B22: 4010400000 | C22: Pendapatan Penambatan | I22: =I11-(I33+I49) -> 1.2223794e+10 | J22: =J11-(J33+J49) -> 3.4958112e+09 | K22: =K11-(K33+K49) -> 3.3030915e+09 | L22: =L11-(L33+L49) -> 3.302191e+09 | M22: =M11-(M33+M49) -> 3.302191e+09 | N22: =N11-(N33+N49) -> 3.302191e+09 | O22: =O11-(O33+O49) -> 3.302201e+09 | P22: =P11-(P33+P49) -> 3.315591e+09 | ... R22: =R11-(R33+R49) -> 3.303591e+09 | S22: =SUM(I22:R22) -> 42162843914 | T22: =T11-(T33+T49) -> 4.1077108e+09 | U22: =U11-(U33+U49) -> 4.101835e+09 | V22: =V11-(V33+V49) -> 7.7823748e+08 | W22: =W11-(W33+W49) -> 4.1087174e+09 | X22: =X11-(X33+X49) -> 4.1095315e+09 | Y22: =Y11-(Y33+Y49) -> 4.1095315e+09 | Z22: =Z11-(Z33+Z49) -> 4.1085315e+09 | AA22: =AA11-(AA33+AA49) -> 4.1085315e+09 | ... AE22: =AE11-(AE33+AE49) -> 4.1101175e+09 | AF22: =SUM(T22:AE22) -> 4.5969518e+10 | AG22: =S22/F22 -> #DIV/0! | AH22: =S22/G22 -> #DIV/0! | AI22: =AF22/S22 -> 1.090285
B23: 4010000000 | C23: PELAYANAN KAPAL | D23: =SUM(D19:D22) -> 0 | E23: =SUM(E19:E22) -> 0 | F23: =SUM(F19:F22) -> 0 | G23: =SUM(G19:G22) -> 0 | H23: =SUM(H19:H22) -> 0 | I23: =SUM(I19:I22) -> 2.0616019e+10 | J23: =SUM(J19:J22) -> 5.7452406e+09 | K23: =SUM(K19:K22) -> 5.531031e+09 | ... S23: =SUM(S19:S22) -> 7.0599259e+10 | AF23: =SUM(AF19:AF22) -> 7.5079211e+10 | AG23: =S23/F23 -> #DIV/0! | AH23: =S23/G23 -> #DIV/0! | AI23: =AF23/S23 -> 1.0634561
B26: PENDAPATAN IKPP
B27: Uraian | D27: Tahun 2023 | E27: Tahun 2024 | F27: Tahun 2025 | G27: RKAP 2026 | H27: RKAP | I27: REALISASI | J27: PROGNOSA 2026 | S27: Prognosa | W27: RKAP 2027 | AF27: RKAP 2027 | AG27: Perbandingan
D28: (Audited) | E28: (Audited) | F28: (Unaudited) | G28: 1 Tahun | H28: s.d. Maret 2026 | I28: s.d. Maret 2026 | J28: APR | K28: MAI | L28: JUN | M28: JULI | N28: AUG | O28: SEPT | P28: OCT | Q28: NOV | R28: DEC | S28: Tahun 2026 | T28: JAN | U28: FEB | V28: MRT | W28: APRIL | X28: MEI | Y28: JUN | Z28: JULI | AA28: AUG | AB28: SEPT | AC28: OCT | AD28: NOV | AE28: DEC | AF28: 1 Tahun
D29: [a] | E29: [b] | F29: [c] | G29: [d] | H29: [f] | I29: [h] | S29: [l] | AF29: [r] | AG29: [w] = l/c | AH29: [x] = l/d | AI29: [y] = r/l
C30: PENDAPATAN USAHA
B31: 4010200000 | C31: Pendapatan Pemanduan | I31: 7.6996613e+08 | J31: 2.5665538e+08 | K31: 2.5665538e+08 | L31: 2.5665538e+08 | M31: 2.5665538e+08 | N31: 2.5665538e+08 | O31: 2.5665538e+08 | P31: 2.5665538e+08 | Q31: 2.5665538e+08 | R31: 2.5665538e+08 | S31: =SUM(I31:R31) -> 3079864506 | T31: 2.6435504e+08 | U31: 2.6435504e+08 | V31: 2.6435504e+08 | W31: 2.6435504e+08 | X31: 2.6435504e+08 | Y31: 2.6435504e+08 | Z31: 2.6435504e+08 | AA31: 2.6435504e+08 | AB31: 2.6435504e+08 | AC31: 2.6435504e+08 | AD31: 2.6435504e+08 | AE31: 2.6435504e+08 | AF31: =SUM(T31:AE31) -> 3.1722604e+09 | AG31: =S31/F31 -> #DIV/0! | AH31: =S31/G31 -> #DIV/0! | AI31: =AF31/S31 -> 1.03
B32: 4010300000 | C32: Pendapatan Penundaan | I32: 5.4493974e+09 | J32: 1.8164658e+09 | K32: 1.8164658e+09 | L32: 1.8164658e+09 | M32: 1.8164658e+09 | N32: 1.8164658e+09 | O32: 1.8164658e+09 | P32: 1.8164658e+09 | Q32: 1.8164658e+09 | R32: 1.8164658e+09 | S32: =SUM(I32:R32) -> 21797589609 | T32: 1.8709598e+09 | U32: 1.8709598e+09 | V32: 1.8709598e+09 | W32: 1.8709598e+09 | X32: 1.8709598e+09 | Y32: 1.8709598e+09 | Z32: 1.8709598e+09 | AA32: 1.8709598e+09 | AB32: 1.8709598e+09 | AC32: 1.8709598e+09 | AD32: 1.8709598e+09 | AE32: 1.8709598e+09 | AF32: =SUM(T32:AE32) -> 2.2451517e+10 | AG32: =S32/F32 -> #DIV/0! | AH32: =S32/G32 -> #DIV/0! | AI32: =AF32/S32 -> 1.03
B33: 4010400000 | C33: Pendapatan Penambatan | I33: 8.1016842e+09 | J33: 2.7005614e+09 | K33: 2.7005614e+09 | L33: 2.7005614e+09 | M33: 2.7005614e+09 | N33: 2.7005614e+09 | O33: 2.7005614e+09 | P33: 2.7005614e+09 | Q33: 2.7005614e+09 | R33: 2.7005614e+09 | S33: =SUM(I33:R33) -> 32406736806 | T33: 2.8815782e+09 | U33: 2.8815782e+09 | V33: 2.8815782e+09 | W33: 2.8815782e+09 | X33: 2.8815782e+09 | Y33: 2.8815782e+09 | Z33: 2.8815782e+09 | AA33: 2.8815782e+09 | AB33: 2.8815782e+09 | AC33: 2.8815782e+09 | AD33: 2.8815782e+09 | AE33: 2.8815782e+09 | AF33: =SUM(T33:AE33) -> 3.4578939e+10 | AG33: =S33/F33 -> #DIV/0! | AH33: =S33/G33 -> #DIV/0! | AI33: =AF33/S33 -> 1.0670293
B34: 4010000000 | C34: PELAYANAN KAPAL | D34: =SUM(D31:D33) -> 0 | E34: =SUM(E31:E33) -> 0 | F34: =SUM(F31:F33) -> 0 | G34: =SUM(G31:G33) -> 0 | H34: =SUM(H31:H33) -> 0 | I34: =SUM(I31:I33) -> 1.4321048e+10 | J34: =SUM(J31:J33) -> 4.7736826e+09 | K34: =SUM(K31:K33) -> 4.7736826e+09 | ... AF34: =SUM(AF31:AF33) -> 6.0202717e+10
B35: 4030101000 | C35: Dermaga - General Cargo | I35: 2.2818507e+09 | J35: 7.606169e+08 | K35: 7.606169e+08 | L35: 7.606169e+08 | M35: 7.606169e+08 | N35: 7.606169e+08 | O35: 7.606169e+08 | P35: 7.606169e+08 | Q35: 7.606169e+08 | R35: 7.606169e+08 | S35: =SUM(I35:R35) -> 9127402758 | T35: 7.834354e+08 | U35: 7.834354e+08 | V35: 7.834354e+08 | W35: 7.834354e+08 | X35: 7.834354e+08 | Y35: 7.834354e+08 | Z35: 7.834354e+08 | AA35: 7.834354e+08 | AB35: 7.834354e+08 | AC35: 7.834354e+08 | AD35: 7.834354e+08 | AE35: 7.834354e+08 | AF35: =SUM(T35:AE35) -> 9.4012248e+09 | AG35: =S35/F35 -> #DIV/0! | AH35: =S35/G35 -> #DIV/0! | AI35: =AF35/S35 -> 1.03
B36: 4030102000 | C36: Pengusahaan Gudang | I36: 25496625 | J36: 8498875 | K36: 8498875 | L36: 8498875 | M36: 8498875 | N36: 8498875 | O36: 8498875 | P36: 8498875 | Q36: 8498875 | R36: 8498875 | S36: =SUM(I36:R36) -> 101986500 | T36: 8753841.2 | U36: 8753841.2 | V36: 8753841.2 | W36: 8753841.2 | X36: 8753841.2 | Y36: 8753841.2 | Z36: 8753841.2 | AA36: 8753841.2 | AB36: 8753841.2 | AC36: 8753841.2 | AD36: 8753841.2 | AE36: 8753841.2 | AF36: =SUM(T36:AE36) -> 105046095 | AG36: =S36/F36 -> #DIV/0! | AH36: =S36/G36 -> #DIV/0! | AI36: =AF36/S36 -> 1.03
B37: 4030103000 | C37: Pengusahaan Lapangan | I37: 143043750 | J37: 47681250 | K37: 47681250 | L37: 47681250 | M37: 47681250 | N37: 47681250 | O37: 47681250 | P37: 47681250 | Q37: 47681250 | R37: 47681250 | S37: =SUM(I37:R37) -> 572175000 | T37: 49111688 | U37: 49111688 | V37: 49111688 | W37: 49111688 | X37: 49111688 | Y37: 49111688 | Z37: 49111688 | AA37: 49111688 | AB37: 49111688 | AC37: 49111688 | AD37: 49111688 | AE37: 49111688 | AF37: =SUM(T37:AE37) -> 589340250 | AG37: =S37/F37 -> #DIV/0! | AH37: =S37/G37 -> #DIV/0! | AI37: =AF37/S37 -> 1.03
I38: =SUM(I35:I37) -> 2.4503911e+09 | J38: =SUM(J35:J37) -> 8.1679702e+08 | K38: =SUM(K35:K37) -> 8.1679702e+08 | L38: =SUM(L35:L37) -> 8.1679702e+08 | M38: =SUM(M35:M37) -> 8.1679702e+08 | N38: =SUM(N35:N37) -> 8.1679702e+08 | O38: =SUM(O35:O37) -> 8.1679702e+08 | P38: =SUM(P35:P37) -> 8.1679702e+08 | ... AF38: =SUM(AF35:AF37) -> 1.0095611e+10
B39: 4060301000 | C39: Timbangan disewakan | I39: 2849169750 | J39: 949723250 | K39: 949723250 | L39: 949723250 | M39: 949723250 | N39: 949723250 | O39: 949723250 | P39: 949723250 | Q39: 949723250 | R39: 949723250 | S39: =SUM(I39:R39) -> 11396679000 | T39: 9.7821495e+08 | U39: 9.7821495e+08 | V39: 9.7821495e+08 | W39: 9.7821495e+08 | X39: 9.7821495e+08 | Y39: 9.7821495e+08 | Z39: 9.7821495e+08 | AA39: 9.7821495e+08 | AB39: 9.7821495e+08 | AC39: 9.7821495e+08 | AD39: 9.7821495e+08 | AE39: 9.7821495e+08 | AF39: =SUM(T39:AE39) -> 11738579370 | AG39: =S39/F39 -> #DIV/0! | AH39: =S39/G39 -> #DIV/0! | AI39: =AF39/S39 -> 1.03
B42: PENDAPATAN BOJONEGARA
B43: Uraian | D43: Tahun 2023 | E43: Tahun 2024 | F43: Tahun 2025 | G43: RKAP 2026 | H43: RKAP | I43: REALISASI | J43: PROGNOSA 2026 | S43: Prognosa | W43: RKAP 2027 | AF43: RKAP 2027 | AG43: Perbandingan
D44: (Audited) | E44: (Audited) | F44: (Unaudited) | G44: 1 Tahun | H44: s.d. Maret 2026 | I44: s.d. Maret 2026 | J44: APRIL | K44: MAI | L44: JUN | M44: JULI | N44: AUG | O44: SEPT | P44: OCT | Q44: NOV | R44: DEC | S44: Tahun 2026 | T44: JAN | U44: FEB | V44: MRT | W44: APRIL | X44: MEI | Y44: JUN | Z44: JULI | AA44: AUG | AB44: SEPT | AC44: OCT | AD44: NOV | AE44: DEC | AF44: 1 Tahun
D45: [a] | E45: [b] | F45: [c] | G45: [d] | H45: [f] | I45: [h] | S45: [l] | AF45: [r] | AG45: [w] = l/c | AH45: [x] = l/d | AI45: [y] = r/l
C46: PENDAPATAN USAHA
B47: 4010200000 | C47: Pendapatan Pemanduan | I47: 19277728 | J47: 6425909.2 | K47: 4942060 | L47: 7413090 | M47: 7413090 | N47: 7413090 | O47: 7413090 | P47: 7413090 | Q47: 7413090 | R47: 7413090 | S47: =SUM(I47:R47) -> 82537327 | T47: 7978735.8 | U47: 10807435 | V47: 3918686.5 | W47: 5750565.6 | X47: 7084453.9 | Y47: 7084453.9 | Z47: 7184453.9 | AA47: 7084453.9 | AB47: 7084453.9 | AC47: 7978735.8 | AD47: 7084453.9 | AE47: 6936130 | AF47: =SUM(T47:AE47) -> 85977012 | AG47: =S47/F47 -> #DIV/0! | AH47: =S47/G47 -> #DIV/0! | AI47: =AF47/S47 -> 1.0416743
B48: 4010300000 | C48: Pendapatan Penundaan | I48: 1.4412917e+08 | J48: 48043057 | K48: 51016682 | L48: 76525024 | M48: 76525024 | N48: 76525024 | O48: 76525024 | P48: 76525024 | Q48: 76525024 | R48: 76525024 | S48: =SUM(I48:R48) -> 7.7886407e+08 | T48: 55290428 | U48: 95027393 | V48: 44484348 | W48: 52642093 | X48: 66852500 | Y48: 74612500 | Z48: 75652500 | AA48: 66952500 | AB48: 66852500 | AC48: 75290428 | AD48: 73852500 | AE48: 64437962 | AF48: =SUM(T48:AE48) -> 8.1194765e+08 | AG48: =S48/F48 -> #DIV/0! | AH48: =S48/G48 -> #DIV/0! | AI48: =AF48/S48 -> 1.0424767
...

Sheet Sheet2
B3: PENDAPATAN USAHA | C3: REALISASI 2025 | D3: RKAP 2026 | E3: REALISASI S.D MRT-26 | F3: PROGNOSA 2026 | G3: RKAP 2027 | H3: PERBANDINGAN RKAP 2027 | K3: PERBANDINGAN PROGNOSA
C4: 1 | D4: 2 | E4: 3 | F4: 4 | G4: 5 | H4: 6=4/3 | I4: 7=4/2 | J4: 8=4/1 | K4: 9=3/2 | L4: 10=3/1
B5: =Sheet1!C9 -> Pendapatan Pemanduan | C5: =Sheet1!F9 -> 5041541657 | D5: =Sheet1!G9 -> 5064214344 | E5: =Sheet1!I9 -> 1747843289 | F5: =Sheet1!S9 -> 6408809405 | G5: =Sheet1!AF9 -> 6.5961807e+09 | H5: =G5/F5 -> 1.0292365 | I5: =G5/D5 -> 1.3025082 | J5: =G5/C5 -> 1.3083658 | K5: =F5/D5 -> 1.2655091 | L5: =F5/C5 -> 1.2712003
B6: =Sheet1!C10 -> Pendapatan Penundaan | C6: =Sheet1!F10 -> 38777589997 | D6: =Sheet1!G10 -> 45802086031 | E6: =Sheet1!I10 -> 13027152416 | F6: =Sheet1!S10 -> 47766461638 | G6: =Sheet1!AF10 -> 4.9035215e+10 | H6: =G6/F6 -> 1.0265616 | I6: =G6/D6 -> 1.0705891 | J6: =G6/C6 -> 1.2645246 | K6: =F6/D6 -> 1.0428883 | L6: =F6/C6 -> 1.2318058
B7: =Sheet1!C11 -> Pendapatan Penambatan | C7: =Sheet1!F11 -> 51229046721 | D7: =Sheet1!G11 -> 48074254664 | E7: =Sheet1!I11 -> 20352721620 | F7: =Sheet1!S11 -> 74626615613 | G7: =Sheet1!AF11 -> 8.0609227e+10 | H7: =G7/F7 -> 1.0801673 | I7: =G7/D7 -> 1.676765 | J7: =G7/C7 -> 1.5735063 | K7: =F7/D7 -> 1.5523198 | L7: =F7/C7 -> 1.4567247
B8: Jumlah | C8: =SUM(C5:C7) -> 95048178375 | D8: =SUM(D5:D7) -> 98940555039 | E8: =Sheet1!I12 -> 35127717325 | F8: =SUM(F5:F7) -> 128801886656 | G8: =SUM(G5:G7) -> 1.3624062e+11 | H8: =G8/F8 -> 1.0577533 | I8: =G8/D8 -> 1.3769947 | J8: =G8/C8 -> 1.4333849 | K8: =F8/D8 -> 1.3018108 | L8: =F8/C8 -> 1.3551221
B10: Note :
B11: 1. Perbandingan antara RKAP 2027 dan Prognosa 2026 | F11: =H8 -> 1.0577533
B12: 2. Perbandingan antara RKAP 2027 dan RKAP 2026 | F12: =I8 -> 1.3769947
B13: 3. Perbandingan antara RKAP 2027 dan Realisasi 2025 | F13: =J8 -> 1.4333849
B14: 4. Perbandingan antara Prognosa 2026 dan RKAP 2026 | F14: =K8 -> 1.3018108
B15: 5. Perbandingan antara Prognosa 2026 dan Realisasi 2025 | F15: =L8 -> 1.3551221
B17: Breakdown Pendapatan Tambat | C17: Prognosa 2026 | E17: RKAP 2027
C18: % | D18: (Rp) | E18: % | F18: (Rp)
B19: Cabang | C19: =Sheet1!S22/Sheet1!S11 -> 0.564984 | D19: =Sheet1!S22 -> 42162843914 | E19: =Sheet1!AF22/Sheet1!AF11 -> 0.57027613 | F19: =Sheet1!AF22 -> 4.5969518e+10
B20: IKPP | C20: =Sheet1!S33/Sheet1!S11 -> 0.43425173 | D20: =Sheet1!S33 -> 32406736806 | E20: =Sheet1!AF33/Sheet1!AF11 -> 0.42896998 | F20: =Sheet1!AF33 -> 3.4578939e+10
B21: Bojonegara | C21: =Sheet1!S49/Sheet1!S11 -> 0.00076427013 | D21: =Sheet1!S49 -> 57034893 | E21: =Sheet1!AF49/Sheet1!AF11 -> 0.00075388504 | F21: =Sheet1!AF49 -> 60770090
B22: Jumlah | C22: =SUM(C19:C21) -> 1 | D22: =SUM(D19:D21) -> 74626615613 | E22: =SUM(E19:E21) -> 1 | F22: =SUM(F19:F21) -> 8.0609227e+10
B24: Breakdown Pendapatan Tambat | C24: Prognosa 2026 | E24: RKAP 2027
C25: % | D25: (Rp) | E25: % | F25: (Rp)
B26: Cabang | C26: =D26/D29 -> 0.50655393 | D26: =Sheet1!S20 -> 3246407572 | E26: =F26/F29 -> 0.50604182 | F26: =Sheet1!AF20 -> 3.3379433e+09
B27: IKPP | C27: =D27/D29 -> 0.48056734 | D27: =Sheet1!S31 -> 3079864506 | E27: =F27/F29 -> 0.48092382 | F27: =Sheet1!AF31 -> 3.1722604e+09
B28: Bojonegara | C28: =D28/D29 -> 0.01287873 | D28: =Sheet1!S47 -> 82537327 | E28: =F28/F29 -> 0.013034363 | F28: =Sheet1!AF47 -> 85977012
B29: Jumlah | C29: =SUM(C26:C28) -> 1 | D29: =SUM(D26:D28) -> 6408809405 | E29: =SUM(E26:E28) -> 1 | F29: =SUM(F26:F28) -> 6.5961807e+09
B31: Breakdown Pendapatan Penundaan | C31: Prognosa 2026 | E31: RKAP 2027
C32: % | D32: (Rp) | E32: % | F32: (Rp)
B33: Cabang | C33: =D33/D36 -> 0.52735763 | D33: =Sheet1!S21 -> 2.5190008e+10 | E33: =F33/F36 -> 0.52557636 | F33: =Sheet1!AF21 -> 2.577175e+10
B34: IKPP | C34: =D34/D36 -> 0.4563367 | D34: =Sheet1!S32 -> 21797589609 | E34: =F34/F36 -> 0.45786518 | F34: =Sheet1!AF32 -> 2.2451517e+10
B35: Bojonegara | C35: =D35/D36 -> 0.016305668 | D35: =Sheet1!S48 -> 7.7886407e+08 | E35: =F35/F36 -> 0.01655846 | F35: =Sheet1!AF48 -> 8.1194765e+08
B36: Jumlah | C36: =SUM(C33:C35) -> 1 | D36: =SUM(D33:D35) -> 4.7766462e+10 | E36: =SUM(E33:E35) -> 1 | F36: =SUM(F33:F35) -> 4.9035215e+10
B38: Total Pendapatan Derum | C38: Prognosa 2026 | E38: RKAP 2027
C39: % | D39: (Rp) | E39: % | F39: (Rp)
B40: Cabang | C40: =D40/D43 -> 0.54812287 | D40: =D19+D26+D33 -> 7.0599259e+10 | E40: =F40/F43 -> 0.55107801 | F40: =F19+F26+F33 -> 7.5079211e+10
B41: IKPP | C41: =D41/D43 -> 0.44474652 | D41: =D20+D27+D34 -> 57284190921 | E41: =F41/F43 -> 0.44188521 | F41: =F20+F27+F34 -> 6.0202717e+10
B42: Bojonegara | C42: =D42/D43 -> 0.0071306121 | D42: =D21+D28+D35 -> 9.1843629e+08 | E42: =F42/F43 -> 0.0070367761 | F42: =F21+F28+F35 -> 9.5869475e+08
B43: Jumlah | C43: =SUM(C40:C42) -> 1 | D43: =SUM(D40:D42) -> 1.2880189e+11 | E43: =SUM(E40:E42) -> 1 | F43: =SUM(F40:F42) -> 1.3624062e+11
B45: Pendapatan TUKS | C45: Prognosa 2026 | E45: RKAP 2027
C46: % | D46: (Rp) | E46: % | F46: (Rp)
B47: Pemanduan | C47: =D47/D49 -> 0.15333087 | D47: =Sheet1!S58 -> 31638144961 | E47: =F47/F49 -> 0.15326632 | F47: =Sheet1!AF58 -> 3.2412974e+10
B48: Penundaan | C48: =D48/D49 -> 0.84666913 | D48: =Sheet1!S59 -> 174700894464 | E48: =F48/F49 -> 0.84673368 | F48: =Sheet1!AF59 -> 1.7906842e+11
...
