Workbook

Sheet Sheet1
A2: NM_REGIONAL | B2: KD_REGIONAL | C2: REGCODE | E2: Regional.1 | F2: KdRegP1 | H2: Regional.2 | I2: KdRegP2 | K2: Regional.3 | L2: KdRegP3 | N2: Regional.4 | O2: KdRegp4 | Q2: SPTP | R2: KdSPTP | T2: SPMT | U2: KdSPMT | W2: SPJM | X2: KdSPJM | Z2: SPSL | AA2: KdSPSL
A3: Regional.1 | B3: 001 | C3: RegP1 | E3: Belawan | F3: 1 | H3: Tanjung Priok | I3: 18 | K3: Tanjung Perak | L3: 44 | N3: Makassar | O3: 77 | Q3: TPK Nilam | R3: 110 | T3: Dumai | U3: 138 | W3: Dumai | X3: 171 | Z3: PIL - Belawan | AA3: 218
A4: Regional.2 | B4: 002 | C4: RegP2 | E4: Prima Terminal Petikemas - Belawan | F4: 2 | H4: IPC TPK TP1 | I4: 19 | K4: Jamrud - Tanjung Perak | L4: 45 | N4: MNP - Makassar | O4: 78 | Q4: TPK Belawan | R4: 111 | T4: Belawan | U4: 139 | W4: Batam | X4: 172 | Z4: PIL - Sei Mangkei | AA4: 219
A5: Regional.3 | B5: 003 | C5: RegP3 | E5: TPK - Belawan | F5: 3 | H5: IPC TPK TP2 | I5: 20 | K5: Nilam Mirah - Tanjung Perak | L5: 46 | N5: TPM - Makassar | O5: 79 | Q5: TPK Semarang | R5: 112 | T5: Tanjung Intan | U5: 140 | W5: Sei Pakning | X5: 173 | Z5: PIL - Kuala Tanjung | AA5: 220
A6: Regional.4 | B6: 004 | C6: RegP4 | E6: Dumai | F6: 4 | H6: JICT - Tanjung Priok | I6: 21 | K6: Kalimas - Tanjung Perak | L6: 47 | N6: Samarinda | O6: 80 | Q6: TPK Banjarmasin | R6: 113 | T6: Bumiharjo | U6: 141 | W6: Belawan | X6: 174 | Z6: PIL - Dumai | AA6: 221
A7: SPTP | B7: 005 | C7: SPTP | E7: Pekanbaru | F7: 5 | H7: TPK Koja - Tanjung Priok | I7: 22 | K7: TPS - Tanjung Perak | L7: 48 | N7: Balikpapan | O7: 81 | Q7: TPK Makassar | R7: 114 | T7: Bagendang | U7: 142 | W7: Tg. Balai Karimun | X7: 175 | Z7: PIL - Perawang | AA7: 222
A8: SPMT | B8: 006 | C8: SPMT | E8: Malahayati | F8: 6 | H8: NPCT1 - Tanjung Priok | I8: 23 | K8: BJTI - Tanjung Perak | L8: 49 | N8: TPK KKT - Balikpapan | O8: 82 | Q8: Makassar New Port | R8: 115 | T8: Tanjung Wangi | U8: 143 | W8: Tanjung Pinang | X8: 176 | Z8: PIL - Tanjung Pinang | AA8: 223
A9: SPJM | B9: 007 | C9: SPJM | E9: Tanjung Balai Karimun | F9: 7 | H9: MTI (MAL) - Tanjung Priok | I9: 24 | K9: TTL - Tanjung Perak | L9: 50 | N9: Bitung | O9: 83 | Q9: TPK Bitung | R9: 116 | T9: Trisakti | U9: 144 | W9: Lhokseumawe | X9: 177 | Z9: MTI - Jambi | AA9: 224
A10: SPSL | B10: 008 | C10: SPSL | E10: Lhokseumawe | F10: 8 | H10: PTP - Tanjung Priok | I10: 25 | K10: Gresik | L10: 51 | N10: TPK - Bitung | O10: 84 | Q10: Ambon | R10: 117 | T10: Jamrud | U10: 145 | W10: Malahayati | X10: 178 | Z10: MTI - Palembang | AA10: 225
E11: Batam | F11: 9 | H11: IKT - Tanjung Priok | I11: 26 | K11: Kalianget | L11: 52 | N11: Ambon | O11: 85 | Q11: Kendari | R11: 118 | T11: Mekar Putih | U11: 146 | W11: Kuala Tanjung | X11: 179 | Z11: MTI - Panjang | AA11: 226
E12: Tanjung Pinang | F12: 10 | H12: Panjang | I12: 27 | K12: Tanjung Tembaga | L12: 53 | N12: Sorong | O12: 86 | Q12: Pantoloan | R12: 119 | T12: Makassar | U12: 147 | W12: Pekanbaru | X12: 180 | Z12: MTI - Tanjung Pandan | AA12: 227
E13: Sibolga | F13: 11 | H13: IPC TPK - Panjang | I13: 28 | K13: Tanjung Wangi | L13: 54 | N13: Jayapura | O13: 87 | Q13: TPK Perawang | R13: 120 | T13: Balikpapan | U13: 148 | W13: Tanjung Perak | X13: 181 | Z13: MTI - Natuna | AA13: 228
E14: Gunung Sitoli | F14: 12 | H14: IKT - Panjang | I14: 29 | K14: Tanjung Emas | L14: 55 | N14: Tarakan | O14: 88 | Q14: Sorong | R14: 121 | T14: PTP - Tanjung Priok | U14: 149 | W14: Tanjung Wangi | X14: 182 | Z14: MTI - Pontianak | AA14: 229
E15: Tembilahan | F15: 13 | H15: Palembang | I15: 30 | K15: TPKS - Tanjung Emas | L15: 56 | N15: Pantoloan | O15: 89 | Q15: Jayapura | R15: 122 | T15: PTP - Banten | U15: 150 | W15: Tanjung Emas | X15: 183 | Z15: MTI - Jakarta | AA15: 230
E16: Tanjung Balai Asahan | F16: 14 | H16: IPC TPK - Palembang | I16: 31 | K16: Tegal | L16: 57 | N16: Ternate | O16: 90 | Q16: Tarakan | R16: 123 | T16: PTP - Bengkulu | U16: 151 | W16: Tanjung Intan | X16: 184 | Z16: MTI - Semarang | AA16: 231
E17: Kuala Tanjung | F17: 15 | H17: Teluk Bayur | I17: 32 | K17: Tanjung Intan | L17: 58 | N17: Kendari | O17: 91 | Q17: TPK Kupang | R17: 124 | T17: PTP - Cirebon | U17: 152 | W17: Banjarmasin | X17: 185 | Z17: MTI - Surabaya | AA17: 232
E18: Prima Multi Terminal - Kuala Tanjung | F18: 16 | H18: IPC TPK - Teluk Bayur | I18: 33 | K18: Trisakti | L18: 59 | N18: Bontang | O18: 92 | Q18: PT PTP | R18: 125 | T18: PTP - Jambi | U18: 153 | W18: Kotabaru | X18: 186 | Z18: MTI - Bali | AA18: 233
E19: Sei Pakning | F19: 17 | H19: Pontianak | I19: 34 | K19: TPKB - Trisakti | L19: 60 | N19: Parepare | O19: 93 | Q19: IPC TPK - TP1 | R19: 127 | T19: PTP - Palembang | U19: 154 | W19: Batulicin | X19: 187 | Z19: MTI - Nunukan | AA19: 234
H20: IPC TPK - Pontianak | I20: 35 | K20: Pulang Pisau | L20: 61 | N20: Biak | O20: 94 | Q20: IPC TPK - TP2 | R20: 128 | T20: PTP - Pangkal Balam | U20: 155 | W20: Sampit | X20: 188 | Z20: MTI - Tarakan | AA20: 235
H21: Jambi | I21: 36 | K21: Batulicin | L21: 62 | N21: Merauke | O21: 95 | Q21: IPC TPK - Panjang | R21: 129 | T21: PTP - Panjang | U21: 156 | W21: Kumai | X21: 189 | Z21: MTI - Tanjung Redep | AA21: 236
H22: IPC TPK - Jambi | I22: 37 | K22: Kotabaru | L22: 63 | N22: Manokwari | O22: 96 | Q22: IPC TPK - Palembang | R22: 130 | T22: PTP - Tanjung Pandan | U22: 157 | W22: Mekar Putih | X22: 190 | Z22: MTI - Sangatta | AA22: 237
H23: Banten | I23: 38 | K23: Bagendang | L23: 64 | N23: Nunukan | O23: 97 | Q23: IPC TPK - Teluk Bayur | R23: 131 | T23: PTP - Teluk Bayur | U23: 158 | W23: Benoa | X23: 191 | Z23: MTI - Bontang | AA23: 238
H24: Cirebon | I24: 39 | K24: Bumiharjo | L24: 65 | N24: Tanjung Redeb | O24: 98 | Q24: IPC TPK - Pontianak | R24: 132 | T24: PTP - Pontianak | U24: 159 | W24: Lembar | X24: 192 | Z24: MTI - Samarinda | AA24: 239
H25: Bengkulu | I25: 40 | K25: Benoa | L25: 66 | N25: Gorontalo | O25: 99 | Q25: IPC TPK - Jambi | R25: 133 | T25: PT TTL | U25: 160 | W25: Kupang | X25: 193 | Z25: MTI - Balikpapan | AA25: 240
H26: Sunda Kelapa | I26: 41 | K26: Celukan Bawang | L26: 67 | N26: Fakfak | O26: 100 | Q26: PT TPS | R26: 134 | T26: IKT - Tanjung Priok | U26: 161 | W26: Balikpapan | X26: 194 | Z26: MTI - Tolitoli | AA26: 241
H27: Pangkal Balam | I27: 42 | K27: Lembar | L27: 68 | N27: Tolitoli | O27: 101 | Q27: PT TTL | R27: 135 | T27: IKT - Panjang | U27: 162 | W27: Samarinda | X27: 195 | Z27: MTI - Gorontalo | AA27: 242
H28: Tanjung Pandan | I28: 43 | K28: Maumere | L28: 69 | N28: Manado | O28: 102 | Q28: PT BJTI | R28: 136 | T28: IKT - Pontianak | U28: 163 | W28: Bontang | X28: 196 | Z28: MTI - Bitung | AA28: 243
H29: PN Panurjwan | I29: 108 | K29: Bima | L29: 70 | N29: Sangatta | O29: 103 | Q29: PT KKT | R29: 137 | T29: IKT - Belawan | U29: 164 | W29: Sangatta | X29: 197 | Z29: MTI - Pantoloan | AA29: 244
K30: Badas | L30: 71 | N30: SBU Marine Luwuk Banggai | O30: 104 | Q30: TPK New Makassar | R30: 170 | T30: IKT - Makassar | U30: 167 | W30: Makassar | X30: 198 | Z30: MTI - Parepare | AA30: 245
K31: Tenau | L31: 72 | N31: SBU Marine Sangkulirang | O31: 105 | T31: Nilam - Mirah | U31: 166 | W31: Kendari | X31: 199 | Z31: MTI - Kendari | AA31: 246
K32: Ende | L32: 73 | N32: SBU Marine Tanah Grogot | O32: 106 | W32: Tanjung Redeb | X32: 200 | Z32: MTI - Ternate | AA32: 247
K33: Waingapu | L33: 74 | N33: SBU Marine Bontang Indominco | O33: 107 | W33: Sorong | X33: 201 | Z33: MTI - Ambon | AA33: 248
K34: Kalabahi | L34: 75 | N34: SBU Marine Tg Santan | O34: 109 | W34: Bitung | X34: 202 | Z34: MTI - Fak fak | AA34: 249
K35: Labuan Bajo | L35: 76 | N35: SBU Marine Lubuk Tutung | O35: 165 | W35: Pantoloan | X35: 203 | Z35: MTI - Sorong | AA35: 250
K36: Sampit | L36: 168 | W36: Parepare | X36: 204 | Z36: MTI - Manokwari | AA36: 251
K37: Kumai | L37: 169 | W37: Manado | X37: 205 | Z37: MTI - Biak | AA37: 252
W38: Tarakan | X38: 206 | Z38: MTI - Jayapura | AA38: 253
W39: Ambon | X39: 207 | Z39: MTI - Merauke | AA39: 254
W40: Ternate | X40: 208 | Z40: PPK - Belawan | AA40: 255
W41: Jayapura | X41: 209 | Z41: PPK - Kuala Tanjung | AA41: 256
...

Sheet ARUS
C1: Version : 3.1
C2: TAHUN (YYYY) : | H2: 2026
B4: =IFERROR(VLOOKUP(H4,Sheet1!$A$3:$B$10,2,0),"") -> 002 | C4: REGIONAL : | H4: Regional.2
B5: =IFERROR(VLOOKUP(H4,Sheet1!$A$3:$C$10,3,0),"") -> RegP2
B6: =IF(B4="001",VLOOKUP(H6,Sheet1!$E$3:$F$100,2,0),IF(B4="002",VLOOKUP(H6,Sheet1!$H$3:$I$100,2,0),IF(B4="003",VLOOKUP(H6,Sheet1!$K$3:$L$100,2,0),IF(B4="004",VLOOKUP(H6,Sheet1!$N$3:$O$100,2,0),IF(B4="005",VLOOKUP(H6,Sheet1!$Q$3:$R$100,2,0),IF(B4="006",VLOOKUP(H6,Sheet1!$T$3:$U$100,2,0),IF(B4="007",VLOOKUP(H6,Sheet1!$W$3:$X$100,2,0),IF(B4="008",VLOOKUP(H6,Sheet1!$Z$3:$AA$100,2,0),"NOTFOUND")))))))) -> 38 | C6: CABANG / TERMINAL : | H6: Banten
A8: 1 | C8: Kunjungan Kapal Berdasarkan Lokasi Sandar, Jenis Pelayaran dan Jenis Muatan Kapal
B10: Bulan | J10: 1 | K10: 2 | L10: 3 | M10: 4 | N10: 5 | O10: 6 | P10: 7 | Q10: 8 | R10: 9 | S10: 10 | T10: 11 | U10: 12
C12: No | D12: Uraian | I12: Satuan | J12: =$H$2 -> 2026
J14: Januari | K14: Februari | L14: Maret | M14: April | N14: Mei | O14: Juni | P14: Juli | Q14: Agustus | R14: September | S14: Oktober | T14: November | U14: Desember | V14: Total
C15: 1 | D15: 2 | I15: 3 | J15: 4 | V15: 5
C17: 1 | D17: DERMAGA UMUM
D18: 1 | E18: Pelayaran Luar Negeri
E19: 1 | F19: Kapal
B20: A010101010000 | F20: 1 | G20: General Cargo | I20: Call | J20: 4 | K20: 8 | L20: 12 | M20: 10 | N20: 7 | V20: =SUM(J20:U20) -> 41 | X20: =V20+V61 -> 95
B21: A010101010000 | I21: GT | J21: 139291 | K21: 111201 | L21: 172807 | M21: 197021 | N21: 112145 | V21: =SUM(J21:U21) -> 732465 | X21: =V21+V62 -> 896210
B22: A010101020000 | F22: 2 | G22: Curah Cair BBM | I22: Call | J22: 1 | K22: 4 | L22: 3 | M22: 5 | N22: 6 | V22: =SUM(J22:U22) -> 19 | X22: =V22+V63+V187 -> 317
B23: A010101020000 | I23: GT | J23: 5072 | K23: 24819 | L23: 15090 | M23: 33124 | N23: 36145 | V23: =SUM(J23:U23) -> 114250 | X23: =V23+V64+V188 -> 2398184
B24: A010101030000 | F24: 3 | G24: Gas | I24: Call | V24: =SUM(J24:U24) -> 0
B25: A010101030000 | I25: GT | V25: =SUM(J25:U25) -> 0
B26: A010101040000 | F26: 4 | G26: Curah Cair Non - BBM | I26: Call | V26: =SUM(J26:U26) -> 0
B27: A010101040000 | I27: GT | V27: =SUM(J27:U27) -> 0
B28: A010101050000 | F28: 5 | G28: Curah Kering | I28: Call | J28: 3 | K28: 9 | L28: 8 | M28: 9 | N28: 7 | V28: =SUM(J28:U28) -> 36 | X28: =V28+V69+V193 -> 196
B29: A010101050000 | I29: GT | J29: 93516 | K29: 272703 | L29: 251792 | M29: 249242 | N29: 246829 | V29: =SUM(J29:U29) -> 1114082 | X29: =V29+V70+V194 -> 5782401
B30: A010101060000 | F30: 6 | G30: Petikemas | I30: Call | V30: =SUM(J30:U30) -> 0
B31: A010101060000 | I31: GT | V31: =SUM(J31:U31) -> 0
B32: A010101070000 | F32: 7 | G32: Ro - ro | I32: Call | V32: =SUM(J32:U32) -> 0
B33: A010101070000 | I33: GT | V33: =SUM(J33:U33) -> 0
B34: A010101080000 | F34: 8 | G34: Hewan | I34: Call | V34: =SUM(J34:U34) -> 0
B35: A010101080000 | I35: GT | V35: =SUM(J35:U35) -> 0
B36: A010101090000 | F36: 9 | G36: Cruise (Penumpang Wisata Asing) | I36: Call | V36: =SUM(J36:U36) -> 0
B37: A010101090000 | I37: GT | V37: =SUM(J37:U37) -> 0
B38: A010101100000 | F38: 10 | G38: Penumpang | I38: Call | V38: =SUM(J38:U38) -> 0
B39: A010101100000 | I39: GT | V39: =SUM(J39:U39) -> 0
E41: 2 | F41: Tug Boat dan Tongkang
B42: A010102010000 | F42: 1 | G42: General Cargo | I42: Call | V42: =SUM(J42:U42) -> 0
B43: A010102010000 | I43: GT | V43: =SUM(J43:U43) -> 0
B44: A010102020000 | F44: 2 | G44: Curah Cair BBM | I44: Call | V44: =SUM(J44:U44) -> 0
B45: A010102020000 | I45: GT | V45: =SUM(J45:U45) -> 0
B46: A010102030000 | F46: 3 | G46: Gas | I46: Call | V46: =SUM(J46:U46) -> 0
B47: A010102030000 | I47: GT | V47: =SUM(J47:U47) -> 0
...

Sheet KINERJA
C2: TAHUN (YYYY) : | H2: =ARUS!H2 -> 2026
B4: =ARUS!B4 -> 002 | C4: REGIONAL : | H4: =ARUS!H4 -> Regional.2
B5: =ARUS!B5 -> RegP2
B6: =ARUS!B6 -> 38 | C6: CABANG / TERMINAL : | H6: =ARUS!H6 -> Banten
A8: 1 | C8: Kinerja Pelayanan Kapal
B10: Bulan | J10: 1 | K10: 2 | L10: 3 | M10: 4 | N10: 5 | O10: 6 | P10: 7 | Q10: 8 | R10: 9 | S10: 10 | T10: 11 | U10: 12
C12: No | D12: Uraian | I12: Satuan | J12: =$H$2 -> 2026
J14: Januari | K14: Februari | L14: Maret | M14: April | N14: Mei | O14: Juni | P14: Juli | Q14: Agustus | R14: September | S14: Oktober | T14: November | U14: Desember | V14: Total
C15: 1 | D15: 2 | I15: 3 | J15: 4 | V15: 5
C17: 1 | D17: LUAR NEGERI
B18: E110100000000 | D18: 1 | E18: Waiting Time (WT) for Pilot | I18: Jam | J18: 0 | K18: 0 | L18: 0.011904762 | M18: 0.01 | N18: 0.01 | V18: =IFERROR(AVERAGE(J18:U18),"") -> 0.0063809524
B19: E110200000000 | D19: 2 | E19: Waiting for Berth | I19: Jam | V19: =IFERROR(AVERAGE(J19:U19),"")
B20: E110300000000 | D20: 3 | E20: Postpone Time (PT) | I20: Jam | V20: =IFERROR(AVERAGE(J20:U20),"")
B21: E110400000000 | D21: 4 | E21: Approach Time (AT) | I21: Jam | J21: 0.75 | K21: 0.77 | L21: 0.75277778 | M21: 0.78985507 | N21: 0.69 | V21: =IFERROR(AVERAGE(J21:U21),"") -> 0.75052657
B22: E110500000000 | D22: 5 | E22: Turn Round Time (TRT) | I22: Jam | V22: =IFERROR(AVERAGE(J22:U22),"")
C24: 2 | D24: DALAM NEGERI
B25: E120100000000 | D25: 1 | E25: Waiting Time (WT) for Pilot | I25: Jam | J25: 0.15 | K25: 0.05 | L25: 0.041666667 | M25: 0.01 | N25: 0.01 | V25: =IFERROR(AVERAGE(J25:U25),"") -> 0.052333333
B26: E120200000000 | D26: 2 | E26: Waiting for Berth | I26: Jam | V26: =IFERROR(AVERAGE(J26:U26),"")
B27: E120300000000 | D27: 3 | E27: Postpone Time (PT) | I27: Jam | V27: =IFERROR(AVERAGE(J27:U27),"")
B28: E120400000000 | D28: 4 | E28: Approach Time (AT) | I28: Jam | J28: 0.5 | K28: 0.53 | L28: 0.48104575 | M28: 0.49464832 | N28: 0.53 | V28: =IFERROR(AVERAGE(J28:U28),"") -> 0.50713881
B29: E120500000000 | D29: 5 | E29: Turn Round Time (TRT) | I29: Jam | V29: =IFERROR(AVERAGE(J29:U29),"")
C31: 3 | D31: KONSOLIDASI
B32: E130100000000 | D32: 1 | E32: Waiting Time (WT) for Pilot | I32: Jam | J32: 0.07 | K32: 0.03 | L32: 0.026785714 | M32: 0.01 | N32: 0 | V32: =IFERROR(AVERAGE(J32:U32),"") -> 0.027357143
B33: E130200000000 | D33: 2 | E33: Waiting for Berth | I33: Jam | V33: =IFERROR(AVERAGE(J33:U33),"")
B34: E130300000000 | D34: 3 | E34: Postpone Time (PT) | I34: Jam | V34: =IFERROR(AVERAGE(J34:U34),"")
B35: E130400000000 | D35: 4 | E35: Approach Time (AT) | I35: Jam | J35: 0.62 | K35: 0.65 | L35: 0.61691176 | M35: 0.6422517 | N35: 0.61 | V35: =IFERROR(AVERAGE(J35:U35),"") -> 0.62783269
B36: E130500000000 | D36: 5 | E36: Turn Round Time (TRT) | I36: Jam | V36: =IFERROR(AVERAGE(J36:U36),"")
C38: 4 | D38: KINERJA PELAYANAN DI DUKS / TUKS
B39: E140100000000 | D39: 1 | E39: Waiting Time (WT) for Pilot | I39: Jam | J39: 0.2 | K39: 0.06 | L39: 0.027805774 | M39: 0.013808901 | N39: 0.03 | V39: =IFERROR(AVERAGE(J39:U39),"") -> 0.066322935
B40: E140200000000 | D40: 2 | E40: Waiting for Berth | I40: Jam | V40: =IFERROR(AVERAGE(J40:U40),"")
B41: E140300000000 | D41: 3 | E41: Postpone Time (PT) | I41: Jam | V41: =IFERROR(AVERAGE(J41:U41),"")
B42: E140400000000 | D42: 4 | E42: Approach Time (AT) | I42: Jam | J42: 0.73 | K42: 0.71 | L42: 0.70154681 | M42: 0.6946226 | N42: 0.68 | V42: =IFERROR(AVERAGE(J42:U42),"") -> 0.70323388
B43: E140500000000 | D43: 5 | E43: Turn Round Time (TRT) | I43: Jam | V43: =IFERROR(AVERAGE(J43:U43),"")
A45: 2 | C45: Kinerja Pelayanan Tambatan
C47: No | D47: Uraian | I47: Satuan | J47: =$H$2 -> 2026
J49: Januari | K49: Februari | L49: Maret | M49: April | N49: Mei | O49: Juni | P49: Juli | Q49: Agustus | R49: September | S49: Oktober | T49: November | U49: Desember | V49: Total
C50: 1 | D50: 2 | I50: 3 | J50: 4 | V50: 5
C52: 1 | D52: LUAR NEGERI
D53: 1 | E53: Terminal Petikemas
B54: F110101000000 | E54: 1 | F54: Berthing Time (BT) | I54: Jam | V54: =IFERROR(AVERAGE(J54:U54),"")
...

Sheet UTILISASI
C2: TAHUN (YYYY) : | H2: =ARUS!H2 -> 2026
B4: =ARUS!B4 -> 002 | C4: REGIONAL : | H4: =ARUS!H4 -> Regional.2
B5: =ARUS!B5 -> RegP2
B6: =ARUS!B6 -> 38 | C6: CABANG / TERMINAL : | H6: =ARUS!H6 -> Banten
A8: 1 | C8: Utilisasi Infrastruktur
B10: Bulan | J10: 1 | K10: 2 | L10: 3 | M10: 4 | N10: 5 | O10: 6 | P10: 7 | Q10: 8 | R10: 9 | S10: 10 | T10: 11 | U10: 12
C12: No | D12: Uraian | I12: Satuan | J12: =$H$2 -> 2026
J14: Januari | K14: Februari | L14: Maret | M14: April | N14: Mei | O14: Juni | P14: Juli | Q14: Agustus | R14: September | S14: Oktober | T14: November | U14: Desember | V14: Total
C15: 1 | D15: 2 | I15: 3 | J15: 4 | V15: 5
C17: 1 | D17: Terminal Petikemas
B18: A21010000 | D18: 1 | E18: BOR | I18: %
B19: A21020000 | D19: 2 | E19: YOR | I19: % | V19: =IFERROR(AVERAGE(J19:U19),"")
C21: 2 | D21: Terminal Multipurpose
B22: A22010000 | D22: 1 | E22: BOR | I22: % | J22: 22.62 | K22: 14.34 | L22: 13.28 | M22: 20.55 | N22: 21.94
B23: A22030000 | D23: 2 | E23: YOR | I23: % | L23: 4.72 | M23: 6.82 | N23: 1.36
B24: A22050000 | D24: 3 | E24: SOR | I24: %
C26: 3 | D26: Terminal Curah Cair
B27: A23010000 | E27: BOR | I27: % | J27: 47.69 | K27: 35.37 | L27: 47.88 | M27: 31.29 | N27: 24.31
C29: 4 | D29: Terminal Curah Kering
B30: A24010000 | D30: 1 | E30: BOR | I30: % | J30: 8.8 | K30: 50.61 | L30: 29.8 | M30: 28.36 | N30: 41.49
B31: A24020000 | D31: 2 | E31: YOR | I31: %
B32: A24030000 | D32: 3 | E32: SOR | I32: % | J32: 10.43 | K32: 28.24 | L32: 66.82 | M32: 49.22 | N32: 59.61
C34: 5 | D34: Terminal Kendaraan
B35: A25010000 | D35: 1 | E35: BOR | I35: %
B36: A25020000 | D36: 2 | E36: YOR | I36: %
C38: 6 | D38: Terminal Pelra
B39: A26010000 | D39: 1 | E39: BOR | I39: %
B40: A26020000 | D40: 2 | E40: YOR | I40: %
B41: A26030000 | D41: 3 | E41: SOR Gudang Multipurpose | I41: %
B42: A26040000 | D42: 4 | E42: SOR Gudang CFS | I42: %
A44: 2 | C44: Utilisasi Suprastruktur
C46: No | D46: Uraian | I46: Satuan | J46: =$H$2 -> 2026
J48: Januari | K48: Februari | L48: Maret | M48: April | N48: Mei | O48: Juni | P48: Juli | Q48: Agustus | R48: September | S48: Oktober | T48: November | U48: Desember | V48: Total
C49: 1 | D49: 2 | I49: 3 | J49: 4 | V49: 5
C51: 1 | D51: Pelayanan Kapal
D52: 1 | E52: Kesiapan alat apung
B53: B21010100 | E53: 1 | F53: Kapal Tunda | I53: % | J53: 98.16 | K53: 100 | L53: 100 | M53: 100 | N53: 100 | V53: =IFERROR(AVERAGE(J53:U53),"") -> 99.632
B54: B21010200 | E54: 2 | F54: Kapal Pandu | I54: % | V54: =IFERROR(AVERAGE(J54:U54),"")
B55: B21010300 | E55: 3 | F55: Kapal Kepil | I55: % | V55: =IFERROR(AVERAGE(J55:U55),"")
B56: B21010400 | E56: 4 | F56: Kapal Keruk | I56: % | V56: =IFERROR(AVERAGE(J56:U56),"")
...

Sheet PRODUKSI
C2: TAHUN (YYYY) : | H2: =ARUS!H2 -> 2026
B4: =ARUS!B4 -> 002 | C4: REGIONAL : | H4: =ARUS!H4 -> Regional.2
B5: =ARUS!B5 -> RegP2
B6: =ARUS!B6 -> 38 | C6: CABANG / TERMINAL : | H6: =ARUS!H6 -> Banten
B10: Bulan | J10: 1 | K10: 2 | L10: 3 | M10: 4 | N10: 5 | O10: 6 | P10: 7 | Q10: 8 | R10: 9 | S10: 10 | T10: 11 | U10: 12
C12: No | D12: Uraian | I12: Satuan | J12: =$H$2 -> 2026
J14: Januari | K14: Februari | L14: Maret | M14: April | N14: Mei | O14: Juni | P14: Juli | Q14: Agustus | R14: September | S14: Oktober | T14: November | U14: Desember | V14: Total
C15: 1 | D15: 2 | I15: 3 | J15: 4 | V15: 5
C17: 1 | D17: PELAYANAN KAPAL
B18: 401.01.00.00.00.00.00.00.00 | D18: 1 | E18: Pelayanan Labuh | I18: GT Masa | V18: =SUM(J18:U18) -> 0
B19: 401.02.00.00.00.00.00.00.00 | D19: 2 | E19: Pelayanan Pemanduan | I19: Kpl Grk | J19: 142 | K19: 154 | L19: 144 | M19: 174 | N19: 176 | V19: =SUM(J19:U19) -> 790
B20: 401.02.00.00.00.00.00.00.00 | I20: GT Kpl Grk | J20: 1120954 | K20: 1280611 | L20: 1018961 | M20: 1540988 | N20: 1424641 | V20: =SUM(J20:U20) -> 6386155
B21: 401.03.00.00.00.00.00.00.00 | D21: 3 | E21: Pelayanan Penundaan | I21: Kpl Jam | J21: 378 | K21: 418.08 | L21: 358.93333 | M21: 462.28333 | N21: 475.37 | V21: =SUM(J21:U21) -> 2092.6667
B22: 401.03.00.00.00.00.00.00.00 | I22: GT Kpl Jam | J22: 3335668 | K22: 3935110 | L22: 2902863.8 | M22: 4574939.1 | N22: 4114191.9 | V22: =SUM(J22:U22) -> 18862773
B23: 401.04.00.00.00.00.00.00.00 | D23: 4 | E23: Pelayanan Penambatan | I23: GT Etmal | J23: 905797 | K23: 1543132 | L23: 2134167 | M23: 1489560 | N23: 1642099.2 | V23: =SUM(J23:U23) -> 7714755.2
B24: 401.04.00.00.00.00.00.00.00 | I24: Unit | V24: =SUM(J24:U24) -> 0
B25: 401.05.00.00.00.00.00.00.00 | D25: 5 | E25: Pelayanan Alur | I25: GT | V25: =SUM(J25:U25) -> 0
B26: 401.05.00.00.00.00.00.00.00 | I26: Ton | V26: =SUM(J26:U26) -> 0
B27: 401.05.00.00.00.00.00.00.00 | I27: M3 | V27: =SUM(J27:U27) -> 0
B28: 401.05.00.00.00.00.00.00.00 | I28: Box | V28: =SUM(J28:U28) -> 0
B29: 401.06.00.00.00.00.00.00.00 | D29: 6 | E29: Pelayanan Kepil | I29: Grk | V29: =SUM(J29:U29) -> 0
B30: 401.06.00.00.00.00.00.00.00 | I30: GT | V30: =SUM(J30:U30) -> 0
B31: 401.06.00.00.00.00.00.00.00 | I31: Kpl Jam | V31: =SUM(J31:U31) -> 0
C33: 2 | D33: PELAYANAN PETIKEMAS
D34: 1 | E34: Pelayanan Petikemas Internasional
B35: 402.01.01.00.00.00.00.00.00 | E35: 1 | F35: Dermaga | I35: Box | V35: =SUM(J35:U35) -> 0
B36: 402.01.01.00.00.00.00.00.00 | I36: Ton | V36: =SUM(J36:U36) -> 0
B37: 402.01.01.00.00.00.00.00.00 | I37: M3 | V37: =SUM(J37:U37) -> 0
B38: 402.01.01.00.00.00.00.00.00 | I38: Unit | V38: =SUM(J38:U38) -> 0
E39: 2 | F39: Operasi Kapal
B40: 402.01.02.01.00.00.00.00.00 | F40: 1 | G40: Stevedoring | I40: Box | V40: =SUM(J40:U40) -> 0
B41: 402.01.02.01.00.00.00.00.00 | I41: Ton | V41: =SUM(J41:U41) -> 0
B42: 402.01.02.01.00.00.00.00.00 | I42: M3 | V42: =SUM(J42:U42) -> 0
B43: 402.01.02.01.00.00.00.00.00 | I43: Unit | V43: =SUM(J43:U43) -> 0
B44: 402.01.02.02.00.00.00.00.00 | F44: 2 | G44: Lift On/Lift Off | I44: Box | V44: =SUM(J44:U44) -> 0
B45: 402.01.02.03.00.00.00.00.00 | F45: 3 | G45: Haulage | I45: Box | V45: =SUM(J45:U45) -> 0
B46: 402.01.02.04.00.00.00.00.00 | F46: 4 | G46: Restowage/Shifting | I46: Box | V46: =SUM(J46:U46) -> 0
B47: 402.01.02.05.00.00.00.00.00 | F47: 5 | G47: Buka Tutup Palka | I47: Palka | V47: =SUM(J47:U47) -> 0
B48: 402.01.02.05.00.00.00.00.00 | I48: Unit | V48: =SUM(J48:U48) -> 0
B49: 402.01.02.05.00.00.00.00.00 | I49: Kegiatan | V49: =SUM(J49:U49) -> 0
...
