Workbook

Sheet Sheet1
C2: Executive Summary | J2: 6 | K2: 7
C3: Keterangan | D3: Satuan | E3: Realisasi 2025 | F3: Realisasi s.d Mei 2026 | G3: RKAP 2026 | H3: Indikasi Prognosa 2026 | I3: Indikasi Usulan RKAP 2027 | J3: Prognosa 2026 | K3: Usulan 2027 | L3: Summary | O3: Kesesuaian dengan Indikasi
E4: 1 | F4: 2 | G4: 3 | J4: 4 | K4: 5 | L4: 8=6/1 | M4: 9=7/1 | N4: 10=7/6 | O4: 10=7/6 | P4: 10=7/6
C5: Pendapatan Bersih* | D5: IDR Juta | E5: 1000000 | F5: 550000 | G5: 1100000 | H5: 1149000 | I5: 1195000 | J5: 1150000 | K5: 1200000 | L5: =J5/E5 -> 1.15 | M5: =K5/E5 -> 1.2 | N5: =K5/J5 -> 1.0434783 | O5: =IF(J5>=H5,"Sesuai","Belum") -> Sesuai | P5: =IF(K5>=I5,"Sesuai","Belum") -> Sesuai
C6: BOPO* | D6: Persentase | E6: 0.547 | F6: 53.5 | G6: 0.54 | H6: 0.5415 | I6: 0.531 | J6: 0.541 | K6: 0.532 | L6: =J6-E6 -> -0.006 | M6: =K6-E6 -> -0.015 | N6: =K6-J6 -> -0.009 | O6: =IF(J6<=H6,"Sesuai","Belum") -> Sesuai | P6: =IF(K6<=I6,"Sesuai","Belum") -> Belum
C7: Laba Bersih | D7: IDR Juta | E7: 551230 | F7: 267500 | G7: 570000 | J7: 566845 | K7: 577231 | L7: =J7/E7 -> 1.0283276 | M7: =K7/E7 -> 1.0471691 | N7: =K7/J7 -> 1.0183225
C8: Arus Kapal DN | D8: GT Juta | E8: 153 | F8: 62 | G8: 155 | J8: 150 | K8: 165 | L8: =J8/E8 -> 0.98039216 | M8: =K8/E8 -> 1.0784314 | N8: =K8/J8 -> 1.1
C9: Arus Kapal LN | D9: GT Juta | E9: 110 | F9: 45 | G9: 112 | J9: 108 | K9: 115 | L9: =J9/E9 -> 0.98181818 | M9: =K9/E9 -> 1.0454545 | N9: =K9/J9 -> 1.0648148
C10: Lahan dikerjasamakan Clean & Clear | D10: M2 | E10: 5300 | F10: 5300 | J10: =F10+300 -> 5600 | K10: 5600 | L10: =J10-E10 -> 300 | M10: =K10-E10 -> 300 | N10: =K10-J10 -> 0
C11: Lahan dikerjasamakan bermasalah | D11: M2 | E11: 20 | F11: 20 | J11: 20 | K11: 0 | L11: =J11-E11 -> 0 | M11: =K11-E11 -> -20 | N11: =K11-J11 -> -20
C12: Lahan Idle Bermasalah | D12: M2 | E12: 300 | F12: 300 | J12: 250 | K12: 220 | L12: =J12-E12 -> -50 | M12: =K12-E12 -> -80 | N12: =K12-J12 -> -30
C13: Lahan Idle Clean & Clear | D13: M2 | E13: 950 | F13: 950 | J13: 700 | K13: 730 | L13: =J13-E13 -> -250 | M13: =K13-E13 -> -220 | N13: =K13-J13 -> 30
C14: Lahan Digunakan Sendiri | D14: M2 | E14: 45 | F14: 45 | J14: 45 | K14: 45 | L14: =J14-E14 -> 0 | M14: =K14-E14 -> 0 | N14: =K14-J14 -> 0
C15: Lahan Lainnya* | D15: M2 | E15: 40 | F15: 40 | J15: 40 | K15: 40
C16: Total Lahan | D16: M2 | E16: =SUM(E10:E15) -> 6655 | F16: =SUM(F10:F15) -> 6655 | J16: =SUM(J10:J15) -> 6655 | K16: =SUM(K10:K15) -> 6635 | L16: =J16-E16 -> 0 | M16: =K16-E16 -> -20 | N16: =K16-J16 -> -20
C17: Pegawai Organik | D17: Personel | E17: 134 | F17: 133 | G17: 135 | J17: 133 | K17: 136 | L17: =J17-E17 -> -1 | M17: =K17-E17 -> 2 | N17: =K17-J17 -> 3
C18: TAD | D18: Personel | E18: 50 | F18: 50 | G18: 51 | J18: 49 | K18: 48 | L18: =J18-E18 -> -1 | M18: =K18-E18 -> -2 | N18: =K18-J18 -> -1
C19: Security | D19: Personel | E19: 33 | F19: 32 | G19: 34 | J19: 34 | K19: 38 | L19: =J19-E19 -> 1 | M19: =K19-E19 -> 5 | N19: =K19-J19 -> 4
C20: Jumlah Aset Relokasi | D20: item | E20: 3 | F20: 0 | J20: 2 | K20: 3 | L20: =J20-E20 -> -1 | M20: =K20-E20 -> 0 | N20: =K20-J20 -> 1
C22: * Pendapatan bersih diluar pendapatan revenue sharing
C23: *BOPO = (Beban Usaha-Beban Revenue Sharing- Beban Penyusutan/Amortisasi - Beban Penyisihan Piutang Afiliasi)/ (Pendapatan Usaha Bersih - Pendapatan Revenue sharing)
Q25: Laba Rugi
Q26: URAIAN | S26: Realisasi Tahun 2025 | T26: RKAP 2026 | U26: Realissi s.d Mei 2026 | V26: Prognosa 2026 | W26: Usulan 2027 | X26: Summary
S27: 1 | T27: 2 | U27: 3 | V27: 4 | W27: 5 | X27: 6=5/1 | Y27: 7=4/1 | Z27: 8=5/4
Q28: Pendapatan Usaha
Q29: Reduksi Pendapatan Pelayanan Kapal | R29: Pelayanan Kapal | S29: 810862639326 | T29: 865955395270 | U29: =T29/12*5 -> 3.6081475e+11 | V29: 961497004235 | W29: 1.09137e+12 | X29: =IF(ISERROR(W29/S29),0,W29/S29) -> 1.345937 | Y29: =IF(ISERROR(V29/S29),0,V29/S29) -> 1.1857705 | Z29: =IF(ISERROR(W29/V29),0,W29/V29) -> 1.1350737
Q30: Reduksi Pendapatan Pelayanan TUKS | R30: Pendapatan Pelayanan Terminal UKS | S30: 0 | T30: 14132982107 | U30: =T30/12*5 -> 5.8887425e+09 | V30: 30961430082 | W30: 3.932878e+10 | X30: =IF(ISERROR(W30/S30),0,W30/S30) -> 0 | Y30: =IF(ISERROR(V30/S30),0,V30/S30) -> 0 | Z30: =IF(ISERROR(W30/V30),0,W30/V30) -> 1.2702507
Q31: Reduksi Pendapatan Pelayanan Pelsus | R31: Pelayanan pelra | S31: 0 | T31: 0 | U31: =T31/12*5 -> 0 | V31: 0 | W31: 0 | X31: =IF(ISERROR(W31/S31),0,W31/S31) -> 0 | Y31: =IF(ISERROR(V31/S31),0,V31/S31) -> 0 | Z31: =IF(ISERROR(W31/V31),0,W31/V31) -> 0
Q32: Reduksi Pendapatan Pelayanan Pelra | R32: Pendapatan Marine | S32: 0 | T32: 0 | U32: =T32/12*5 -> 0 | V32: 0 | W32: 0 | X32: =IF(ISERROR(W32/S32),0,W32/S32) -> 0 | Y32: =IF(ISERROR(V32/S32),0,V32/S32) -> 0 | Z32: =IF(ISERROR(W32/V32),0,W32/V32) -> 0
R33: Pendapatan Pelsus, Tersus, dan Dersus | S33: 0 | T33: 0 | U33: =T33/12*5 -> 0 | V33: 0 | W33: 0 | X33: =IF(ISERROR(W33/S33),0,W33/S33) -> 0 | Y33: =IF(ISERROR(V33/S33),0,V33/S33) -> 0 | Z33: =IF(ISERROR(W33/V33),0,W33/V33) -> 0
R34: Total Pendapatan Kapal | S34: =SUM(S29:S33) -> 810862639326 | T34: =SUM(T29:T33) -> 880088377377 | U34: =SUM(U29:U33) -> 3.6670349e+11 | V34: =SUM(V29:V33) -> 992458434317 | W34: =SUM(W29:W33) -> 1.1306988e+12 | X34: =IF(ISERROR(W34/S34),0,W34/S34) -> 1.3944394 | Y34: =IF(ISERROR(V34/S34),0,V34/S34) -> 1.2239538 | Z34: =IF(ISERROR(W34/V34),0,W34/V34) -> 1.1392908
Q35: Reduksi Pendapatan Pelayanan Petikemas | R35: Pelayanan Petikemas | S35: 45048696500 | T35: 51360511500 | U35: =T35/12*5 -> 21400213125 | V35: 100900291000 | W35: 1.0657546e+11 | X35: =IF(ISERROR(W35/S35),0,W35/S35) -> 2.3657833 | Y35: =IF(ISERROR(V35/S35),0,V35/S35) -> 2.2398049 | Z35: =IF(ISERROR(W35/V35),0,W35/V35) -> 1.0562453
Q36: Reduksi Pendapatan Barang Non Petikemas | R36: Pendapatan Barang Non Petikemas | S36: 86072813121 | T36: 75799168087 | U36: =T36/12*5 -> 3.1582987e+10 | V36: 75678681014 | W36: 5.5659741e+10 | X36: =IF(ISERROR(W36/S36),0,W36/S36) -> 0.64665879 | Y36: =IF(ISERROR(V36/S36),0,V36/S36) -> 0.87924024 | Z36: =IF(ISERROR(W36/V36),0,W36/V36) -> 0.73547451
Q37: Reduksi Pendapatan Konsolidasi dan Distribusi Barang | R37: Pelayanan Konsolidasi dan Distribusi Barang | S37: 0 | T37: 0 | U37: =T37/12*5 -> 0 | V37: 0 | W37: 0 | X37: =IF(ISERROR(W37/S37),0,W37/S37) -> 0 | Y37: =IF(ISERROR(V37/S37),0,V37/S37) -> 0 | Z37: =IF(ISERROR(W37/V37),0,W37/V37) -> 0
Q38: Reduksi Pendapatan Pengusahaan Alat | R38: Pendapatan Pengusahaan Alat | S38: 0 | T38: 0 | U38: =T38/12*5 -> 0 | V38: 0 | W38: 0 | X38: =IF(ISERROR(W38/S38),0,W38/S38) -> 0 | Y38: =IF(ISERROR(V38/S38),0,V38/S38) -> 0 | Z38: =IF(ISERROR(W38/V38),0,W38/V38) -> 0
Q39: Reduksi Pendapatan Pengusahaan Properti | R39: Pendapatan Pengusahaan Properti | S39: 431942664108 | T39: 459329580716 | U39: =T39/12*5 -> 1.9138733e+11 | V39: 480400759634 | W39: 4.552194e+11 | X39: =IF(ISERROR(W39/S39),0,W39/S39) -> 1.0538885 | Y39: =IF(ISERROR(V39/S39),0,V39/S39) -> 1.1121864 | Z39: =IF(ISERROR(W39/V39),0,W39/V39) -> 0.9475826
Q40: Reduksi Pendapatan Pengusahaan Air / Listrik | R40: Pendapatan Pengusahaan Air / Listrik | S40: 22363776 | T40: 103046784 | U40: =T40/12*5 -> 42936160 | V40: 228079275 | W40: 0 | X40: =IF(ISERROR(W40/S40),0,W40/S40) -> 0 | Y40: =IF(ISERROR(V40/S40),0,V40/S40) -> 10.198603 | Z40: =IF(ISERROR(W40/V40),0,W40/V40) -> 0
Q41: Reduksi Pendapatan Rupa-Rupa Usaha | R41: Pelayanan Rupa-Rupa Usaha | S41: 639015023272 | T41: 652634177971 | U41: =T41/12*5 -> 2.7193091e+11 | V41: 859478218593 | W41: 7.3108951e+11 | X41: =IF(ISERROR(W41/S41),0,W41/S41) -> 1.1440881 | Y41: =IF(ISERROR(V41/S41),0,V41/S41) -> 1.3450047 | Z41: =IF(ISERROR(W41/V41),0,W41/V41) -> 0.85062017
R42: Pelayanan Rupa-Rupa Managemen fee | S42: 301015023272 | T42: 332634177971 | U42: 141200177811 | V42: 3.3888043e+11 | W42: 2.8825853e+11 | X42: =IF(ISERROR(W42/S42),0,W42/S42) -> 0.95762173 | Y42: =IF(ISERROR(V42/S42),0,V42/S42) -> 1.1257924 | Z42: =IF(ISERROR(W42/V42),0,W42/V42) -> 0.85062017
R43: Pelayanan Rupa-Rupa lainnya | S43: =S41-S42 -> 338000000000 | T43: =T41-T42 -> 320000000000 | U43: =U41-U42 -> 1.3073073e+11 | V43: =V41-V42 -> 5.2059779e+11 | W43: =W41-W42 -> 4.4283098e+11 | X43: =IF(ISERROR(W43/S43),0,W43/S43) -> 1.3101508 | Y43: =IF(ISERROR(V43/S43),0,V43/S43) -> 1.5402302 | Z43: =IF(ISERROR(W43/V43),0,W43/V43) -> 0.85062017
...

Sheet Operasi
C3: URAIAN | D3: SATUAN | E3: REALISASI 2025 | F3: RKAP 2026 | G3: Realisasi s.d Maret 2026 | H3: PROGNOSA 2026 | I3: USULAN RKAP 2027
E4: Trafik | F4: Trafik | G4: Trafik | H4: Trafik | I4: Trafik
C5: UMUM Dalam Negeri | D5: Call | E5: ='Trafik vs Pend'!E5 -> 806 | F5: ='Trafik vs Pend'!F5 -> 674 | G5: ='Trafik vs Pend'!G5 -> 634 | H5: ='Trafik vs Pend'!H5 -> 1421 | I5: ='Trafik vs Pend'!I5 -> 1449.42
D6: GT | E6: ='Trafik vs Pend'!E6 -> 2619161 | F6: ='Trafik vs Pend'!F6 -> 2508863.2 | G6: ='Trafik vs Pend'!G6 -> 1338067 | H6: ='Trafik vs Pend'!H6 -> 3111361 | I6: ='Trafik vs Pend'!I6 -> 3173588.2
C7: UMUM Luar Negeri | D7: Call | E7: ='Trafik vs Pend'!E7 -> 184 | F7: ='Trafik vs Pend'!F7 -> 180 | G7: ='Trafik vs Pend'!G7 -> 98 | H7: ='Trafik vs Pend'!H7 -> 225 | I7: ='Trafik vs Pend'!I7 -> 229.5
D8: GT | E8: ='Trafik vs Pend'!E8 -> 3691444 | F8: ='Trafik vs Pend'!F8 -> 3556185.8 | G8: ='Trafik vs Pend'!G8 -> 1964950 | H8: ='Trafik vs Pend'!H8 -> 4615880 | I8: ='Trafik vs Pend'!I8 -> 4708197.6
C9: Total Trafik Dermaga Umum | D9: Call | E9: =SUM(E5,E7) -> 990 | F9: =SUM(F5,F7) -> 854 | G9: =SUM(G5,G7) -> 732 | H9: =SUM(H5,H7) -> 1646 | I9: =SUM(I5,I7) -> 1678.92
D10: GT | E10: =SUM(E6,E8) -> 6310605 | F10: =SUM(F6,F8) -> 6065049 | G10: =SUM(G6,G8) -> 3303017 | H10: =SUM(H6,H8) -> 7727241 | I10: =SUM(I6,I8) -> 7881785.8
C11: Total Pendapatan Pandu, Tunda, Tambat di Dermaga Umum | D11: IDR Juta | E11: ='Trafik vs Pend'!E11 -> 95048178375 | F11: ='Trafik vs Pend'!F11 -> 98940555039 | G11: ='Trafik vs Pend'!G11 -> 29181123591 | H11: ='Trafik vs Pend'!H11 -> 128801886656 | I11: ='Trafik vs Pend'!I11 -> 1.3624062e+11
C12: TUKS Dalam Negeri | D12: Call | E12: ='Trafik vs Pend'!E12 -> 3639 | F12: ='Trafik vs Pend'!F12 -> 4308 | G12: ='Trafik vs Pend'!G12 -> 1218 | H12: ='Trafik vs Pend'!H12 -> 3343 | I12: ='Trafik vs Pend'!I12 -> 3409.86
D13: GT | E13: ='Trafik vs Pend'!E13 -> 22673573 | F13: ='Trafik vs Pend'!F13 -> 26778183 | G13: ='Trafik vs Pend'!G13 -> 9771942 | H13: ='Trafik vs Pend'!H13 -> 23452661 | I13: ='Trafik vs Pend'!I13 -> 23921714
C14: TUKS Luar Negeri | D14: Call | E14: ='Trafik vs Pend'!E14 -> 543 | F14: ='Trafik vs Pend'!F14 -> 510 | G14: ='Trafik vs Pend'!G14 -> 247 | H14: ='Trafik vs Pend'!H14 -> 582 | I14: ='Trafik vs Pend'!I14 -> 593.64
D15: GT | E15: ='Trafik vs Pend'!E15 -> 9889101 | F15: ='Trafik vs Pend'!F15 -> 9644471 | G15: ='Trafik vs Pend'!G15 -> 4308561 | H15: ='Trafik vs Pend'!H15 -> 10240546 | I15: ='Trafik vs Pend'!I15 -> 10445357
C16: Total Trafik Dermaga Khusus | D16: Call | E16: =SUM(E12,E14) -> 4182 | F16: =SUM(F12,F14) -> 4818 | G16: =SUM(G12,G14) -> 1465 | H16: =SUM(H12,H14) -> 3925 | I16: =SUM(I12,I14) -> 4003.5
D17: GT | E17: =SUM(E13,E15) -> 32562674 | F17: =SUM(F13,F15) -> 36422654 | G17: =SUM(G13,G15) -> 14080503 | H17: =SUM(H13,H15) -> 33693207 | I17: =SUM(I13,I15) -> 34367071
C18: Total Pendapatan Pandu, Tunda, Tambat di Dermaga Khusus | D18: IDR Juta | E18: ='Trafik vs Pend'!E18 -> 224964602823 | F18: ='Trafik vs Pend'!F18 -> 2.472931e+11 | G18: ='Trafik vs Pend'!G18 -> 72792039360 | H18: ='Trafik vs Pend'!H18 -> 206339039425 | I18: 5583.0996
C19: Total Trafik | D19: Call | E19: =SUM(E9,E16) -> 5172 | F19: =SUM(F9,F16) -> 5672 | G19: =SUM(G9,G16) -> 2197 | H19: =SUM(H9,H16) -> 5571 | I19: =SUM(I9,I16) -> 5682.42
D20: GT | E20: =SUM(E10,E17) -> 38873279 | F20: =SUM(F10,F17) -> 42487703 | G20: =SUM(G10,G17) -> 17383520 | H20: =SUM(H10,H17) -> 41420448 | I20: =SUM(I10,I17) -> 42248857
C21: Total Pendapatan Kapal | D21: IDR Juta | E21: =E11+E18 -> 320012781198 | F21: =F11+F18 -> 3.4623366e+11 | G21: =G11+G18 -> 101973162951 | H21: =H11+H18 -> 335140926081 | I21: =I11+I18 -> 1.3624063e+11

Sheet Executive Summary
C2: Executive Summary
C3: Keterangan | D3: Satuan | E3: Realisasi 2025 | F3: Realisasi s.d Mei 2026 | G3: RKAP 2026 | H3: Indikasi Prognosa 2026 | I3: Indikasi Usulan RKAP 2027 | J3: Prognosa 2026 | K3: Usulan 2027 | L3: Summary | O3: Kesesuaian dengan Indikasi
E4: 1 | F4: 2 | G4: 3 | J4: 4 | K4: 5 | L4: 8=6/1 | M4: 9=7/1 | N4: 10=7/6 | O4: 10=7/6 | P4: 10=7/6
C5: Pendapatan Bersih* | D5: IDR Juta | E5: 1000000 | F5: 550000 | G5: 1100000 | H5: 1149000 | I5: 1195000 | J5: 1150000 | K5: 1200000 | L5: =J5/E5 -> 1.15 | M5: =K5/E5 -> 1.2 | N5: =K5/J5 -> 1.0434783 | O5: =IF(J5>=H5,"Sesuai","Belum") -> Sesuai | P5: =IF(K5>=I5,"Sesuai","Belum") -> Sesuai
C6: BOPO* | D6: Persentase | E6: 0.547 | F6: 53.5 | G6: 0.54 | H6: 0.5415 | I6: 0.531 | J6: 0.541 | K6: 0.532 | L6: =J6-E6 -> -0.006 | M6: =K6-E6 -> -0.015 | N6: =K6-J6 -> -0.009 | O6: =IF(J6<=H6,"Sesuai","Belum") -> Sesuai | P6: =IF(K6<=I6,"Sesuai","Belum") -> Belum
C7: Laba Bersih | D7: IDR Juta | E7: 551230 | F7: 267500 | G7: 570000 | J7: 566845 | K7: 577231 | L7: =J7/E7 -> 1.0283276 | M7: =K7/E7 -> 1.0471691 | N7: =K7/J7 -> 1.0183225
C8: Arus Kapal DN | D8: GT Juta | E8: 153 | F8: 62 | G8: 155 | J8: 150 | K8: 165 | L8: =J8/E8 -> 0.98039216 | M8: =K8/E8 -> 1.0784314 | N8: =K8/J8 -> 1.1
C9: Arus Kapal LN | D9: GT Juta | E9: 110 | F9: 45 | G9: 112 | J9: 108 | K9: 115 | L9: =J9/E9 -> 0.98181818 | M9: =K9/E9 -> 1.0454545 | N9: =K9/J9 -> 1.0648148
C10: Lahan dikerjasamakan Clean & Clear | D10: M2 | E10: 5300 | F10: 5300 | J10: =F10+300 -> 5600 | K10: 5600 | L10: =J10-E10 -> 300 | M10: =K10-E10 -> 300 | N10: =K10-J10 -> 0
C11: Lahan dikerjasamakan bermasalah | D11: M2 | E11: 20 | F11: 20 | J11: 20 | K11: 0 | L11: =J11-E11 -> 0 | M11: =K11-E11 -> -20 | N11: =K11-J11 -> -20
C12: Lahan Idle Bermasalah | D12: M2 | E12: 300 | F12: 300 | J12: 250 | K12: 220 | L12: =J12-E12 -> -50 | M12: =K12-E12 -> -80 | N12: =K12-J12 -> -30
C13: Lahan Idle Clean & Clear | D13: M2 | E13: 950 | F13: 950 | J13: 700 | K13: 730 | L13: =J13-E13 -> -250 | M13: =K13-E13 -> -220 | N13: =K13-J13 -> 30
C14: Lahan Digunakan Sendiri | D14: M2 | E14: 45 | F14: 45 | J14: 45 | K14: 45 | L14: =J14-E14 -> 0 | M14: =K14-E14 -> 0 | N14: =K14-J14 -> 0
C15: Lahan Lainnya* | D15: M2 | E15: 40 | F15: 40 | J15: 40 | K15: 40
C16: Total Lahan | D16: M2 | E16: =SUM(E10:E15) -> 6655 | F16: =SUM(F10:F15) -> 6655 | J16: =SUM(J10:J15) -> 6655 | K16: =SUM(K10:K15) -> 6635 | L16: =J16-E16 -> 0 | M16: =K16-E16 -> -20 | N16: =K16-J16 -> -20
C17: Pegawai Organik | D17: Personel | E17: 134 | F17: 133 | G17: 135 | J17: 133 | K17: 136 | L17: =J17-E17 -> -1 | M17: =K17-E17 -> 2 | N17: =K17-J17 -> 3
C18: TAD | D18: Personel | E18: 50 | F18: 50 | G18: 51 | J18: 49 | K18: 48 | L18: =J18-E18 -> -1 | M18: =K18-E18 -> -2 | N18: =K18-J18 -> -1
C19: Security | D19: Personel | E19: 33 | F19: 32 | G19: 34 | J19: 34 | K19: 38 | L19: =J19-E19 -> 1 | M19: =K19-E19 -> 5 | N19: =K19-J19 -> 4
C20: Jumlah Aset Relokasi | D20: item | E20: 3 | F20: 0 | J20: 2 | K20: 3 | L20: =J20-E20 -> -1 | M20: =K20-E20 -> 0 | N20: =K20-J20 -> 1
C22: * Pendapatan bersih diluar pendapatan revenue sharing
C23: *BOPO = (Beban Usaha-Beban Revenue Sharing- Beban Penyusutan/Amortisasi - Beban Penyisihan Piutang Afiliasi)/ (Pendapatan Usaha Bersih - Pendapatan Revenue sharing)

Sheet Laba Rugi
B2: Laba Rugi
B3: URAIAN | D3: Realisasi Tahun 2025 | E3: RKAP 2026 | F3: Realissi s.d Maret 2026 | G3: Prognosa 2026 | H3: Usulan 2027 | I3: Summary
D4: 1 | E4: 2 | F4: 3 | G4: 4 | H4: 5 | I4: 6=5/1 | J4: 7=4/1 | K4: 8=5/4
B5: Pendapatan Usaha
B6: Reduksi Pendapatan Pelayanan Kapal | C6: Pelayanan Kapal | D6: ='Trafik vs Pend'!E11 -> 95048178375 | E6: ='Trafik vs Pend'!F11 -> 98940555039 | F6: ='Trafik vs Pend'!G11 -> 29181123591 | G6: ='Trafik vs Pend'!H11 -> 128801886656 | H6: ='Trafik vs Pend'!I11 -> 1.3624062e+11 | I6: =IF(ISERROR(H6/D6),0,H6/D6) -> 1.4333849 | J6: =IF(ISERROR(G6/D6),0,G6/D6) -> 1.3551221 | K6: =IF(ISERROR(H6/G6),0,H6/G6) -> 1.0577533
B7: Reduksi Pendapatan Pelayanan TUKS | C7: Pendapatan Pelayanan Terminal UKS | D7: ='Trafik vs Pend'!E18 -> 224964602823 | E7: ='Trafik vs Pend'!F18 -> 2.472931e+11 | F7: ='Trafik vs Pend'!G18 -> 72792039360 | G7: ='Trafik vs Pend'!H18 -> 206339039425 | H7: ='Trafik vs Pend'!I18 -> 2.1148139e+11 | I7: =IF(ISERROR(H7/D7),0,H7/D7) -> 0.94006518 | J7: =IF(ISERROR(G7/D7),0,G7/D7) -> 0.91720669 | K7: =IF(ISERROR(H7/G7),0,H7/G7) -> 1.0249219
B8: Reduksi Pendapatan Pelayanan Pelsus | C8: Pelayanan pelra | D8: 0 | E8: 0 | F8: =E8/12*5 -> 0 | G8: 0 | H8: 0 | I8: =IF(ISERROR(H8/D8),0,H8/D8) -> 0 | J8: =IF(ISERROR(G8/D8),0,G8/D8) -> 0 | K8: =IF(ISERROR(H8/G8),0,H8/G8) -> 0
B9: Reduksi Pendapatan Pelayanan Pelra | C9: Pendapatan Marine | D9: 0 | E9: 0 | F9: =E9/12*5 -> 0 | G9: 0 | H9: 0 | I9: =IF(ISERROR(H9/D9),0,H9/D9) -> 0 | J9: =IF(ISERROR(G9/D9),0,G9/D9) -> 0 | K9: =IF(ISERROR(H9/G9),0,H9/G9) -> 0
C10: Pendapatan Pelsus, Tersus, dan Dersus | D10: 0 | E10: 0 | F10: =E10/12*5 -> 0 | G10: 0 | H10: 0 | I10: =IF(ISERROR(H10/D10),0,H10/D10) -> 0 | J10: =IF(ISERROR(G10/D10),0,G10/D10) -> 0 | K10: =IF(ISERROR(H10/G10),0,H10/G10) -> 0
C11: Total Pendapatan Kapal | D11: =SUM(D6:D10) -> 320012781198 | E11: =SUM(E6:E10) -> 3.4623366e+11 | F11: =SUM(F6:F10) -> 101973162951 | G11: =SUM(G6:G10) -> 335140926081 | H11: =SUM(H6:H10) -> 3.4772201e+11 | I11: =IF(ISERROR(H11/D11),0,H11/D11) -> 1.0865879 | J11: =IF(ISERROR(G11/D11),0,G11/D11) -> 1.0472736 | K11: =IF(ISERROR(H11/G11),0,H11/G11) -> 1.0375397
B12: Reduksi Pendapatan Pelayanan Petikemas | C12: Pelayanan Petikemas | D12: 45048696500 | E12: 51360511500 | F12: =E12/12*5 -> 21400213125 | G12: 100900291000 | H12: 1.0657546e+11 | I12: =IF(ISERROR(H12/D12),0,H12/D12) -> 2.3657833 | J12: =IF(ISERROR(G12/D12),0,G12/D12) -> 2.2398049 | K12: =IF(ISERROR(H12/G12),0,H12/G12) -> 1.0562453
B13: Reduksi Pendapatan Barang Non Petikemas | C13: Pendapatan Barang Non Petikemas | D13: 86072813121 | E13: 75799168087 | F13: =E13/12*5 -> 3.1582987e+10 | G13: 75678681014 | H13: 5.5659741e+10 | I13: =IF(ISERROR(H13/D13),0,H13/D13) -> 0.64665879 | J13: =IF(ISERROR(G13/D13),0,G13/D13) -> 0.87924024 | K13: =IF(ISERROR(H13/G13),0,H13/G13) -> 0.73547451
B14: Reduksi Pendapatan Konsolidasi dan Distribusi Barang | C14: Pelayanan Konsolidasi dan Distribusi Barang | D14: 0 | E14: 0 | F14: =E14/12*5 -> 0 | G14: 0 | H14: 0 | I14: =IF(ISERROR(H14/D14),0,H14/D14) -> 0 | J14: =IF(ISERROR(G14/D14),0,G14/D14) -> 0 | K14: =IF(ISERROR(H14/G14),0,H14/G14) -> 0
B15: Reduksi Pendapatan Pengusahaan Alat | C15: Pendapatan Pengusahaan Alat | D15: 0 | E15: 0 | F15: =E15/12*5 -> 0 | G15: 0 | H15: 0 | I15: =IF(ISERROR(H15/D15),0,H15/D15) -> 0 | J15: =IF(ISERROR(G15/D15),0,G15/D15) -> 0 | K15: =IF(ISERROR(H15/G15),0,H15/G15) -> 0
B16: Reduksi Pendapatan Pengusahaan Properti | C16: Pendapatan Pengusahaan Properti | D16: 431942664108 | E16: 459329580716 | F16: =E16/12*5 -> 1.9138733e+11 | G16: 480400759634 | H16: 4.552194e+11 | I16: =IF(ISERROR(H16/D16),0,H16/D16) -> 1.0538885 | J16: =IF(ISERROR(G16/D16),0,G16/D16) -> 1.1121864 | K16: =IF(ISERROR(H16/G16),0,H16/G16) -> 0.9475826
B17: Reduksi Pendapatan Pengusahaan Air / Listrik | C17: Pendapatan Pengusahaan Air / Listrik | D17: 22363776 | E17: 103046784 | F17: =E17/12*5 -> 42936160 | G17: 228079275 | H17: 0 | I17: =IF(ISERROR(H17/D17),0,H17/D17) -> 0 | J17: =IF(ISERROR(G17/D17),0,G17/D17) -> 10.198603 | K17: =IF(ISERROR(H17/G17),0,H17/G17) -> 0
B18: Reduksi Pendapatan Rupa-Rupa Usaha | C18: Pelayanan Rupa-Rupa Usaha | D18: 639015023272 | E18: 652634177971 | F18: =E18/12*5 -> 2.7193091e+11 | G18: 859478218593 | H18: 7.3108951e+11 | I18: =IF(ISERROR(H18/D18),0,H18/D18) -> 1.1440881 | J18: =IF(ISERROR(G18/D18),0,G18/D18) -> 1.3450047 | K18: =IF(ISERROR(H18/G18),0,H18/G18) -> 0.85062017
C19: Pelayanan Rupa-Rupa Managemen fee | D19: 301015023272 | E19: 332634177971 | F19: 141200177811 | G19: 3.3888043e+11 | H19: 2.8825853e+11 | I19: =IF(ISERROR(H19/D19),0,H19/D19) -> 0.95762173 | J19: =IF(ISERROR(G19/D19),0,G19/D19) -> 1.1257924 | K19: =IF(ISERROR(H19/G19),0,H19/G19) -> 0.85062017
C20: Pelayanan Rupa-Rupa lainnya | D20: =D18-D19 -> 338000000000 | E20: =E18-E19 -> 320000000000 | F20: =F18-F19 -> 1.3073073e+11 | G20: =G18-G19 -> 5.2059779e+11 | H20: =H18-H19 -> 4.4283098e+11 | I20: =IF(ISERROR(H20/D20),0,H20/D20) -> 1.3101508 | J20: =IF(ISERROR(G20/D20),0,G20/D20) -> 1.5402302 | K20: =IF(ISERROR(H20/G20),0,H20/G20) -> 0.85062017
C21: TOTAL PENDAPATAN USAHA | D21: =SUM(D11:D18) -> 1522114341975 | E21: =SUM(E11:E18) -> 1.5854601e+12 | F21: =SUM(F11:F18) -> 6.1831753e+11 | G21: =SUM(G11:G18) -> 1851826955597 | H21: =SUM(H11:H18) -> 1.6962661e+12 | I21: =IF(ISERROR(H21/D21),0,H21/D21) -> 1.1144144 | J21: =IF(ISERROR(G21/D21),0,G21/D21) -> 1.2166149 | K21: =IF(ISERROR(H21/G21),0,H21/G21) -> 0.91599602
B22: Reduksi Pendapatan Marine | C22: TOTAL REDUKSI PENDAPATAN | D22: 0 | E22: 0 | F22: 0 | G22: 0 | H22: 0 | I22: =IF(ISERROR(H22/D22),0,H22/D22) -> 0 | J22: =IF(ISERROR(G22/D22),0,G22/D22) -> 0 | K22: =IF(ISERROR(H22/G22),0,H22/G22) -> 0
C23: TOTAL PENDAPATAN USAHA | D23: =D21+D22 -> 1522114341975 | E23: =E21+E22 -> 1.5854601e+12 | F23: =F21+F22 -> 6.1831753e+11 | G23: =G21+G22 -> 1851826955597 | H23: =H21+H22 -> 1.6962661e+12 | I23: =IF(ISERROR(H23/D23),0,H23/D23) -> 1.1144144 | J23: =IF(ISERROR(G23/D23),0,G23/D23) -> 1.2166149 | K23: =IF(ISERROR(H23/G23),0,H23/G23) -> 0.91599602
B24: Beban Penghasilan | C24: Beban Penghasilan | D24: -153440115859 | E24: -121727456532 | F24: =E24/12*5 -> -50719773555 | G24: -83279941263 | H24: -8.7562176e+10 | I24: =IF(ISERROR(H24/D24),0,H24/D24) -> 0.57066025 | J24: =IF(ISERROR(G24/D24),0,G24/D24) -> 0.54275207 | K24: =IF(ISERROR(H24/G24),0,H24/G24) -> 1.0514198
B25: Beban Bahan | C25: Beban Bahan | D25: -33763489129 | E25: -24751929788 | F25: =E25/12*5 -> -1.0313304e+10 | G25: -23118604907 | H25: -2.7409208e+10 | I25: =IF(ISERROR(H25/D25),0,H25/D25) -> 0.81180022 | J25: =IF(ISERROR(G25/D25),0,G25/D25) -> 0.68472203 | K25: =IF(ISERROR(H25/G25),0,H25/G25) -> 1.1855909
B26: Beban Pemeliharaan | C26: Beban Pemeliharaan | D26: -50150142315 | E26: -47854171477 | F26: =E26/12*5 -> -1.9939238e+10 | G26: -55072743729 | H26: -5.60387e+10 | I26: =IF(ISERROR(H26/D26),0,H26/D26) -> 1.1174186 | J26: =IF(ISERROR(G26/D26),0,G26/D26) -> 1.0981573 | K26: =IF(ISERROR(H26/G26),0,H26/G26) -> 1.0175396
B27: Beban Penyusutan dan Amortisasi | C27: Beban Penyusutan dan Amortisasi | D27: -222368917608 | E27: -223804037186 | F27: =E27/12*5 -> -9.3251682e+10 | G27: -150060315846 | H27: -1.2315549e+11 | I27: =IF(ISERROR(H27/D27),0,H27/D27) -> 0.55383412 | J27: =IF(ISERROR(G27/D27),0,G27/D27) -> 0.67482595 | K27: =IF(ISERROR(H27/G27),0,H27/G27) -> 0.82070661
B28: Beban Asuransi | C28: Beban Asuransi | D28: -10515268361 | E28: -12915967029 | F28: =E28/12*5 -> -5.3816529e+09 | G28: -16814155205 | H28: -1.592618e+10 | I28: =IF(ISERROR(H28/D28),0,H28/D28) -> 1.5145767 | J28: =IF(ISERROR(G28/D28),0,G28/D28) -> 1.5990229 | K28: =IF(ISERROR(H28/G28),0,H28/G28) -> 0.94718885
B29: Beban Kerjasama Mitra Usaha (KSMU) | C29: Beban Kerjasama Mitra Usaha (KSMU) | D29: -588267592868 | E29: -646716043685 | F29: =E29/12*5 -> -2.6946502e+11 | G29: -775333229806 | H29: -8.3358805e+11 | I29: =IF(ISERROR(H29/D29),0,H29/D29) -> 1.4170219 | J29: =IF(ISERROR(G29/D29),0,G29/D29) -> 1.3179941 | K29: =IF(ISERROR(H29/G29),0,H29/G29) -> 1.0751352
C30: Beban KSMU Revenue Sharing | D30: -3.2434506e+11 | E30: -346382158108 | F30: -1.443259e+11 | G30: -384598801694 | H30: -4.36548e+11 | I30: =IF(ISERROR(H30/D30),0,H30/D30) -> 1.345937 | J30: =IF(ISERROR(G30/D30),0,G30/D30) -> 1.1857705 | K30: =IF(ISERROR(H30/G30),0,H30/G30) -> 1.1350737
C31: Beban KSMU Non Revenue Sharing | D31: =D29-D30 -> -2.6392254e+11 | E31: =E29-E30 -> -300333885577 | F31: =F29-F30 -> -1.2513912e+11 | G31: =G29-G30 -> -390734428112 | H31: =H29-H30 -> -3.9704005e+11 | I31: =IF(ISERROR(H31/D31),0,H31/D31) -> 1.504381 | J31: =IF(ISERROR(G31/D31),0,G31/D31) -> 1.4804891 | K31: =IF(ISERROR(H31/G31),0,H31/G31) -> 1.0161379
B32: Beban Administrasi Kantor | C32: Beban Administrasi Kantor | D32: -952922291 | E32: -1144182711 | F32: =E32/12*5 -> -4.767428e+08 | G32: -930898801 | H32: -1103860000 | I32: =IF(ISERROR(H32/D32),0,H32/D32) -> 1.1583946 | J32: =IF(ISERROR(G32/D32),0,G32/D32) -> 0.97688847 | K32: =IF(ISERROR(H32/G32),0,H32/G32) -> 1.1858002
B33: Beban Umum | C33: Beban Umum | D33: -66407485742 | E33: -82959626626 | F33: =E33/12*5 -> -3.4566511e+10 | G33: -106088833995 | H33: -1.0488249e+11 | I33: =IF(ISERROR(H33/D33),0,H33/D33) -> 1.5793776 | J33: =IF(ISERROR(G33/D33),0,G33/D33) -> 1.5975433 | K33: =IF(ISERROR(H33/G33),0,H33/G33) -> 0.98862895
C34: TOTAL BEBAN USAHA | D34: =SUM(D24:D33) -> -1714133527041 | E34: =SUM(E24:E33) -> -1808589458719 | F34: =SUM(F24:F33) -> -7.5357894e+11 | G34: =SUM(G24:G33) -> -1986031953358 | H34: =SUM(H24:H33) -> -2.0832542e+12 | I34: =IF(ISERROR(H34/D34),0,H34/D34) -> 1.2153395 | J34: =IF(ISERROR(G34/D34),0,G34/D34) -> 1.1586215 | K34: =IF(ISERROR(H34/G34),0,H34/G34) -> 1.048953
B35: LABA (RUGI) USAHA | D35: =D23+D34 -> -192019185066 | E35: =E23+E34 -> -2.2312932e+11 | F35: =F23+F34 -> -1.3526141e+11 | G35: =G23+G34 -> -134204997761 | H35: =H23+H34 -> -3.8698809e+11 | I35: =IF(ISERROR(H35/D35),0,H35/D35) -> 2.0153616 | J35: =IF(ISERROR(G35/D35),0,G35/D35) -> 0.69891453 | K35: =IF(ISERROR(H35/G35),0,H35/G35) -> 2.8835594
B36: Pendapatan (Beban) di Luar Usaha | J36: =IF(ISERROR(G36/D36),0,G36/D36) -> 0 | K36: =IF(ISERROR(H36/G36),0,H36/G36) -> 0
B37: Pendapatan di Luar Usaha *) | C37: Pendapatan Di Luar Usaha | D37: 6225447076 | E37: 92285845887 | F37: =E37/12*5 -> 3.8452436e+10 | G37: 4628212157 | H37: 0 | I37: =IF(ISERROR(H37/D37),0,H37/D37) -> 0 | J37: =IF(ISERROR(G37/D37),0,G37/D37) -> 0.7434345 | K37: =IF(ISERROR(H37/G37),0,H37/G37) -> 0
B38: Beban di Luar Usaha *) | C38: Beban diluar usaha | D38: -10801911954 | E38: -7259949782 | F38: =E38/12*5 -> -3.0249791e+09 | G38: -2574872887 | H38: 0 | I38: =IF(ISERROR(H38/D38),0,H38/D38) -> 0 | J38: =IF(ISERROR(G38/D38),0,G38/D38) -> 0.23837196 | K38: =IF(ISERROR(H38/G38),0,H38/G38) -> 0
B39: Jumlah Pendapatan (Beban) di Luar Usaha | D39: =D37+D38 -> -4576464878 | E39: =E37+E38 -> 85025896105 | F39: =F37+F38 -> 3.5427457e+10 | G39: =G37+G38 -> 2053339270 | H39: =H37+H38 -> 0 | I39: =IF(ISERROR(H39/D39),0,H39/D39) -> 0 | J39: =IF(ISERROR(G39/D39),0,G39/D39) -> -0.44867367 | K39: =IF(ISERROR(H39/G39),0,H39/G39) -> 0
B40: LABA (RUGI) SEBELUM PAJAK DAN PENUGASAN | D40: =D35+D39 -> -196595649944 | E40: =E35+E39 -> -1.3810342e+11 | F40: =F35+F39 -> -9.9833953e+10 | G40: =G35+G39 -> -132151658491 | H40: =H35+H39 -> -3.8698809e+11 | I40: =IF(ISERROR(H40/D40),0,H40/D40) -> 1.9684469 | J40: =IF(ISERROR(G40/D40),0,G40/D40) -> 0.67220032 | K40: =IF(ISERROR(H40/G40),0,H40/G40) -> 2.9283635
C41: Beban Penugasan Pemerintah | D41: 0 | E41: 0 | F41: =E41/12*5 -> 0 | G41: 0 | H41: 0 | I41: =IF(ISERROR(H41/D41),0,H41/D41) -> 0 | J41: =IF(ISERROR(G41/D41),0,G41/D41) -> 0 | K41: =IF(ISERROR(H41/G41),0,H41/G41) -> 0
...

Sheet Trafik vs Pend
C3: URAIAN | D3: SATUAN | E3: REALISASI 2025 | F3: RKAP 2026 | G3: Realisasi s.d Mei 2026 | H3: PROGNOSA 2026 | I3: USULAN RKAP 2027 | J3: Summary
E4: 1 | F4: 2 | G4: 3 | H4: 4 | I4: 5 | J4: 6=4/1 | K4: 7=5/4 | L4: 8=5/1
C5: UMUM Dalam Negeri | D5: Call | E5: ='[1]Regional 2'!$P$16 -> 806 | F5: ='[1]Regional 2'!$Q$16 -> 674 | G5: ='[2]Regional 2'!$S$16 -> 634 | H5: ='[2]Regional 2'!$T$16 -> 1421 | I5: ='[2]Regional 2'!$U$16 -> 1449.42 | J5: =H5/E5 -> 1.7630273 | K5: =I5/H5 -> 1.02 | L5: =I5/E5 -> 1.7982878
D6: GT | E6: ='[1]Regional 2'!$P$17 -> 2619161 | F6: ='[1]Regional 2'!$Q$17 -> 2508863.2 | G6: ='[2]Regional 2'!$S$17 -> 1338067 | H6: ='[2]Regional 2'!$T$17 -> 3111361 | I6: ='[2]Regional 2'!$U$17 -> 3173588.2 | J6: =H6/E6 -> 1.1879228 | K6: =I6/H6 -> 1.02 | L6: =I6/E6 -> 1.2116812
C7: UMUM Luar Negeri | D7: Call | E7: ='[1]Regional 2'!$P$14 -> 184 | F7: ='[1]Regional 2'!$Q$14 -> 180 | G7: ='[2]Regional 2'!$S$14 -> 98 | H7: ='[2]Regional 2'!$T$14 -> 225 | I7: ='[2]Regional 2'!$U$14 -> 229.5 | J7: =H7/E7 -> 1.2228261 | K7: =I7/H7 -> 1.02 | L7: =I7/E7 -> 1.2472826
D8: GT | E8: ='[1]Regional 2'!$P$15 -> 3691444 | F8: ='[1]Regional 2'!$Q$15 -> 3556185.8 | G8: ='[2]Regional 2'!$S$15 -> 1964950 | H8: ='[2]Regional 2'!$T$15 -> 4615880 | I8: ='[2]Regional 2'!$U$15 -> 4708197.6 | J8: =H8/E8 -> 1.2504267 | K8: =I8/H8 -> 1.02 | L8: =I8/E8 -> 1.2754352
C9: Total Trafik Dermaga Umum | D9: Call | E9: =SUM(E5,E7) -> 990 | F9: =SUM(F5,F7) -> 854 | G9: =SUM(G5,G7) -> 732 | H9: =SUM(H5,H7) -> 1646 | I9: =SUM(I5,I7) -> 1678.92 | J9: =H9/E9 -> 1.6626263 | K9: =I9/H9 -> 1.02 | L9: =I9/E9 -> 1.6958788
D10: GT | E10: =SUM(E6,E8) -> 6310605 | F10: =SUM(F6,F8) -> 6065049 | G10: =SUM(G6,G8) -> 3303017 | H10: =SUM(H6,H8) -> 7727241 | I10: =SUM(I6,I8) -> 7881785.8 | J10: =H10/E10 -> 1.224485 | K10: =I10/H10 -> 1.02 | L10: =I10/E10 -> 1.2489747
C11: Total Pendapatan Pandu, Tunda, Tambat di Dermaga Umum | D11: IDR Juta | E11: =[3]Sheet1!$F$12 -> 95048178375 | F11: =[3]Sheet1!$G$12 -> 98940555039 | G11: =[3]Sheet1!$H$12 -> 29181123591 | H11: =[3]Sheet1!$S$12 -> 128801886656 | I11: =[3]Sheet1!$AF$12 -> 1.3624062e+11 | J11: =H11/E11 -> 1.3551221 | K11: =I11/H11 -> 1.0577533 | L11: =I11/E11 -> 1.4333849
C12: TUKS Dalam Negeri | D12: Call | E12: ='[1]Regional 2'!$P$22 -> 3639 | F12: ='[1]Regional 2'!$Q$22 -> 4308 | G12: ='[2]Regional 2'!$S$22 -> 1218 | H12: ='[2]Regional 2'!$T$22 -> 3343 | I12: ='[2]Regional 2'!$U$22 -> 3409.86 | J12: =H12/E12 -> 0.91865897 | K12: =I12/H12 -> 1.02 | L12: =I12/E12 -> 0.93703215
D13: GT | E13: ='[1]Regional 2'!$P$23 -> 22673573 | F13: ='[1]Regional 2'!$Q$23 -> 26778183 | G13: ='[2]Regional 2'!$S$23 -> 9771942 | H13: ='[2]Regional 2'!$T$23 -> 23452661 | I13: ='[2]Regional 2'!$U$23 -> 23921714 | J13: =H13/E13 -> 1.0343611 | K13: =I13/H13 -> 1.02 | L13: =I13/E13 -> 1.0550483
C14: TUKS Luar Negeri | D14: Call | E14: ='[1]Regional 2'!$P$20 -> 543 | F14: ='[1]Regional 2'!$Q$20 -> 510 | G14: ='[2]Regional 2'!$S$20 -> 247 | H14: ='[2]Regional 2'!$T$20 -> 582 | I14: ='[2]Regional 2'!$U$20 -> 593.64 | J14: =H14/E14 -> 1.0718232 | K14: =I14/H14 -> 1.02 | L14: =I14/E14 -> 1.0932597
D15: GT | E15: ='[1]Regional 2'!$P$21 -> 9889101 | F15: ='[1]Regional 2'!$Q$21 -> 9644471 | G15: ='[2]Regional 2'!$S$21 -> 4308561 | H15: ='[2]Regional 2'!$T$21 -> 10240546 | I15: ='[2]Regional 2'!$U$21 -> 10445357 | J15: =H15/E15 -> 1.0355386 | K15: =I15/H15 -> 1.02 | L15: =I15/E15 -> 1.0562494
C16: Total Trafik Dermaga Khusus | D16: Call | E16: =SUM(E12,E14) -> 4182 | F16: =SUM(F12,F14) -> 4818 | G16: =SUM(G12,G14) -> 1465 | H16: =SUM(H12,H14) -> 3925 | I16: =SUM(I12,I14) -> 4003.5 | J16: =H16/E16 -> 0.93854615 | K16: =I16/H16 -> 1.02 | L16: =I16/E16 -> 0.95731707
D17: GT | E17: =SUM(E13,E15) -> 32562674 | F17: =SUM(F13,F15) -> 36422654 | G17: =SUM(G13,G15) -> 14080503 | H17: =SUM(H13,H15) -> 33693207 | I17: =SUM(I13,I15) -> 34367071 | J17: =H17/E17 -> 1.0347187 | K17: =I17/H17 -> 1.02 | L17: =I17/E17 -> 1.0554131
C18: Total Pendapatan Pandu, Tunda, Tambat di Dermaga Khusus | D18: IDR Juta | E18: =[3]Sheet1!$F$61 -> 224964602823 | F18: =[3]Sheet1!$G$61 -> 2.472931e+11 | G18: 72792039360 | H18: =[4]Sheet1!$S$61 -> 206339039425 | I18: =[4]Sheet1!$AF$61 -> 2.1148139e+11 | J18: =H18/E18 -> 0.91720669 | K18: =I18/H18 -> 1.0249219 | L18: =I18/E18 -> 0.94006518
C19: Total Trafik | D19: Call | E19: =SUM(E9,E16) -> 5172 | F19: =SUM(F9,F16) -> 5672 | G19: =SUM(G9,G16) -> 2197 | H19: =SUM(H9,H16) -> 5571 | I19: =SUM(I9,I16) -> 5682.42 | J19: =H19/E19 -> 1.0771462 | K19: =I19/H19 -> 1.02 | L19: =I19/E19 -> 1.0986891
D20: GT | E20: =SUM(E10,E17) -> 38873279 | F20: =SUM(F10,F17) -> 42487703 | G20: =SUM(G10,G17) -> 17383520 | H20: =SUM(H10,H17) -> 41420448 | I20: =SUM(I10,I17) -> 42248857 | J20: =H20/E20 -> 1.0655249 | K20: =I20/H20 -> 1.02 | L20: =I20/E20 -> 1.0868354
C21: Total Pendapatan Kapal | D21: IDR Juta | E21: =E11+E18 -> 320012781198 | F21: =F11+F18 -> 3.4623366e+11 | G21: =G11+G18 -> 101973162951 | H21: =H11+H18 -> 335140926081 | I21: =I11+I18 -> 3.4772201e+11 | J21: =H21/E21 -> 1.0472736 | K21: =I21/H21 -> 1.0375397 | L21: =I21/E21 -> 1.0865879
C22: Total pendapatan Pas Pelabuhan | D22: IDR Juta | J22: =H22/E22 -> #DIV/0! | K22: =I22/H22 -> #DIV/0! | L22: =I22/E22 -> #DIV/0!

Sheet Permasalahan Strategis
C3: Permasalahan Strategis
B5: No | C5: Permasalahan Strategis | D5: Potensi Dampak | G5: Rencana Mitigasi | H5: Kebutuhan Anggaran mitigasi | I5: keterangan
D6: Account | E6: Nilai | F6: Durasi
B7: 1 | C7: Implementasi kenaikan Tarif Petikemas | D7: Pendapatan petikemas | E7: 1500000000 | F7: 1 tahun | G7: Pelaksanaan konsinyering dengan asosiasi untuk pembuatan BA kesekapatan | H7: 500000000 | I7: untuk biaya pelaksanaan konsinyering dan honor 2x di Yogyakarta
B8: 2 | C8: Permasalahan Kemacetan di Tanjung Priok | D8: Pendapatan Pas Pelabuhan | E8: -500000000 | F8: 1 hari | G8: Sewa lapangan penumpukan di Cakung | H8: 1500000000 | I8: Proyeksi nilai sewa lapangan
D9: Biaya jamuan | E9: 50000000 | F9: 1 hari | G9: Penambahan personel operasional | H9: 240000000 | I9: Penghasilan untuk 3 personel lapangan
D10: Biaya lembur TAD | E10: 15000000 | F10: 1 hari | G10: Pelebaran jalan di jalan Utara | H10: 5000000000 | I10: Usulan Investasi

Sheet Rencana Kenaikan Tarif
B3: Rencana Kenaikan Tarif
B4: Cabang | C4: Jenis Tarif Pelayanan | D4: Negosiasi | E4: Berita Acara Kesepakatan | F4: Konsultasi | G4: Pembahasan dengan Kementerian | H4: Rekomendasi Menhub | I4: Pemberlakuan | J4: Avrg % Penyesuaian | K4: Potensi Tambahan Pendapatan per Tahun | L4: Efektif Per
F5: HO
B6: Pontianak | C6: tarif Jasa Kapal | D6: Agst 25 | G6: Proses negosisasi dan kelengkapan Data Pendukung | K6: 3000000000 | L6: 1 Januari 2027
C7: Tarif Petikemas | K7: 400000000 | L7: TW II 2027
C8: dst….

Sheet Optipi
B2: OPTIPI 2026/2027
B3: Kategori | C3: Keterangan | D3: Potensi Nilai | E3: Biaya Yang dibutuhkan
E4: Nilai | F4: Keterangan
B5: Revenue growth | C5: Pemanfaat lahan iddle di … | D5: 600000000 | E5: 200000000 | F5: untuk Biaya Promosi dan Jamuan
B7: Cost Avoidance | C7: 1.Pemanfaatan Discount PBB | D7: 125000000 | E7: 0 | F7: nihil
C8: 2. penagihan Piutang PT Djakarta Lyod | D8: 5347110500 | E8: 300000000 | F8: Untuk honor dengan JPN dan Konsumsi
B9: Cost Eficiency | C9: 1. Standarisasi pemberian Jamuan kepada tamu | D9: 200000000
C10: 2. Evaluasi kontrak kebersihan dengan vendor | D10: 75000000

Sheet Investasi yang sudah menghasilk
B2: Investasi 2025-2026 yang telah menghasilkan pendapatan
B3: Cabang | C3: Investasi | D3: Beban / Tahun | F3: Jenis Tarif Pelayanan | G3: Pendapatan di 2026 | H3: Potensi Pendapatan di 2027
D4: Uraian | E4: Nominal
B5: Bengkulu | C5: Pengerukan Alur | D5: Penyusutan | E5: 7500000000 | F5: Pendapatan Alur | G5: 7500000000 | H5: 80000000000
D6: pemeliharaan | E6: 80000000000
C7: Perbaikan Conveyor | D7: Penyusutan | E7: 400000000 | F7: Pendapatan Manajemen Fee | G7: 300000000 | H7: 700000000
D8: Listrik | E8: 30000000
B10: Sunda kelapa | C10: Perbaikan Jalan dan tanggul dermaga | D10: Penyusutan | E10: =16000000000/20 -> 800000000 | F10: PFS | G10: 3000000000 | H10: 5000000000
D11: pemeliharaan | E11: 400000000 | F11: Pas pelabuhan | G11: 450000000 | H11: 650000000

Sheet Rencana Relokasi
B3: Daftar Rencana Aset Relokasi In/out
B4: Cabang | C4: Nama Item Aset | F4: Rencana Relokasi in/out | G4: Tujuan/Dari | H4: Rencana TMT
B6: Tanjung Priok | C6: KT Tanjung Priok | F6: Out | G6: Cirebon | H6: Juni 2027
C7: RTGC 01 | F7: Out | G7: Kijing | H7: Desember 2026
C8: KP Tanjung Priok 2 | F8: In | G8: Palembang | H8: Februari 2027
C9: dst… | F9: Out

Sheet Struktur Kosong
B3: Daftar Struktur Kosong
B4: No | C4: Struktur Kosong | D4: Rencana Pengisian | E4: Justifikasi
B6: 1 | C6: Supervisor Keuangan | D6: Ya | E6: Saat ini hanya terisi Manager dan 1 TAD tanpa memiliki Organik di Keuangan
B7: 2 | C7: Asman SDM dan Umum | D7: Ya | E7: Posisi Supervisor SDM umum saat ini terisi namun akan pensiun pada TW III 2026
B8: 3 | C8: Manager Teknik | D8: Tidak
B9: 4 | C9: dst | D9: Tidak
