Workbook

Sheet Perbln
B2: Produksi | E2: Jan | F2: Feb | G2: Mar | H2: Apr | I2: Mei | J2: Jun | K2: Jul | L2: Aug | M2: Sept | N2: Okt | O2: Nov | P2: Des | Q2: JUMLAH
B3: PELUM | C3: PANDU | D3: Call | E3: ='PANDU IKPP'!C7+'PANDU IKPP'!C13+'PANDU IKPP'!C19+'PANDU IKPP'!C34+'PANDU IKPP'!C40+'PANDU IKPP'!C46+'PANDU IKPP'!C52+'PANDU IKPP'!C58+'PANDU IKPP'!C64 -> 32 | F3: ='PANDU IKPP'!D7+'PANDU IKPP'!D13+'PANDU IKPP'!D19+'PANDU IKPP'!D34+'PANDU IKPP'!D40+'PANDU IKPP'!D46+'PANDU IKPP'!D52+'PANDU IKPP'!D58+'PANDU IKPP'!D64 -> 37 | G3: ='PANDU IKPP'!E7+'PANDU IKPP'!E13+'PANDU IKPP'!E19+'PANDU IKPP'!E34+'PANDU IKPP'!E40+'PANDU IKPP'!E46+'PANDU IKPP'!E52+'PANDU IKPP'!E58+'PANDU IKPP'!E64 -> 159 | H3: ='PANDU IKPP'!F7+'PANDU IKPP'!F13+'PANDU IKPP'!F19+'PANDU IKPP'!F34+'PANDU IKPP'!F40+'PANDU IKPP'!F46+'PANDU IKPP'!F52+'PANDU IKPP'!F58+'PANDU IKPP'!F64 -> 39 | I3: ='PANDU IKPP'!G7+'PANDU IKPP'!G13+'PANDU IKPP'!G19+'PANDU IKPP'!G34+'PANDU IKPP'!G40+'PANDU IKPP'!G46+'PANDU IKPP'!G52+'PANDU IKPP'!G58+'PANDU IKPP'!G64 -> 34 | J3: ='PANDU IKPP'!H7+'PANDU IKPP'!H13+'PANDU IKPP'!H19+'PANDU IKPP'!H34+'PANDU IKPP'!H40+'PANDU IKPP'!H46+'PANDU IKPP'!H52+'PANDU IKPP'!H58+'PANDU IKPP'!H64 -> 37 | K3: ='PANDU IKPP'!I7+'PANDU IKPP'!I13+'PANDU IKPP'!I19+'PANDU IKPP'!I34+'PANDU IKPP'!I40+'PANDU IKPP'!I46+'PANDU IKPP'!I52+'PANDU IKPP'!I58+'PANDU IKPP'!I64 -> 35 | L3: ='PANDU IKPP'!J7+'PANDU IKPP'!J13+'PANDU IKPP'!J19+'PANDU IKPP'!J34+'PANDU IKPP'!J40+'PANDU IKPP'!J46+'PANDU IKPP'!J52+'PANDU IKPP'!J58+'PANDU IKPP'!J64 -> 34 | ... P3: ='PANDU IKPP'!N7+'PANDU IKPP'!N13+'PANDU IKPP'!N19+'PANDU IKPP'!N34+'PANDU IKPP'!N40+'PANDU IKPP'!N46+'PANDU IKPP'!N52+'PANDU IKPP'!N58+'PANDU IKPP'!N64 -> 32 | Q3: =SUM(E3:P3) -> 556
D4: GT | E4: ='PANDU IKPP'!C8+'PANDU IKPP'!C14+'PANDU IKPP'!C20+'PANDU IKPP'!C35+'PANDU IKPP'!C41+'PANDU IKPP'!C47+'PANDU IKPP'!C53+'PANDU IKPP'!C59+'PANDU IKPP'!C65 -> 263773 | F4: ='PANDU IKPP'!D8+'PANDU IKPP'!D14+'PANDU IKPP'!D20+'PANDU IKPP'!D35+'PANDU IKPP'!D41+'PANDU IKPP'!D47+'PANDU IKPP'!D53+'PANDU IKPP'!D59+'PANDU IKPP'!D65 -> 203390 | G4: ='PANDU IKPP'!E8+'PANDU IKPP'!E14+'PANDU IKPP'!E20+'PANDU IKPP'!E35+'PANDU IKPP'!E41+'PANDU IKPP'!E47+'PANDU IKPP'!E53+'PANDU IKPP'!E59+'PANDU IKPP'!E65 -> 1340528 | H4: ='PANDU IKPP'!F8+'PANDU IKPP'!F14+'PANDU IKPP'!F20+'PANDU IKPP'!F35+'PANDU IKPP'!F41+'PANDU IKPP'!F47+'PANDU IKPP'!F53+'PANDU IKPP'!F59+'PANDU IKPP'!F65 -> 352434.49 | I4: ='PANDU IKPP'!G8+'PANDU IKPP'!G14+'PANDU IKPP'!G20+'PANDU IKPP'!G35+'PANDU IKPP'!G41+'PANDU IKPP'!G47+'PANDU IKPP'!G53+'PANDU IKPP'!G59+'PANDU IKPP'!G65 -> 153376.2 | J4: ='PANDU IKPP'!H8+'PANDU IKPP'!H14+'PANDU IKPP'!H20+'PANDU IKPP'!H35+'PANDU IKPP'!H41+'PANDU IKPP'!H47+'PANDU IKPP'!H53+'PANDU IKPP'!H59+'PANDU IKPP'!H65 -> 331503.44 | K4: ='PANDU IKPP'!I8+'PANDU IKPP'!I14+'PANDU IKPP'!I20+'PANDU IKPP'!I35+'PANDU IKPP'!I41+'PANDU IKPP'!I47+'PANDU IKPP'!I53+'PANDU IKPP'!I59+'PANDU IKPP'!I65 -> 170593.35 | L4: ='PANDU IKPP'!J8+'PANDU IKPP'!J14+'PANDU IKPP'!J20+'PANDU IKPP'!J35+'PANDU IKPP'!J41+'PANDU IKPP'!J47+'PANDU IKPP'!J53+'PANDU IKPP'!J59+'PANDU IKPP'!J65 -> 258839.47 | ... P4: ='PANDU IKPP'!N8+'PANDU IKPP'!N14+'PANDU IKPP'!N20+'PANDU IKPP'!N35+'PANDU IKPP'!N41+'PANDU IKPP'!N47+'PANDU IKPP'!N53+'PANDU IKPP'!N59+'PANDU IKPP'!N65 -> 274917.8 | Q4: =SUM(E4:P4) -> 4073742
D5: Kpl.Grk | E5: ='PANDU IKPP'!C79 -> 32 | F5: ='PANDU IKPP'!D79 -> 37 | G5: ='PANDU IKPP'!E79 -> 159 | H5: ='PANDU IKPP'!F79 -> 39 | I5: ='PANDU IKPP'!G79 -> 34 | J5: ='PANDU IKPP'!H79 -> 37 | K5: ='PANDU IKPP'!I79 -> 35 | L5: ='PANDU IKPP'!J79 -> 34 | ... P5: ='PANDU IKPP'!N79 -> 32 | Q5: =SUM(E5:P5) -> 556
D6: GT.Kpl.Grk | E6: ='PANDU IKPP'!C80 -> 263773 | F6: ='PANDU IKPP'!D80 -> 203390 | G6: ='PANDU IKPP'!E80 -> 1340528 | H6: ='PANDU IKPP'!F80 -> 352434.49 | I6: ='PANDU IKPP'!G80 -> 153376.2 | J6: ='PANDU IKPP'!H80 -> 331503.44 | K6: ='PANDU IKPP'!I80 -> 170593.35 | L6: ='PANDU IKPP'!J80 -> 258839.47 | ... P6: ='PANDU IKPP'!N80 -> 274917.8 | Q6: =SUM(E6:P6) -> 4073742
C7: TUNDA | D7: Call | E7: ='TUNDA IKPP'!E8+'TUNDA IKPP'!E30+'TUNDA IKPP'!E52+'TUNDA IKPP'!E98+'TUNDA IKPP'!E120+'TUNDA IKPP'!E142+'TUNDA IKPP'!E164+'TUNDA IKPP'!E172+'TUNDA IKPP'!E180 -> 32 | F7: ='TUNDA IKPP'!F8+'TUNDA IKPP'!F30+'TUNDA IKPP'!F52+'TUNDA IKPP'!F98+'TUNDA IKPP'!F120+'TUNDA IKPP'!F142+'TUNDA IKPP'!F164+'TUNDA IKPP'!F172+'TUNDA IKPP'!F180 -> 37 | G7: ='TUNDA IKPP'!G8+'TUNDA IKPP'!G30+'TUNDA IKPP'!G52+'TUNDA IKPP'!G98+'TUNDA IKPP'!G120+'TUNDA IKPP'!G142+'TUNDA IKPP'!G164+'TUNDA IKPP'!G172+'TUNDA IKPP'!G180 -> 159 | H7: ='TUNDA IKPP'!H8+'TUNDA IKPP'!H30+'TUNDA IKPP'!H52+'TUNDA IKPP'!H98+'TUNDA IKPP'!H120+'TUNDA IKPP'!H142+'TUNDA IKPP'!H164+'TUNDA IKPP'!H172+'TUNDA IKPP'!H180 -> 39 | I7: ='TUNDA IKPP'!I8+'TUNDA IKPP'!I30+'TUNDA IKPP'!I52+'TUNDA IKPP'!I98+'TUNDA IKPP'!I120+'TUNDA IKPP'!I142+'TUNDA IKPP'!I164+'TUNDA IKPP'!I172+'TUNDA IKPP'!I180 -> 34 | J7: ='TUNDA IKPP'!J8+'TUNDA IKPP'!J30+'TUNDA IKPP'!J52+'TUNDA IKPP'!J98+'TUNDA IKPP'!J120+'TUNDA IKPP'!J142+'TUNDA IKPP'!J164+'TUNDA IKPP'!J172+'TUNDA IKPP'!J180 -> 37 | K7: ='TUNDA IKPP'!K8+'TUNDA IKPP'!K30+'TUNDA IKPP'!K52+'TUNDA IKPP'!K98+'TUNDA IKPP'!K120+'TUNDA IKPP'!K142+'TUNDA IKPP'!K164+'TUNDA IKPP'!K172+'TUNDA IKPP'!K180 -> 35 | L7: ='TUNDA IKPP'!L8+'TUNDA IKPP'!L30+'TUNDA IKPP'!L52+'TUNDA IKPP'!L98+'TUNDA IKPP'!L120+'TUNDA IKPP'!L142+'TUNDA IKPP'!L164+'TUNDA IKPP'!L172+'TUNDA IKPP'!L180 -> 34 | ... P7: ='TUNDA IKPP'!P8+'TUNDA IKPP'!P30+'TUNDA IKPP'!P52+'TUNDA IKPP'!P98+'TUNDA IKPP'!P120+'TUNDA IKPP'!P142+'TUNDA IKPP'!P164+'TUNDA IKPP'!P172+'TUNDA IKPP'!P180 -> 32 | Q7: =SUM(E7:P7) -> 556
D8: GT | E8: ='TUNDA IKPP'!E9+'TUNDA IKPP'!E31+'TUNDA IKPP'!E53+'TUNDA IKPP'!E99+'TUNDA IKPP'!E121+'TUNDA IKPP'!E143+'TUNDA IKPP'!E165+'TUNDA IKPP'!E173+'TUNDA IKPP'!E181 -> 263773 | F8: ='TUNDA IKPP'!F9+'TUNDA IKPP'!F31+'TUNDA IKPP'!F53+'TUNDA IKPP'!F99+'TUNDA IKPP'!F121+'TUNDA IKPP'!F143+'TUNDA IKPP'!F165+'TUNDA IKPP'!F173+'TUNDA IKPP'!F181 -> 203390 | G8: ='TUNDA IKPP'!G9+'TUNDA IKPP'!G31+'TUNDA IKPP'!G53+'TUNDA IKPP'!G99+'TUNDA IKPP'!G121+'TUNDA IKPP'!G143+'TUNDA IKPP'!G165+'TUNDA IKPP'!G173+'TUNDA IKPP'!G181 -> 1340528 | H8: ='TUNDA IKPP'!H9+'TUNDA IKPP'!H31+'TUNDA IKPP'!H53+'TUNDA IKPP'!H99+'TUNDA IKPP'!H121+'TUNDA IKPP'!H143+'TUNDA IKPP'!H165+'TUNDA IKPP'!H173+'TUNDA IKPP'!H181 -> 352434.49 | I8: ='TUNDA IKPP'!I9+'TUNDA IKPP'!I31+'TUNDA IKPP'!I53+'TUNDA IKPP'!I99+'TUNDA IKPP'!I121+'TUNDA IKPP'!I143+'TUNDA IKPP'!I165+'TUNDA IKPP'!I173+'TUNDA IKPP'!I181 -> 153376.2 | J8: ='TUNDA IKPP'!J9+'TUNDA IKPP'!J31+'TUNDA IKPP'!J53+'TUNDA IKPP'!J99+'TUNDA IKPP'!J121+'TUNDA IKPP'!J143+'TUNDA IKPP'!J165+'TUNDA IKPP'!J173+'TUNDA IKPP'!J181 -> 331503.44 | K8: ='TUNDA IKPP'!K9+'TUNDA IKPP'!K31+'TUNDA IKPP'!K53+'TUNDA IKPP'!K99+'TUNDA IKPP'!K121+'TUNDA IKPP'!K143+'TUNDA IKPP'!K165+'TUNDA IKPP'!K173+'TUNDA IKPP'!K181 -> 170593.35 | L8: ='TUNDA IKPP'!L9+'TUNDA IKPP'!L31+'TUNDA IKPP'!L53+'TUNDA IKPP'!L99+'TUNDA IKPP'!L121+'TUNDA IKPP'!L143+'TUNDA IKPP'!L165+'TUNDA IKPP'!L173+'TUNDA IKPP'!L181 -> 258839.47 | ... P8: ='TUNDA IKPP'!P9+'TUNDA IKPP'!P31+'TUNDA IKPP'!P53+'TUNDA IKPP'!P99+'TUNDA IKPP'!P121+'TUNDA IKPP'!P143+'TUNDA IKPP'!P165+'TUNDA IKPP'!P173+'TUNDA IKPP'!P181 -> 274917.8 | Q8: =SUM(E8:P8) -> 4073742
D9: Kpl Jam | E9: ='TUNDA IKPP'!E201 -> 154.9856 | F9: ='TUNDA IKPP'!F201 -> 179.2021 | G9: ='TUNDA IKPP'!G201 -> 140.4557 | H9: ='TUNDA IKPP'!H201 -> 188.8887 | I9: ='TUNDA IKPP'!I201 -> 164.6722 | J9: ='TUNDA IKPP'!J201 -> 179.2021 | K9: ='TUNDA IKPP'!K201 -> 169.5155 | L9: ='TUNDA IKPP'!L201 -> 164.6722 | ... P9: ='TUNDA IKPP'!P201 -> 154.9856 | Q9: =SUM(E9:P9) -> 2063.2458
D10: GT Kpl Jam | E10: ='TUNDA IKPP'!E202 -> 1277531.8 | F10: ='TUNDA IKPP'!F202 -> 985078.79 | G10: ='TUNDA IKPP'!G202 -> 1319770.2 | H10: ='TUNDA IKPP'!H202 -> 1706945.9 | I10: ='TUNDA IKPP'!I202 -> 742846.95 | J10: ='TUNDA IKPP'!J202 -> 1605570.6 | K10: ='TUNDA IKPP'!K202 -> 826234.77 | L10: ='TUNDA IKPP'!L202 -> 1253637.2 | ... P10: ='TUNDA IKPP'!P202 -> 1331509.4 | Q10: =SUM(E10:P10) -> 14557546
B11: PELSUS | C11: PANDU | D11: Call | E11: =#REF!+#REF!+#REF!+#REF!+#REF!+#REF!+#REF!+#REF!+#REF!+#REF! -> #REF! | F11: =#REF!+#REF!+#REF!+#REF!+#REF!+#REF!+#REF!+#REF!+#REF!+#REF! -> #REF! | G11: =#REF!+#REF!+#REF!+#REF!+#REF!+#REF!+#REF!+#REF!+#REF!+#REF! -> #REF! | H11: =#REF!+#REF!+#REF!+#REF!+#REF!+#REF!+#REF!+#REF!+#REF!+#REF! -> #REF! | I11: =#REF!+#REF!+#REF!+#REF!+#REF!+#REF!+#REF!+#REF!+#REF!+#REF! -> #REF! | J11: =#REF!+#REF!+#REF!+#REF!+#REF!+#REF!+#REF!+#REF!+#REF!+#REF! -> #REF! | K11: =#REF!+#REF!+#REF!+#REF!+#REF!+#REF!+#REF!+#REF!+#REF!+#REF! -> #REF! | L11: =#REF!+#REF!+#REF!+#REF!+#REF!+#REF!+#REF!+#REF!+#REF!+#REF! -> #REF! | ... P11: =#REF!+#REF!+#REF!+#REF!+#REF!+#REF!+#REF!+#REF!+#REF!+#REF! -> #REF! | Q11: =SUM(E11:P11) -> #REF!
D12: GT | E12: =#REF!+#REF!+#REF!+#REF!+#REF!+#REF!+#REF!+#REF!+#REF!+#REF! -> #REF! | F12: =#REF!+#REF!+#REF!+#REF!+#REF!+#REF!+#REF!+#REF!+#REF!+#REF! -> #REF! | G12: =#REF!+#REF!+#REF!+#REF!+#REF!+#REF!+#REF!+#REF!+#REF!+#REF! -> #REF! | H12: =#REF!+#REF!+#REF!+#REF!+#REF!+#REF!+#REF!+#REF!+#REF!+#REF! -> #REF! | I12: =#REF!+#REF!+#REF!+#REF!+#REF!+#REF!+#REF!+#REF!+#REF!+#REF! -> #REF! | J12: =#REF!+#REF!+#REF!+#REF!+#REF!+#REF!+#REF!+#REF!+#REF!+#REF! -> #REF! | K12: =#REF!+#REF!+#REF!+#REF!+#REF!+#REF!+#REF!+#REF!+#REF!+#REF! -> #REF! | L12: =#REF!+#REF!+#REF!+#REF!+#REF!+#REF!+#REF!+#REF!+#REF!+#REF! -> #REF! | ... P12: =#REF!+#REF!+#REF!+#REF!+#REF!+#REF!+#REF!+#REF!+#REF!+#REF! -> #REF! | Q12: =SUM(E12:P12) -> #REF!
D13: Kpl.Grk | E13: =#REF! -> #REF! | F13: =#REF! -> #REF! | G13: =#REF! -> #REF! | H13: =#REF! -> #REF! | I13: =#REF! -> #REF! | J13: =#REF! -> #REF! | K13: =#REF! -> #REF! | L13: =#REF! -> #REF! | ... P13: =#REF! -> #REF! | Q13: =SUM(E13:P13) -> #REF!
D14: GT.Kpl.Grk | E14: =#REF! -> #REF! | F14: =#REF! -> #REF! | G14: =#REF! -> #REF! | H14: =#REF! -> #REF! | I14: =#REF! -> #REF! | J14: =#REF! -> #REF! | K14: =#REF! -> #REF! | L14: =#REF! -> #REF! | ... P14: =#REF! -> #REF! | Q14: =SUM(E14:P14) -> #REF!
C15: TUNDA | D15: Call | E15: =#REF!+#REF!+#REF!+#REF!+#REF!+#REF!+#REF!+#REF!+#REF!+#REF!+#REF! -> #REF! | F15: =#REF!+#REF!+#REF!+#REF!+#REF!+#REF!+#REF!+#REF!+#REF!+#REF!+#REF! -> #REF! | G15: =#REF!+#REF!+#REF!+#REF!+#REF!+#REF!+#REF!+#REF!+#REF!+#REF!+#REF! -> #REF! | H15: =#REF!+#REF!+#REF!+#REF!+#REF!+#REF!+#REF!+#REF!+#REF!+#REF!+#REF! -> #REF! | I15: =#REF!+#REF!+#REF!+#REF!+#REF!+#REF!+#REF!+#REF!+#REF!+#REF!+#REF! -> #REF! | J15: =#REF!+#REF!+#REF!+#REF!+#REF!+#REF!+#REF!+#REF!+#REF!+#REF!+#REF! -> #REF! | K15: =#REF!+#REF!+#REF!+#REF!+#REF!+#REF!+#REF!+#REF!+#REF!+#REF!+#REF! -> #REF! | L15: =#REF!+#REF!+#REF!+#REF!+#REF!+#REF!+#REF!+#REF!+#REF!+#REF!+#REF! -> #REF! | ... P15: =#REF!+#REF!+#REF!+#REF!+#REF!+#REF!+#REF!+#REF!+#REF!+#REF!+#REF! -> #REF! | Q15: =SUM(E15:P15) -> #REF!
D16: GT | E16: =#REF!+#REF!+#REF!+#REF!+#REF!+#REF!+#REF!+#REF!+#REF!+#REF!+#REF! -> #REF! | F16: =#REF!+#REF!+#REF!+#REF!+#REF!+#REF!+#REF!+#REF!+#REF!+#REF!+#REF! -> #REF! | G16: =#REF!+#REF!+#REF!+#REF!+#REF!+#REF!+#REF!+#REF!+#REF!+#REF!+#REF! -> #REF! | H16: =#REF!+#REF!+#REF!+#REF!+#REF!+#REF!+#REF!+#REF!+#REF!+#REF!+#REF! -> #REF! | I16: =#REF!+#REF!+#REF!+#REF!+#REF!+#REF!+#REF!+#REF!+#REF!+#REF!+#REF! -> #REF! | J16: =#REF!+#REF!+#REF!+#REF!+#REF!+#REF!+#REF!+#REF!+#REF!+#REF!+#REF! -> #REF! | K16: =#REF!+#REF!+#REF!+#REF!+#REF!+#REF!+#REF!+#REF!+#REF!+#REF!+#REF! -> #REF! | L16: =#REF!+#REF!+#REF!+#REF!+#REF!+#REF!+#REF!+#REF!+#REF!+#REF!+#REF! -> #REF! | ... P16: =#REF!+#REF!+#REF!+#REF!+#REF!+#REF!+#REF!+#REF!+#REF!+#REF!+#REF! -> #REF! | Q16: =SUM(E16:P16) -> #REF!
D17: Kpl Jam | E17: =#REF! -> #REF! | F17: =#REF! -> #REF! | G17: =#REF! -> #REF! | H17: =#REF! -> #REF! | I17: =#REF! -> #REF! | J17: =#REF! -> #REF! | K17: =#REF! -> #REF! | L17: =#REF! -> #REF! | ... P17: =#REF! -> #REF! | Q17: =SUM(E17:P17) -> #REF!
D18: GT Kpl Jam | E18: =#REF! -> #REF! | F18: =#REF! -> #REF! | G18: =#REF! -> #REF! | H18: =#REF! -> #REF! | I18: =#REF! -> #REF! | J18: =#REF! -> #REF! | K18: =#REF! -> #REF! | L18: =#REF! -> #REF! | ... P18: =#REF! -> #REF! | Q18: =SUM(E18:P18) -> #REF!

Sheet TRAFIK baru
K1: 1.25
A3: No | B3: Uraian | C3: Satuan | D3: 45292 | E3: 45323 | F3: 45352 | G3: 45383 | H3: 45413 | I3: 45444 | J3: Realisasi sd Juni 24 | K3: 45474 | L3: 45505 | M3: 45536 | N3: 45566 | O3: 45597 | P3: 45627 | Q3: Prognosa 2024 | R3: Semester 2 | T3: 45658 | U3: 45689 | V3: 45717 | W3: 45748 | X3: 45778 | Y3: 45809 | Z3: 45839 | AA3: 45870 | AB3: 45901 | AC3: 45931 | AD3: 45962 | AE3: 45992 | AF3: RKAP 2025 | AI3: No | AJ3: Uraian | AK3: Satuan | AL3: 45292 | AM3: 45323 | AN3: 45352 | AO3: 45383 | AP3: 45413 | AQ3: Realisasi sd Mei 24 | AR3: 45444 | AS3: 45474 | AT3: 45505 | AU3: 45536 | AV3: 45566 | AW3: 45597 | AX3: 45627 | AY3: Prognosa 2024 | AZ3: 45658 | BA3: 45689 | BB3: 45717 | BC3: 45748 | BD3: 45778 | BE3: 45809 | BF3: 45839 | BG3: 45870 | BH3: 45901 | BI3: 45931 | BJ3: 45962 | BK3: 45992 | BL3: RKAP 2025
A4: 1 | B4: Dermaga Umum | C4: Call | D4: =D6+D8 -> 72 | E4: =E6+E8 -> 58 | F4: =F6+F8 -> 63 | G4: =G6+G8 -> 182 | H4: =H6+H8 -> 63 | I4: =I6+I8 -> 37 | J4: =SUM(D4:I4) -> 475 | K4: =K6+K8 -> 35 | L4: =L6+L8 -> 34 | M4: =M6+M8 -> 37 | N4: =N6+N8 -> 43 | O4: =O6+O8 -> 37 | P4: =P6+P8 -> 32 | Q4: =SUM(J4:P4) -> 693 | R4: =Q4-J4 -> 218 | T4: =T6+T8 -> 38 | U4: =U6+U8 -> 37 | V4: =V6+V8 -> 177 | W4: =W6+W8 -> 36 | X4: =X6+X8 -> 36 | Y4: =Y6+Y8 -> 33 | Z4: =Z6+Z8 -> 52 | AA4: =AA6+AA8 -> 60 | ... AE4: =AE6+AE8 -> 50 | AF4: =SUM(T4:AE4) -> 680 | AI4: 1 | AJ4: Dermaga Umum | AK4: Call | AL4: 72 | AM4: 58 | AN4: 63 | AO4: 182 | AP4: 63 | AQ4: 438 | AR4: 45.136024 | AS4: 85.540233 | AT4: 103.67101 | AU4: 93.099203 | AV4: 86.170068 | AW4: 102.64039 | AX4: 85.387311 | AY4: 1039.6442 | AZ4: 73.44 | BA4: 57.12 | BB4: 64.26 | BC4: 183.6 | BD4: 64.26 | BE4: 46.038745 | BF4: 87.251037 | BG4: 105.74443 | BH4: 94.961187 | BI4: 87.89347 | BJ4: 104.6932 | BK4: 87.095057 | BL4: 1056.3571
C5: GT | D5: =D7+D9 -> 465142 | E5: =E7+E9 -> 434175 | F5: =F7+F9 -> 526613 | G5: =G7+G9 -> 1383182 | H5: =H7+H9 -> 454798 | I5: =I7+I9 -> 331503.44 | J5: =SUM(D5:I5) -> 3595413.4 | K5: =K7+K9 -> 673915.7 | L5: =L7+L9 -> 609201.25 | M5: =M7+M9 -> 675550 | N5: =N7+N9 -> 265463.75 | O5: =O7+O9 -> 517410 | P5: =P7+P9 -> 431443.06 | Q5: =SUM(J5:P5) -> 6768397.2 | R5: =Q5-J5 -> 3172983.8 | T5: =T7+T9 -> 228260 | U5: =U7+U9 -> 164061 | V5: =V7+V9 -> 1393196.2 | W5: =W7+W9 -> 318287 | X5: =X7+X9 -> 126855 | Y5: =Y7+Y9 -> 305794 | Z5: =Z7+Z9 -> 185268 | AA5: =AA7+AA9 -> 285324 | ... AE5: =AE7+AE9 -> 288530 | AF5: =SUM(T5:AE5) -> 4035194.2 | AK5: GT | AL5: 465142 | AM5: 434175 | AN5: 526613 | AO5: 1383182 | AP5: 454798 | AQ5: 3263910 | AR5: 148982.77 | AS5: 400537.71 | AT5: 491866.08 | AU5: 433835.63 | AV5: 442268.56 | AW5: 473836.65 | AX5: 381978.45 | AY5: 6037215.8 | AZ5: 474444.84 | BA5: 439417.02 | BB5: 537145.26 | BC5: 1409889.9 | BD5: 463893.96 | BE5: 151962.42 | BF5: 408548.46 | BG5: 501703.41 | BH5: 442512.34 | BI5: 451113.93 | BJ5: 483313.38 | BK5: 389618.02 | BL5: 6153562.9
B6: Kapal Internatinal | C6: Call | D6: 16 | E6: 17 | F6: 16 | G6: 10 | H6: 14 | I6: ='PANDU IKPP'!H89 -> 11 | J6: =SUM(D6:I6) -> 84 | K6: ='PANDU IKPP'!I89 -> 11 | L6: ='PANDU IKPP'!J89 -> 8 | M6: ='PANDU IKPP'!K89 -> 10 | N6: ='PANDU IKPP'!L89 -> 13 | O6: ='PANDU IKPP'!M89 -> 10 | P6: ='PANDU IKPP'!N89 -> 9 | Q6: =SUM(J6:P6) -> 145 | R6: =Q6-J6 -> 61 | T6: ='PANDU IKPP'!W89 -> 14 | U6: ='PANDU IKPP'!X89 -> 11 | V6: ='PANDU IKPP'!Y89 -> 6 | W6: ='PANDU IKPP'!Z89 -> 8 | X6: ='PANDU IKPP'!AA89 -> 7 | Y6: ='PANDU IKPP'!AB89 -> 7 | Z6: ='PANDU IKPP'!AC89 -> 11 | AA6: ='PANDU IKPP'!AD89 -> 14 | ... AE6: ='PANDU IKPP'!AH89 -> 11 | AF6: =SUM(T6:AE6) -> 120 | AJ6: Kapal Internatinal | AK6: Call | AL6: 16 | AM6: 17 | AN6: 16 | AO6: 10 | AP6: 14 | AQ6: 73 | AR6: 5.6181396 | AS6: 19.191667 | AT6: 21.123865 | AU6: 19.528246 | AV6: 19.725277 | AW6: 20.039153 | AX6: 16.485273 | AY6: 194.71162 | AZ6: 16.32 | BA6: 15.3 | BB6: 16.32 | BC6: 8.16 | BD6: 14.28 | BE6: 5.7305024 | BF6: 19.5755 | BG6: 21.546343 | BH6: 19.918811 | BI6: 20.119783 | BJ6: 20.439936 | BK6: 16.814978 | BL6: 194.52585
C7: GT | D7: 310995 | E7: 333214 | F7: 439479 | G7: 125237 | H7: 334888 | I7: ='PANDU IKPP'!H90 -> 225244.44 | J7: =SUM(D7:I7) -> 1769057.4 | K7: =D7*$K$1 -> 388743.75 | L7: =E7*$K$1 -> 416517.5 | M7: =F7*$K$1 -> 549348.75 | N7: =G7*$K$1 -> 156546.25 | O7: =H7*$K$1 -> 418610 | P7: =I7*$K$1 -> 281555.56 | Q7: =SUM(J7:P7) -> 3980379.2 | R7: =Q7-J7 -> 2211321.8 | T7: ='PANDU IKPP'!W90 -> 182605 | U7: ='PANDU IKPP'!X90 -> 95130 | V7: ='PANDU IKPP'!Y90 -> 195082 | W7: ='PANDU IKPP'!Z90 -> 260668 | X7: ='PANDU IKPP'!AA90 -> 61991 | Y7: ='PANDU IKPP'!AB90 -> 225246 | Z7: ='PANDU IKPP'!AC90 -> 88989 | AA7: ='PANDU IKPP'!AD90 -> 163604 | ... AE7: ='PANDU IKPP'!AH90 -> 184924 | AF7: =SUM(T7:AE7) -> 1877104 | AK7: GT | AL7: 310995 | AM7: 333214 | AN7: 439479 | AO7: 125237 | AP7: 334888 | AQ7: 1543813 | AR7: 83319.099 | AS7: 279205.84 | AT7: 344697.36 | AU7: 292024.55 | AV7: 318582.86 | AW7: 327013.05 | AX7: 266353.03 | AY7: 3455008.8 | AZ7: 317214.9 | BA7: 336436.8 | BB7: 448268.58 | BC7: 126786 | BD7: 341585.76 | BE7: 84985.481 | BF7: 284789.95 | BG7: 351591.3 | BH7: 297865.04 | BI7: 324954.52 | BJ7: 333553.32 | BK7: 271680.09 | BL7: 3519711.7
B8: Kapal Domestik | C8: Call | D8: 56 | E8: 41 | F8: 47 | G8: 172 | H8: 49 | I8: ='PANDU IKPP'!H91 -> 26 | J8: =SUM(D8:I8) -> 391 | K8: ='PANDU IKPP'!I91 -> 24 | L8: ='PANDU IKPP'!J91 -> 26 | M8: ='PANDU IKPP'!K91 -> 27 | N8: ='PANDU IKPP'!L91 -> 30 | O8: ='PANDU IKPP'!M91 -> 27 | P8: ='PANDU IKPP'!N91 -> 23 | Q8: =SUM(J8:P8) -> 548 | R8: =Q8-J8 -> 157 | T8: ='PANDU IKPP'!W91 -> 24 | U8: ='PANDU IKPP'!X91 -> 26 | V8: ='PANDU IKPP'!Y91 -> 171 | W8: ='PANDU IKPP'!Z91 -> 28 | X8: ='PANDU IKPP'!AA91 -> 29 | Y8: ='PANDU IKPP'!AB91 -> 26 | Z8: ='PANDU IKPP'!AC91 -> 41 | AA8: ='PANDU IKPP'!AD91 -> 46 | ... AE8: ='PANDU IKPP'!AH91 -> 39 | AF8: =SUM(T8:AE8) -> 560 | AJ8: Kapal Domestik | AK8: Call | AL8: 56 | AM8: 41 | AN8: 47 | AO8: 172 | AP8: 49 | AQ8: 365 | AR8: 39.517885 | AS8: 66.348566 | AT8: 82.547144 | AU8: 73.570957 | AV8: 66.444791 | AW8: 82.601235 | AX8: 68.902038 | AY8: 844.93261 | AZ8: 57.12 | BA8: 41.82 | BB8: 47.94 | BC8: 175.44 | BD8: 49.98 | BE8: 40.308242 | BF8: 67.675537 | BG8: 84.198087 | BH8: 75.042376 | BI8: 67.773687 | BJ8: 84.253259 | BK8: 70.280079 | BL8: 861.83127
C9: GT | D9: 154147 | E9: 100961 | F9: 87134 | G9: 1257945 | H9: 119910 | I9: ='PANDU IKPP'!H92 -> 106259 | J9: =SUM(D9:I9) -> 1826356 | K9: =D9*1.85 -> 285171.95 | L9: =D9*$K$1 -> 192683.75 | M9: =E9*$K$1 -> 126201.25 | N9: =F9*$K$1 -> 108917.5 | O9: =79040*$K$1 -> 98800 | P9: =H9*$K$1 -> 149887.5 | Q9: =SUM(J9:P9) -> 2788018 | R9: =Q9-J9 -> 961661.95 | T9: ='PANDU IKPP'!W92 -> 45655 | U9: ='PANDU IKPP'!X92 -> 68931 | V9: ='PANDU IKPP'!Y92 -> 1198114.2 | W9: ='PANDU IKPP'!Z92 -> 57619 | X9: ='PANDU IKPP'!AA92 -> 64864 | Y9: ='PANDU IKPP'!AB92 -> 80548 | Z9: ='PANDU IKPP'!AC92 -> 96279 | AA9: ='PANDU IKPP'!AD92 -> 121720 | ... AE9: ='PANDU IKPP'!AH92 -> 103606 | AF9: =SUM(T9:AE9) -> 2158090.2 | AK9: GT | AL9: 154147 | AM9: 100961 | AN9: 87134 | AO9: 1257945 | AP9: 119910 | AQ9: 1720097 | AR9: 65663.67 | AS9: 121331.87 | AT9: 147168.73 | AU9: 141811.08 | AV9: 123685.7 | AW9: 146823.6 | AX9: 115625.42 | AY9: 2582207.1 | AZ9: 157229.94 | BA9: 102980.22 | BB9: 88876.68 | BC9: 1283103.9 | BD9: 122308.2 | BE9: 66976.943 | BF9: 123758.51 | BG9: 150112.1 | BH9: 144647.3 | BI9: 126159.41 | BJ9: 149760.07 | BK9: 117937.93 | BL9: 2633851.2
A10: 2 | B10: Non Dermaga Umum | C10: Call | D10: =D12+D14 -> 292 | E10: =E12+E14 -> 250 | F10: =F12+F14 -> 277 | G10: =G12+G14 -> 258 | H10: =H12+H14 -> 264 | I10: =I12+I14 -> #REF! | J10: =SUM(D10:I10) -> #REF! | K10: =K12+K14 -> #REF! | L10: =L12+L14 -> #REF! | M10: =M12+M14 -> #REF! | N10: =N12+N14 -> #REF! | O10: =O12+O14 -> #REF! | P10: =P12+P14 -> #REF! | Q10: =SUM(J10:P10) -> #REF! | T10: =T12+T14 -> #REF! | U10: =U12+U14 -> #REF! | V10: =V12+V14 -> #REF! | W10: =W12+W14 -> #REF! | X10: =X12+X14 -> #REF! | Y10: =Y12+Y14 -> #REF! | Z10: =Z12+Z14 -> #REF! | AA10: =AA12+AA14 -> #REF! | ... AE10: =AE12+AE14 -> #REF! | AF10: =SUM(T10:AE10) -> #REF! | AI10: 2 | AJ10: Non Dermaga Umum | AK10: Call | AL10: 292 | AM10: 250 | AN10: 277 | AO10: 258 | AP10: 264 | AQ10: 1341 | AR10: 255 | AS10: 252 | AT10: 323.17494 | AU10: 349.02572 | AV10: 332.80451 | AW10: 328.37651 | AX10: 340.25558 | AY10: 3521.6373 | AZ10: 340.76 | BA10: 297.5 | BB10: 325.31 | BC10: 305.74 | BD10: 311.92 | BE10: 302.65 | BF10: 299.56 | BG10: 372.87019 | BH10: 399.49649 | BI10: 382.78864 | BJ10: 378.22781 | BK10: 390.46324 | BL10: 4107.2864
C11: GT | D11: =D13+D15 -> 2718105 | E11: =E13+E15 -> 2575912 | F11: =F13+F15 -> 3591621 | G11: =G13+G15 -> 2743511 | H11: =H13+H15 -> 2631934 | I11: =I13+I15 -> #REF! | J11: =SUM(D11:I11) -> #REF! | K11: =K13+K15 -> #REF! | L11: =L13+L15 -> #REF! | M11: =M13+M15 -> #REF! | N11: =N13+N15 -> #REF! | O11: =O13+O15 -> #REF! | P11: =P13+P15 -> #REF! | Q11: =SUM(J11:P11) -> #REF! | T11: =T13+T15 -> #REF! | U11: =U13+U15 -> #REF! | V11: =V13+V15 -> #REF! | W11: =W13+W15 -> #REF! | X11: =X13+X15 -> #REF! | Y11: =Y13+Y15 -> #REF! | Z11: =Z13+Z15 -> #REF! | AA11: =AA13+AA15 -> #REF! | ... AE11: =AE13+AE15 -> #REF! | AF11: =SUM(T11:AE11) -> #REF! | AK11: GT | AL11: 2718105 | AM11: 2575912 | AN11: 3591621 | AO11: 2743511 | AP11: 2631934 | AQ11: 14261083 | AR11: 2594157 | AS11: 2512076 | AT11: 2332269 | AU11: 2541234.6 | AV11: 2290931.1 | AW11: 2431265.3 | AX11: 2445923.6 | AY11: 31408940 | AZ11: 3044657.2 | BA11: 2898198.4 | BB11: 3932533.2 | BC11: 3070825.4 | BD11: 2955901.1 | BE11: 2981634.5 | BF11: 2497316.9 | BG11: 2647246.1 | BH11: 2862480.6 | BI11: 2604668 | BJ11: 2749212.3 | BK11: 2764310.3 | BL11: 35008984
B12: Kapal Internatinal | C12: Call | D12: 53 | E12: 46 | F12: 63 | G12: 41 | H12: 40 | I12: =#REF! -> #REF! | J12: =SUM(D12:I12) -> #REF! | K12: =#REF! -> #REF! | L12: =#REF! -> #REF! | M12: =#REF! -> #REF! | N12: =#REF! -> #REF! | O12: =#REF! -> #REF! | P12: =#REF! -> #REF! | Q12: =SUM(J12:P12) -> #REF! | T12: =#REF! -> #REF! | U12: =#REF! -> #REF! | V12: =#REF! -> #REF! | W12: =#REF! -> #REF! | X12: =#REF! -> #REF! | Y12: =#REF! -> #REF! | Z12: =#REF! -> #REF! | AA12: =#REF! -> #REF! | ... AE12: =#REF! -> #REF! | AF12: =SUM(T12:AE12) -> #REF! | AJ12: Kapal Internatinal | AK12: Call | AL12: 53 | AM12: 46 | AN12: 63 | AO12: 41 | AP12: 40 | AQ12: 243 | AR12: 42 | AS12: 48 | AT12: 58.286965 | AU12: 59.604584 | AV12: 59.082527 | AW12: 55.547405 | AX12: 57.423255 | AY12: 622.94474 | AZ12: 54.59 | BA12: 47.38 | BB12: 64.89 | BC12: 42.23 | BD12: 41.2 | BE12: 43.26 | BF12: 49.44 | BG12: 60.035574 | BH12: 61.392722 | BI12: 60.855003 | BJ12: 57.213828 | BK12: 59.145953 | BL12: 641.63308
C13: GT | D13: 1046679 | E13: 777181 | F13: 1635212 | G13: 817527 | H13: 670045 | I13: =#REF! -> #REF! | J13: =SUM(D13:I13) -> #REF! | K13: =#REF! -> #REF! | L13: =#REF! -> #REF! | M13: =#REF! -> #REF! | N13: =#REF! -> #REF! | O13: =#REF! -> #REF! | P13: =#REF! -> #REF! | Q13: =SUM(J13:P13) -> #REF! | T13: =#REF! -> #REF! | U13: =#REF! -> #REF! | V13: =#REF! -> #REF! | W13: =#REF! -> #REF! | X13: =#REF! -> #REF! | Y13: =#REF! -> #REF! | Z13: =#REF! -> #REF! | AA13: =#REF! -> #REF! | ... AE13: =#REF! -> #REF! | AF13: =SUM(T13:AE13) -> #REF! | AK13: GT | AL13: 1046679 | AM13: 777181 | AN13: 1635212 | AO13: 817527 | AP13: 670045 | AQ13: 4946644 | AR13: 723685 | AS13: 673088 | AT13: 771351.54 | AU13: 857478.32 | AV13: 669068.38 | AW13: 789965.41 | AX13: 781963.37 | AY13: 10213244 | AZ13: 1078079.4 | BA13: 800496.43 | BB13: 1684268.4 | BC13: 842052.81 | BD13: 690146.35 | BE13: 745395.55 | BF13: 693280.64 | BG13: 794492.09 | BH13: 883202.67 | BI13: 689140.43 | BJ13: 813664.38 | BK13: 805422.27 | BL13: 10519641
B14: Kapal Domestik | C14: Call | D14: 239 | E14: 204 | F14: 214 | G14: 217 | H14: 224 | I14: =#REF! -> #REF! | J14: =SUM(D14:I14) -> #REF! | K14: =#REF! -> #REF! | L14: =#REF! -> #REF! | M14: =#REF! -> #REF! | N14: =#REF! -> #REF! | O14: =#REF! -> #REF! | P14: =#REF! -> #REF! | Q14: =SUM(J14:P14) -> #REF! | T14: =#REF! -> #REF! | U14: =#REF! -> #REF! | V14: =#REF! -> #REF! | W14: =#REF! -> #REF! | X14: =#REF! -> #REF! | Y14: =#REF! -> #REF! | Z14: =#REF! -> #REF! | AA14: =#REF! -> #REF! | ... AE14: =#REF! -> #REF! | AF14: =SUM(T14:AE14) -> #REF! | AJ14: Kapal Domestik | AK14: Call | AL14: 239 | AM14: 204 | AN14: 214 | AO14: 217 | AP14: 224 | AQ14: 1098 | AR14: 213 | AS14: 204 | AT14: 264.88798 | AU14: 289.42114 | AV14: 273.72198 | AW14: 272.82911 | AX14: 282.83232 | AY14: 2898.6925 | AZ14: 286.17 | BA14: 250.12 | BB14: 260.42 | BC14: 263.51 | BD14: 270.72 | BE14: 259.39 | BF14: 250.12 | BG14: 312.83461 | BH14: 338.10377 | BI14: 321.93364 | BJ14: 321.01398 | BK14: 331.31729 | BL14: 3465.6533
C15: GT | D15: 1671426 | E15: 1798731 | F15: 1956409 | G15: 1925984 | H15: 1961889 | I15: =#REF! -> #REF! | J15: =SUM(D15:I15) -> #REF! | K15: =#REF! -> #REF! | L15: =#REF! -> #REF! | M15: =#REF! -> #REF! | N15: =#REF! -> #REF! | O15: =#REF! -> #REF! | P15: =#REF! -> #REF! | Q15: =SUM(J15:P15) -> #REF! | T15: =#REF! -> #REF! | U15: =#REF! -> #REF! | V15: =#REF! -> #REF! | W15: =#REF! -> #REF! | X15: =#REF! -> #REF! | Y15: =#REF! -> #REF! | Z15: =#REF! -> #REF! | AA15: =#REF! -> #REF! | ... AE15: =#REF! -> #REF! | AF15: =SUM(T15:AE15) -> #REF! | AK15: GT | AL15: 1671426 | AM15: 1798731 | AN15: 1956409 | AO15: 1925984 | AP15: 1961889 | AQ15: 9314439 | AR15: 1870472 | AS15: 1838988 | AT15: 1560917.5 | AU15: 1683756.3 | AV15: 1621862.7 | AW15: 1641299.9 | AX15: 1663960.2 | AY15: 21195696 | AZ15: 1966577.8 | BA15: 2097702 | BB15: 2248264.8 | BC15: 2228772.6 | BD15: 2265754.7 | BE15: 2236239 | BF15: 1804036.3 | BG15: 1852754.1 | BH15: 1979278 | BI15: 1915527.6 | BJ15: 1935547.9 | BK15: 1958888 | BL15: 24489343
A16: TOTAL | C16: Call | D16: =D4+D10 -> 364 | E16: =E4+E10 -> 308 | F16: =F4+F10 -> 340 | G16: =G4+G10 -> 440 | H16: =H4+H10 -> 327 | I16: =I4+I10 -> #REF! | J16: =SUM(D16:I16) -> #REF! | K16: =K4+K10 -> #REF! | L16: =L4+L10 -> #REF! | M16: =M4+M10 -> #REF! | N16: =N4+N10 -> #REF! | O16: =O4+O10 -> #REF! | P16: =P4+P10 -> #REF! | Q16: =SUM(I16:P16) -> #REF! | T16: =T4+T10 -> #REF! | U16: =U4+U10 -> #REF! | V16: =V4+V10 -> #REF! | W16: =W4+W10 -> #REF! | X16: =X4+X10 -> #REF! | Y16: =Y4+Y10 -> #REF! | Z16: =Z4+Z10 -> #REF! | AA16: =AA4+AA10 -> #REF! | ... AE16: =AE4+AE10 -> #REF! | AF16: =SUM(T16:AE16) -> #REF! | AI16: TOTAL | AK16: Call | AL16: 364 | AM16: 308 | AN16: 340 | AO16: 440 | AP16: 327 | AQ16: 1779 | AR16: 300.13602 | AS16: 337.54023 | AT16: 426.84595 | AU16: 442.12492 | AV16: 418.97458 | AW16: 431.0169 | AX16: 425.64289 | AY16: 4561.2815 | AZ16: 414.2 | BA16: 354.62 | BB16: 389.57 | BC16: 489.34 | BD16: 376.18 | BE16: 348.68874 | BF16: 386.81104 | BG16: 478.61462 | BH16: 494.45768 | BI16: 470.68211 | BJ16: 482.921 | BK16: 477.5583 | BL16: 5163.6435
C17: GT | D17: =D5+D11 -> 3183247 | E17: =E5+E11 -> 3010087 | F17: =F5+F11 -> 4118234 | G17: =G5+G11 -> 4126693 | H17: =H5+H11 -> 3086732 | I17: =I5+I11 -> #REF! | J17: =SUM(D17:I17) -> #REF! | K17: =K5+K11 -> #REF! | L17: =L5+L11 -> #REF! | M17: =M5+M11 -> #REF! | N17: =N5+N11 -> #REF! | O17: =O5+O11 -> #REF! | P17: =P5+P11 -> #REF! | Q17: =SUM(I17:P17) -> #REF! | T17: =T5+T11 -> #REF! | U17: =U5+U11 -> #REF! | V17: =V5+V11 -> #REF! | W17: =W5+W11 -> #REF! | X17: =X5+X11 -> #REF! | Y17: =Y5+Y11 -> #REF! | Z17: =Z5+Z11 -> #REF! | AA17: =AA5+AA11 -> #REF! | ... AE17: =AE5+AE11 -> #REF! | AF17: =SUM(T17:AE17) -> #REF! | AK17: GT | AL17: 3183247 | AM17: 3010087 | AN17: 4118234 | AO17: 4126693 | AP17: 3086732 | AQ17: 17524993 | AR17: 2743139.8 | AS17: 2912613.7 | AT17: 2824135.1 | AU17: 2975070.2 | AV17: 2733199.6 | AW17: 2905102 | AX17: 2827902 | AY17: 37446155 | AZ17: 3519102 | BA17: 3337615.4 | BB17: 4469678.4 | BC17: 4480715.3 | BD17: 3419795 | BE17: 3133597 | BF17: 2905865.4 | BG17: 3148949.5 | BH17: 3304993 | BI17: 3055782 | BJ17: 3232525.7 | BK17: 3153928.3 | BL17: 41162547
J20: 2254947.8 | K20: =J20*1.25 -> 2818684.7 | R20: =R5/J5 -> 0.88250873
J21: =G9/J5 -> 0.34987492 | Q21: =R5-J20 -> 918035.99 | R21: =R5/J20 -> 1.4071207
B23: Memori
A24: 1 | B24: Kenaikan Trafik Kapal Sudah Selaras dengan Kenaikan PTP sebesar 25% dari Semester 1
A25: 2 | B25: Trafik GT pada semester 1 sebesar 3,4 Jt GT , sudah termasuk GT Angleb Sebesar 1,2 Jt
A26: 3 | B26: Kontribusi GT Angleb Pada Semester 1 Sebesar 37%

Sheet USULAN
N1: RKAP 2025 | P1: PROGNOSA 2024
N2: 0.035 | O2: Derum | P2: Produksi | S2: Jan | T2: Feb | U2: Mar | V2: Apr | W2: Mei | X2: Jun | Y2: Jul | Z2: Aug | AA2: Sept | AB2: Okt | AC2: Nov | AD2: Des | AE2: JUMLAH | AH2: Jan | AI2: Feb | AJ2: Mar | AK2: Apr | AL2: Mei | AM2: Jun | AN2: Jul | AO2: Aug | AP2: Sept | AQ2: Okt | AR2: Nov | AS2: Des | AT2: JUMLAH
B3: Produksi Pandu dan Tunda Unit Banten | N3: 0.035 | O3: Pelsus | P3: PELUM | Q3: PANDU | R3: Call | S3: ='PANDU IKPP'!C79 -> 32 | T3: ='PANDU IKPP'!D79 -> 37 | U3: ='PANDU IKPP'!E79 -> 159 | V3: ='PANDU IKPP'!F79 -> 39 | W3: ='PANDU IKPP'!G79 -> 34 | X3: ='PANDU IKPP'!H79 -> 37 | Y3: ='PANDU IKPP'!I79 -> 35 | Z3: ='PANDU IKPP'!J79 -> 34 | ... AD3: ='PANDU IKPP'!N79 -> 32 | AE3: =SUM(S3:AD3) -> 556 | AH3: ='PANDU IKPP'!W79 -> 38 | AI3: ='PANDU IKPP'!X79 -> 37 | AJ3: ='PANDU IKPP'!Y79 -> 177 | AK3: ='PANDU IKPP'!Z79 -> 36 | AL3: ='PANDU IKPP'!AA79 -> 36 | AM3: ='PANDU IKPP'!AB79 -> 33 | AN3: ='PANDU IKPP'!AC79 -> 52 | AO3: ='PANDU IKPP'!AD79 -> 60 | ... AS3: ='PANDU IKPP'!AH79 -> 50 | AT3: =SUM(AH3:AS3) -> 680
B4: Area | C4: Layanan | E4: REALISASI 2024 | F4: RKAP 2025 | H4: PROGNOSA 2025 | J4: RKAP 2026 | R4: GT | S4: ='PANDU IKPP'!C80 -> 263773 | T4: ='PANDU IKPP'!D80 -> 203390 | U4: ='PANDU IKPP'!E80 -> 1340528 | V4: ='PANDU IKPP'!F80 -> 352434.49 | W4: ='PANDU IKPP'!G80 -> 153376.2 | X4: ='PANDU IKPP'!H80 -> 331503.44 | Y4: ='PANDU IKPP'!I80 -> 170593.35 | Z4: ='PANDU IKPP'!J80 -> 258839.47 | ... AD4: ='PANDU IKPP'!N80 -> 274917.8 | AE4: =SUM(S4:AD4) -> 4073742 | AH4: ='PANDU IKPP'!W80 -> 228260 | AI4: ='PANDU IKPP'!X80 -> 164061 | AJ4: ='PANDU IKPP'!Y80 -> 1393196.2 | AK4: ='PANDU IKPP'!Z80 -> 318287 | AL4: ='PANDU IKPP'!AA80 -> 126855 | AM4: ='PANDU IKPP'!AB80 -> 305794 | AN4: ='PANDU IKPP'!AC80 -> 185268 | AO4: ='PANDU IKPP'!AD80 -> 285324 | ... AS4: ='PANDU IKPP'!AH80 -> 288530 | AT4: =SUM(AH4:AS4) -> 4035194.2
E5: a | F5: b | H5: c | J5: d | K5: e=c/a | L5: f=c/b | M5: g=d/c | R5: Kpl.Grk | S5: ='PANDU IKPP'!C81 -> 64 | T5: ='PANDU IKPP'!D81 -> 74 | U5: ='PANDU IKPP'!E81 -> 318 | V5: ='PANDU IKPP'!F81 -> 78 | W5: ='PANDU IKPP'!G81 -> 68 | X5: ='PANDU IKPP'!H81 -> 74 | Y5: ='PANDU IKPP'!I81 -> 70 | Z5: ='PANDU IKPP'!J81 -> 68 | ... AD5: ='PANDU IKPP'!N81 -> 64 | AE5: =SUM(S5:AD5) -> 1112 | AH5: ='PANDU IKPP'!W81 -> 76 | AI5: ='PANDU IKPP'!X81 -> 74 | AJ5: ='PANDU IKPP'!Y81 -> 354 | AK5: ='PANDU IKPP'!Z81 -> 72 | AL5: ='PANDU IKPP'!AA81 -> 72 | AM5: ='PANDU IKPP'!AB81 -> 66 | AN5: ='PANDU IKPP'!AC81 -> 104 | AO5: ='PANDU IKPP'!AD81 -> 120 | ... AS5: ='PANDU IKPP'!AH81 -> 100 | AT5: =SUM(AH5:AS5) -> 1360
B6: Derum | C6: Pandu | D6: Kpl Grk | H6: =AE5 -> 1112 | J6: =AT5 -> 1360 | K6: =H6/E6 -> #DIV/0! | L6: =H6/F6 -> #DIV/0! | M6: =J6/H6 -> 1.2230216 | R6: GT.Kpl.Grk | S6: ='PANDU IKPP'!C82 -> 527546 | T6: ='PANDU IKPP'!D82 -> 406780 | U6: ='PANDU IKPP'!E82 -> 2681056 | V6: ='PANDU IKPP'!F82 -> 704868.97 | W6: ='PANDU IKPP'!G82 -> 306752.4 | X6: ='PANDU IKPP'!H82 -> 663006.89 | Y6: ='PANDU IKPP'!I82 -> 341186.7 | Z6: ='PANDU IKPP'!J82 -> 517678.94 | ... AD6: ='PANDU IKPP'!N82 -> 549835.6 | AE6: =SUM(S6:AD6) -> 8147484.1 | AH6: ='PANDU IKPP'!W82 -> 456520 | AI6: ='PANDU IKPP'!X82 -> 328122 | AJ6: ='PANDU IKPP'!Y82 -> 2786392.5 | AK6: ='PANDU IKPP'!Z82 -> 636574 | AL6: ='PANDU IKPP'!AA82 -> 253710 | AM6: ='PANDU IKPP'!AB82 -> 611588 | AN6: ='PANDU IKPP'!AC82 -> 370536 | AO6: ='PANDU IKPP'!AD82 -> 570648 | ... AS6: ='PANDU IKPP'!AH82 -> 577060 | AT6: =SUM(AH6:AS6) -> 8070388.5
D7: GT Kpl Grk | H7: =AE6 -> 8147484.1 | J7: =AT6 -> 8070388.5 | K7: =H7/E7 -> #DIV/0! | L7: =H7/F7 -> #DIV/0! | M7: =J7/H7 -> 0.99053749 | Q7: TUNDA | R7: Call | S7: ='TUNDA IKPP'!E199 -> 32 | T7: ='TUNDA IKPP'!F199 -> 37 | U7: ='TUNDA IKPP'!G199 -> 159 | V7: ='TUNDA IKPP'!H199 -> 39 | W7: ='TUNDA IKPP'!I199 -> 34 | X7: ='TUNDA IKPP'!J199 -> 37 | Y7: ='TUNDA IKPP'!K199 -> 35 | Z7: ='TUNDA IKPP'!L199 -> 34 | ... AD7: ='TUNDA IKPP'!P199 -> 32 | AE7: =SUM(S7:AD7) -> 556 | AH7: ='TUNDA IKPP'!AB199 -> 38 | AI7: ='TUNDA IKPP'!AC199 -> 37 | AJ7: ='TUNDA IKPP'!AD199 -> 177 | AK7: ='TUNDA IKPP'!AE199 -> 36 | AL7: ='TUNDA IKPP'!AF199 -> 36 | AM7: ='TUNDA IKPP'!AG199 -> 33 | AN7: ='TUNDA IKPP'!AH199 -> 52 | AO7: ='TUNDA IKPP'!AI199 -> 60 | ... AS7: ='TUNDA IKPP'!AM199 -> 50 | AT7: =SUM(AH7:AS7) -> 680
C8: Tunda | D8: Kpl Jam | H8: =AE9 -> 2063.2458 | J8: =AT9 -> 2471.2241 | K8: =H8/E8 -> #DIV/0! | L8: =H8/F8 -> #DIV/0! | M8: =J8/H8 -> 1.1977362 | R8: GT | S8: ='TUNDA IKPP'!E200 -> 263773 | T8: ='TUNDA IKPP'!F200 -> 203390 | U8: ='TUNDA IKPP'!G200 -> 1340528 | V8: ='TUNDA IKPP'!H200 -> 352434.49 | W8: ='TUNDA IKPP'!I200 -> 153376.2 | X8: ='TUNDA IKPP'!J200 -> 331503.44 | Y8: ='TUNDA IKPP'!K200 -> 170593.35 | Z8: ='TUNDA IKPP'!L200 -> 258839.47 | ... AD8: ='TUNDA IKPP'!P200 -> 274917.8 | AE8: =SUM(S8:AD8) -> 4073742 | AH8: ='TUNDA IKPP'!AB200 -> 228260 | AI8: ='TUNDA IKPP'!AC200 -> 164061 | AJ8: ='TUNDA IKPP'!AD200 -> 1393196.2 | AK8: ='TUNDA IKPP'!AE200 -> 318287 | AL8: ='TUNDA IKPP'!AF200 -> 126855 | AM8: ='TUNDA IKPP'!AG200 -> 305794 | AN8: ='TUNDA IKPP'!AH200 -> 185268 | AO8: ='TUNDA IKPP'!AI200 -> 285324 | ... AS8: ='TUNDA IKPP'!AM200 -> 288530 | AT8: =SUM(AH8:AS8) -> 4035194.2
D9: GT Kpl Jam | H9: =AE10 -> 14557546 | J9: =AT10 -> 13390749 | K9: =H9/E9 -> #DIV/0! | L9: =H9/F9 -> #DIV/0! | M9: =J9/H9 -> 0.91984935 | R9: Kpl Jam | S9: ='TUNDA IKPP'!E201 -> 154.9856 | T9: ='TUNDA IKPP'!F201 -> 179.2021 | U9: ='TUNDA IKPP'!G201 -> 140.4557 | V9: ='TUNDA IKPP'!H201 -> 188.8887 | W9: ='TUNDA IKPP'!I201 -> 164.6722 | X9: ='TUNDA IKPP'!J201 -> 179.2021 | Y9: ='TUNDA IKPP'!K201 -> 169.5155 | Z9: ='TUNDA IKPP'!L201 -> 164.6722 | ... AD9: ='TUNDA IKPP'!P201 -> 154.9856 | AE9: =SUM(S9:AD9) -> 2063.2458 | AH9: ='TUNDA IKPP'!AB201 -> 173.90096 | AI9: ='TUNDA IKPP'!AC201 -> 169.32462 | AJ9: ='TUNDA IKPP'!AD201 -> 169.32462 | AK9: ='TUNDA IKPP'!AE201 -> 164.74828 | AL9: ='TUNDA IKPP'!AF201 -> 164.74828 | AM9: ='TUNDA IKPP'!AG201 -> 151.01925 | AN9: ='TUNDA IKPP'!AH201 -> 237.96973 | AO9: ='TUNDA IKPP'!AI201 -> 274.58046 | ... AS9: ='TUNDA IKPP'!AM201 -> 228.81705 | AT9: =SUM(AH9:AS9) -> 2471.2241
B10: Pelsus | C10: Pandu | D10: Kpl Grk | H10: =AE13 -> #REF! | J10: =AT13 -> #REF! | K10: =H10/E10 -> #REF! | L10: =H10/F10 -> #REF! | M10: =J10/H10 -> #REF! | R10: GT Kpl Jam | S10: ='TUNDA IKPP'!E202 -> 1277531.8 | T10: ='TUNDA IKPP'!F202 -> 985078.79 | U10: ='TUNDA IKPP'!G202 -> 1319770.2 | V10: ='TUNDA IKPP'!H202 -> 1706945.9 | W10: ='TUNDA IKPP'!I202 -> 742846.95 | X10: ='TUNDA IKPP'!J202 -> 1605570.6 | Y10: ='TUNDA IKPP'!K202 -> 826234.77 | Z10: ='TUNDA IKPP'!L202 -> 1253637.2 | ... AD10: ='TUNDA IKPP'!P202 -> 1331509.4 | AE10: =SUM(S10:AD10) -> 14557546 | AH10: ='TUNDA IKPP'!AB202 -> 1044595.6 | AI10: ='TUNDA IKPP'!AC202 -> 750799.08 | AJ10: ='TUNDA IKPP'!AD202 -> 1300065.3 | AK10: ='TUNDA IKPP'!AE202 -> 1456589.8 | AL10: ='TUNDA IKPP'!AF202 -> 580531.74 | AM10: ='TUNDA IKPP'!AG202 -> 1399417.6 | AN10: ='TUNDA IKPP'!AH202 -> 847849.54 | AO10: ='TUNDA IKPP'!AI202 -> 1305739.9 | ... AS10: ='TUNDA IKPP'!AM202 -> 1320411.7 | AT10: =SUM(AH10:AS10) -> 13390749
D11: GT Kpl Grk | H11: =AE14 -> #REF! | J11: =AT14 -> #REF! | K11: =H11/E11 -> #REF! | L11: =H11/F11 -> #REF! | M11: =J11/H11 -> #REF! | P11: PELSUS | Q11: PANDU | R11: Call | S11: =#REF! -> #REF! | T11: =#REF! -> #REF! | U11: =#REF! -> #REF! | V11: =#REF! -> #REF! | W11: =#REF! -> #REF! | X11: =#REF! -> #REF! | Y11: =#REF! -> #REF! | Z11: =#REF! -> #REF! | ... AD11: =#REF! -> #REF! | AE11: =SUM(S11:AD11) -> #REF! | AH11: =#REF! -> #REF! | AI11: =#REF! -> #REF! | AJ11: =#REF! -> #REF! | AK11: =#REF! -> #REF! | AL11: =#REF! -> #REF! | AM11: =#REF! -> #REF! | AN11: =#REF! -> #REF! | AO11: =#REF! -> #REF! | ... AS11: =#REF! -> #REF! | AT11: =SUM(AH11:AS11) -> #REF!
C12: Tunda | D12: Kpl Jam | H12: =AE17 -> #REF! | J12: =AT17 -> #REF! | K12: =H12/E12 -> #REF! | L12: =H12/F12 -> #REF! | M12: =J12/H12 -> #REF! | R12: GT | S12: =#REF! -> #REF! | T12: =#REF! -> #REF! | U12: =#REF! -> #REF! | V12: =#REF! -> #REF! | W12: =#REF! -> #REF! | X12: =#REF! -> #REF! | Y12: =#REF! -> #REF! | Z12: =#REF! -> #REF! | ... AD12: =#REF! -> #REF! | AE12: =SUM(S12:AD12) -> #REF! | AH12: =#REF! -> #REF! | AI12: =#REF! -> #REF! | AJ12: =#REF! -> #REF! | AK12: =#REF! -> #REF! | AL12: =#REF! -> #REF! | AM12: =#REF! -> #REF! | AN12: =#REF! -> #REF! | AO12: =#REF! -> #REF! | ... AS12: =#REF! -> #REF! | AT12: =SUM(AH12:AS12) -> #REF!
D13: GT Kpl Jam | H13: =AE18 -> #REF! | J13: =AT18 -> #REF! | K13: =H13/E13 -> #REF! | L13: =H13/F13 -> #REF! | M13: =J13/H13 -> #REF! | R13: Kpl.Grk | S13: =#REF! -> #REF! | T13: =#REF! -> #REF! | U13: =#REF! -> #REF! | V13: =#REF! -> #REF! | W13: =#REF! -> #REF! | X13: =#REF! -> #REF! | Y13: =#REF! -> #REF! | Z13: =#REF! -> #REF! | ... AD13: =#REF! -> #REF! | AE13: =SUM(S13:AD13) -> #REF! | AH13: =#REF! -> #REF! | AI13: =#REF! -> #REF! | AJ13: =#REF! -> #REF! | AK13: =#REF! -> #REF! | AL13: =#REF! -> #REF! | AM13: =#REF! -> #REF! | AN13: =#REF! -> #REF! | AO13: =#REF! -> #REF! | ... AS13: =#REF! -> #REF! | AT13: =SUM(AH13:AS13) -> #REF!
B14: Konsolidasi | C14: Pandu | D14: Kpl Grk | E14: =E6+E10 -> 0 | F14: =F6+F10 -> 0 | H14: =H6+H10 -> #REF! | J14: =J6+J10 -> #REF! | K14: =(K6+K10)/2 -> #DIV/0! | L14: =(L6+L10)/2 -> #DIV/0! | M14: =(M6+M10)/2 -> #REF! | R14: GT.Kpl.Grk | S14: =#REF! -> #REF! | T14: =#REF! -> #REF! | U14: =#REF! -> #REF! | V14: =#REF! -> #REF! | W14: =#REF! -> #REF! | X14: =#REF! -> #REF! | Y14: =#REF! -> #REF! | Z14: =#REF! -> #REF! | ... AD14: =#REF! -> #REF! | AE14: =SUM(S14:AD14) -> #REF! | AH14: =#REF! -> #REF! | AI14: =#REF! -> #REF! | AJ14: =#REF! -> #REF! | AK14: =#REF! -> #REF! | AL14: =#REF! -> #REF! | AM14: =#REF! -> #REF! | AN14: =#REF! -> #REF! | AO14: =#REF! -> #REF! | ... AS14: =#REF! -> #REF! | AT14: =SUM(AH14:AS14) -> #REF!
D15: GT Kpl Grk | E15: =E7+E11 -> 0 | F15: =F7+F11 -> 0 | H15: =H7+H11 -> #REF! | J15: =J7+J11 -> #REF! | K15: =(K7+K11)/2 -> #DIV/0! | L15: =(L7+L11)/2 -> #DIV/0! | M15: =(M7+M11)/2 -> #REF! | Q15: TUNDA | R15: Call | S15: =#REF! -> #REF! | T15: =#REF! -> #REF! | U15: =#REF! -> #REF! | V15: =#REF! -> #REF! | W15: =#REF! -> #REF! | X15: =#REF! -> #REF! | Y15: =#REF! -> #REF! | Z15: =#REF! -> #REF! | ... AD15: =#REF! -> #REF! | AE15: =SUM(S15:AD15) -> #REF! | AH15: =#REF! -> #REF! | AI15: =#REF! -> #REF! | AJ15: =#REF! -> #REF! | AK15: =#REF! -> #REF! | AL15: =#REF! -> #REF! | AM15: =#REF! -> #REF! | AN15: =#REF! -> #REF! | AO15: =#REF! -> #REF! | ... AS15: =#REF! -> #REF! | AT15: =SUM(AH15:AS15) -> #REF!
C16: Tunda | D16: Kpl Jam | E16: =E8+E12 -> 0 | F16: =F8+F12 -> 0 | H16: =H8+H12 -> #REF! | J16: =J8+J12 -> #REF! | K16: =(K8+K12)/2 -> #DIV/0! | L16: =(L8+L12)/2 -> #DIV/0! | M16: =(M8+M12)/2 -> #REF! | R16: GT | S16: =#REF! -> #REF! | T16: =#REF! -> #REF! | U16: =#REF! -> #REF! | V16: =#REF! -> #REF! | W16: =#REF! -> #REF! | X16: =#REF! -> #REF! | Y16: =#REF! -> #REF! | Z16: =#REF! -> #REF! | ... AD16: =#REF! -> #REF! | AE16: =SUM(S16:AD16) -> #REF! | AH16: =#REF! -> #REF! | AI16: =#REF! -> #REF! | AJ16: =#REF! -> #REF! | AK16: =#REF! -> #REF! | AL16: =#REF! -> #REF! | AM16: =#REF! -> #REF! | AN16: =#REF! -> #REF! | AO16: =#REF! -> #REF! | ... AS16: =#REF! -> #REF! | AT16: =SUM(AH16:AS16) -> #REF!
D17: GT Kpl Jam | E17: =E9+E13 -> 0 | F17: =F9+F13 -> 0 | H17: =H9+H13 -> #REF! | J17: =J9+J13 -> #REF! | K17: =(K9+K13)/2 -> #DIV/0! | L17: =(L9+L13)/2 -> #DIV/0! | M17: =(M9+M13)/2 -> #REF! | R17: Kpl Jam | S17: =#REF! -> #REF! | T17: =#REF! -> #REF! | U17: =#REF! -> #REF! | V17: =#REF! -> #REF! | W17: =#REF! -> #REF! | X17: =#REF! -> #REF! | Y17: =#REF! -> #REF! | Z17: =#REF! -> #REF! | ... AD17: =#REF! -> #REF! | AE17: =SUM(S17:AD17) -> #REF! | AH17: =#REF! -> #REF! | AI17: =#REF! -> #REF! | AJ17: =#REF! -> #REF! | AK17: =#REF! -> #REF! | AL17: =#REF! -> #REF! | AM17: =#REF! -> #REF! | AN17: =#REF! -> #REF! | AO17: =#REF! -> #REF! | ... AS17: =#REF! -> #REF! | AT17: =SUM(AH17:AS17) -> #REF!
R18: GT Kpl Jam | S18: =#REF! -> #REF! | T18: =#REF! -> #REF! | U18: =#REF! -> #REF! | V18: =#REF! -> #REF! | W18: =#REF! -> #REF! | X18: =#REF! -> #REF! | Y18: =#REF! -> #REF! | Z18: =#REF! -> #REF! | ... AD18: =#REF! -> #REF! | AE18: =SUM(S18:AD18) -> #REF! | AH18: =#REF! -> #REF! | AI18: =#REF! -> #REF! | AJ18: =#REF! -> #REF! | AK18: =#REF! -> #REF! | AL18: =#REF! -> #REF! | AM18: =#REF! -> #REF! | AN18: =#REF! -> #REF! | AO18: =#REF! -> #REF! | ... AS18: =#REF! -> #REF! | AT18: =SUM(AH18:AS18) -> #REF!
B19: Pendapatan Pelayanan Kapal IKPP | P19: KONSOLIDASI | Q19: PANDU | R19: Call | S19: =S3+S11 -> #REF! | T19: =T3+T11 -> #REF! | U19: =U3+U11 -> #REF! | V19: =V3+V11 -> #REF! | W19: =W3+W11 -> #REF! | X19: =X3+X11 -> #REF! | Y19: =Y3+Y11 -> #REF! | Z19: =Z3+Z11 -> #REF! | ... AD19: =AD3+AD11 -> #REF! | AE19: =SUM(S19:AD19) -> #REF! | AH19: =AH3+AH11 -> #REF! | AI19: =AI3+AI11 -> #REF! | AJ19: =AJ3+AJ11 -> #REF! | AK19: =AK3+AK11 -> #REF! | AL19: =AL3+AL11 -> #REF! | AM19: =AM3+AM11 -> #REF! | AN19: =AN3+AN11 -> #REF! | AO19: =AO3+AO11 -> #REF! | ... AS19: =AS3+AS11 -> #REF! | AT19: =SUM(AH19:AS19) -> #REF!
B20: Area | C20: Layanan | D20: Satuan | E20: Realisasi 2024 | F20: RKAP 2025 | G20: Prog Cabang | H20: PROGNOSA 2026 | I20: RKAP 2026 | J20: RKAP 2027 | R20: GT | S20: =S4+S12 -> #REF! | T20: =T4+T12 -> #REF! | U20: =U4+U12 -> #REF! | V20: =V4+V12 -> #REF! | W20: =W4+W12 -> #REF! | X20: =X4+X12 -> #REF! | Y20: =Y4+Y12 -> #REF! | Z20: =Z4+Z12 -> #REF! | ... AD20: =AD4+AD12 -> #REF! | AE20: =SUM(S20:AD20) -> #REF! | AH20: =AH4+AH12 -> #REF! | AI20: =AI4+AI12 -> #REF! | AJ20: =AJ4+AJ12 -> #REF! | AK20: =AK4+AK12 -> #REF! | AL20: =AL4+AL12 -> #REF! | AM20: =AM4+AM12 -> #REF! | AN20: =AN4+AN12 -> #REF! | AO20: =AO4+AO12 -> #REF! | ... AS20: =AS4+AS12 -> #REF! | AT20: =SUM(AH20:AS20) -> #REF!
E21: a | F21: b | H21: c | J21: d | K21: e=c/a | L21: f=c/b | M21: g=d/c | R21: Kpl.Grk | S21: =S5+S13 -> #REF! | T21: =T5+T13 -> #REF! | U21: =U5+U13 -> #REF! | V21: =V5+V13 -> #REF! | W21: =W5+W13 -> #REF! | X21: =X5+X13 -> #REF! | Y21: =Y5+Y13 -> #REF! | Z21: =Z5+Z13 -> #REF! | ... AD21: =AD5+AD13 -> #REF! | AE21: =SUM(S21:AD21) -> #REF! | AH21: =AH5+AH13 -> #REF! | AI21: =AI5+AI13 -> #REF! | AJ21: =AJ5+AJ13 -> #REF! | AK21: =AK5+AK13 -> #REF! | AL21: =AL5+AL13 -> #REF! | AM21: =AM5+AM13 -> #REF! | AN21: =AN5+AN13 -> #REF! | AO21: =AO5+AO13 -> #REF! | ... AS21: =AS5+AS13 -> #REF! | AT21: =SUM(AH21:AS21) -> #REF!
B22: Derum IKPP | C22: Pandu | D22: Kpl Grk | E22: 5775542903 | F22: 6.0918612e+09 | G22: 5334422376 | H22: ='PANDU IKPP'!$O$76 -> 3.108918e+09 | I22: 5660490824 | J22: ='PANDU IKPP'!$AI$76 -> 3.2307889e+09 | K22: =H22/E22 -> 0.53829018 | L22: =H22/F22 -> 0.5103396 | M22: =J22/H22 -> 1.0392004 | N22: 3079864506 | O22: 3.1722604e+09 | R22: GT.Kpl.Grk | S22: =S6+S14 -> #REF! | T22: =T6+T14 -> #REF! | U22: =U6+U14 -> #REF! | V22: =V6+V14 -> #REF! | W22: =W6+W14 -> #REF! | X22: =X6+X14 -> #REF! | Y22: =Y6+Y14 -> #REF! | Z22: =Z6+Z14 -> #REF! | ... AD22: =AD6+AD14 -> #REF! | AE22: =SUM(S22:AD22) -> #REF! | AH22: =AH6+AH14 -> #REF! | AI22: =AI6+AI14 -> #REF! | AJ22: =AJ6+AJ14 -> #REF! | AK22: =AK6+AK14 -> #REF! | AL22: =AL6+AL14 -> #REF! | AM22: =AM6+AM14 -> #REF! | AN22: =AN6+AN14 -> #REF! | AO22: =AO6+AO14 -> #REF! | ... AS22: =AS6+AS14 -> #REF! | AT22: =SUM(AH22:AS22) -> #REF!
C23: Tunda | D23: GT Kpl Grk | E23: 41905655605 | F23: 4.2072104e+10 | G23: 41271499059 | H23: ='TUNDA IKPP'!Q193 -> 2.1797647e+10 | I23: 43686249040 | J23: ='TUNDA IKPP'!AN193 -> 2.2451534e+10 | K23: =H23/E23 -> 0.52016003 | L23: =H23/F23 -> 0.51810214 | M23: =J23/H23 -> 1.029998 | N23: 21797589609 | O23: 2.2451517e+10 | Q23: TUNDA | R23: Call | S23: =S7+S15 -> #REF! | T23: =T7+T15 -> #REF! | U23: =U7+U15 -> #REF! | V23: =V7+V15 -> #REF! | W23: =W7+W15 -> #REF! | X23: =X7+X15 -> #REF! | Y23: =Y7+Y15 -> #REF! | Z23: =Z7+Z15 -> #REF! | ... AD23: =AD7+AD15 -> #REF! | AE23: =SUM(S23:AD23) -> #REF! | AH23: =AH7+AH15 -> #REF! | AI23: =AI7+AI15 -> #REF! | AJ23: =AJ7+AJ15 -> #REF! | AK23: =AK7+AK15 -> #REF! | AL23: =AL7+AL15 -> #REF! | AM23: =AM7+AM15 -> #REF! | AN23: =AN7+AN15 -> #REF! | AO23: =AO7+AO15 -> #REF! | ... AS23: =AS7+AS15 -> #REF! | AT23: =SUM(AH23:AS23) -> #REF!
C24: Tambat | D24: GT Etmal | H24: ='TAMBAT-IKPP'!Q71 -> 3.5155087e+10 | J24: ='TAMBAT-IKPP'!AJ71 -> 3.6117986e+10 | K24: =H24/E24 -> #DIV/0! | L24: =H24/F24 -> #DIV/0! | M24: =J24/H24 -> 1.02739 | N24: 32406736806 | O24: 3.4578939e+10
B25: Total | E25: =SUM(E22:E24) -> 47681198508 | F25: =SUM(F22:F24) -> 4.8163966e+10 | G25: =SUM(G22:G24) -> 46605921435 | H25: =SUM(H22:H24) -> 6.0061652e+10 | I25: =SUM(I22:I24) -> 49346739864 | J25: =SUM(J22:J24) -> 6.1800308e+10 | K25: =F25/E25 -> 1.0101249 | L25: =H25/F25 -> 1.2470246 | M25: =H25/F25 -> 1.2470246 | N25: =SUM(N22:N24) -> 57284190921 | O25: =SUM(O22:O24) -> 6.0202717e+10 | R25: GT Kpl Jam | S25: =S10+S18 -> #REF! | T25: =T10+T18 -> #REF! | U25: =U10+U18 -> #REF! | V25: =V10+V18 -> #REF! | W25: =W10+W18 -> #REF! | X25: =X10+X18 -> #REF! | Y25: =Y10+Y18 -> #REF! | Z25: =Z10+Z18 -> #REF! | ... AD25: =AD10+AD18 -> #REF! | AE25: =SUM(S25:AD25) -> #REF! | AH25: =AH10+AH18 -> #REF! | AI25: =AI10+AI18 -> #REF! | AJ25: =AJ10+AJ18 -> #REF! | AK25: =AK10+AK18 -> #REF! | AL25: =AL10+AL18 -> #REF! | AM25: =AM10+AM18 -> #REF! | AN25: =AN10+AN18 -> #REF! | AO25: =AO10+AO18 -> #REF! | ... AS25: =AS10+AS18 -> #REF! | AT25: =SUM(AH25:AS25) -> #REF!
B28: Pendapatan Pelayanan Kapal Ciwandan
B29: Area | C29: Layanan | D29: Satuan | E29: Realisasi 2024 | F29: RKAP 2025 | G29: Prog Cabang | H29: PROGNOSA 2026 | I29: RKAP 2026 | J29: RKAP 2027
E30: a | F30: b | H30: c | J30: d | K30: e=c/a | L30: f=c/b | M30: g=d/c
B31: Derum BTN | C31: Pandu | D31: Kpl Grk | E31: 5775542903 | F31: 6.0918612e+09 | G31: 5334422376 | H31: ='PANDU CWD'!$O$76 -> 4.1450588e+09 | I31: 5660490824 | J31: ='PANDU CWD'!$AI$76 -> 5199880926 | K31: =H31/E31 -> 0.71769163 | L31: =H31/F31 -> 0.68042568 | M31: =J31/H31 -> 1.254477 | N31: 3246407572 | O31: 3.3389433e+09 | S31: 3.3389433e+09
C32: Tunda | D32: GT Kpl Grk | E32: 41905655605 | F32: 4.2072104e+10 | G32: 41271499059 | H32: ='TUNDA CWD'!Q193 -> 2.3573621e+10 | I32: 43686249040 | J32: ='TUNDA CWD'!AN193 -> 3.0388832e+10 | K32: =H32/E32 -> 0.56254033 | L32: =H32/F32 -> 0.56031477 | M32: =J32/H32 -> 1.2891033 | N32: 2.5190008e+10 | O32: 2.578175e+10 | S32: 2.578175e+10
C33: Tambat | D33: GT Etmal | H33: ='TAMBAT CWD'!O70 -> 4.2265746e+10 | J33: ='TAMBAT CWD'!AF70 -> 4.5970215e+10 | K33: =H33/E33 -> #DIV/0! | L33: =H33/F33 -> #DIV/0! | M33: =J33/H33 -> 1.0876471 | N33: 42162843914 | O33: 4.5969518e+10 | S33: 4.5969518e+10
B34: Total | E34: =SUM(E31:E33) -> 47681198508 | F34: =SUM(F31:F33) -> 4.8163966e+10 | G34: =SUM(G31:G33) -> 46605921435 | H34: =SUM(H31:H33) -> 6.9984426e+10 | I34: =SUM(I31:I33) -> 49346739864 | J34: =SUM(J31:J33) -> 8.1558928e+10 | K34: =F34/E34 -> 1.0101249 | L34: =H34/F34 -> 1.4530454 | M34: =H34/F34 -> 1.4530454 | N34: =SUM(N31:N33) -> 7.0599259e+10 | O34: =SUM(O31:O33) -> 7.5090211e+10
B37: Pendapatan Pelayanan Kapal Bojonegara
B38: Area | C38: Layanan | D38: Satuan | E38: Realisasi 2024 | F38: RKAP 2025 | G38: Prog Cabang | H38: PROGNOSA 2026 | I38: RKAP 2026 | J38: RKAP 2027
E39: a | F39: b | H39: c | J39: d | K39: e=c/a | L39: f=c/b | M39: g=d/c
B40: Derum BJN | C40: Pandu | D40: Kpl Grk | E40: 5775542903 | F40: 6.0918612e+09 | G40: 5334422376 | H40: ='PANDU CWD'!$O$76 -> 4.1450588e+09 | I40: 5660490824 | J40: ='PANDU IKPP'!$AI$76 -> 3.2307889e+09 | K40: =H40/E40 -> 0.71769163 | L40: =H40/F40 -> 0.68042568 | M40: =J40/H40 -> 0.77943138 | N40: 82537327 | O40: 85977012
C41: Tunda | D41: GT Kpl Grk | E41: 41905655605 | F41: 4.2072104e+10 | G41: 41271499059 | H41: ='TUNDA CWD'!Q202 -> 17604695 | I41: 43686249040 | J41: ='TUNDA CWD'!AN202 -> 20247698 | K41: =H41/E41 -> 0.00042010309 | L41: =H41/F41 -> 0.00041844105 | M41: =J41/H41 -> 1.1501306 | N41: 7.7886407e+08 | O41: 8.1194765e+08
C42: Tambat | D42: GT Etmal | H42: ='TAMBAT CWD'!O79 -> 0 | J42: ='TAMBAT CWD'!AF79 -> 0 | K42: =H42/E42 -> #DIV/0! | L42: =H42/F42 -> #DIV/0! | M42: =J42/H42 -> #DIV/0! | N42: 57034893 | O42: 60770090
B43: Total | E43: =SUM(E40:E42) -> 47681198508 | F43: =SUM(F40:F42) -> 4.8163966e+10 | G43: =SUM(G40:G42) -> 46605921435 | H43: =SUM(H40:H42) -> 4.1626635e+09 | I43: =SUM(I40:I42) -> 49346739864 | J43: =SUM(J40:J42) -> 3.2510366e+09 | K43: =F43/E43 -> 1.0101249 | L43: =H43/F43 -> 0.086426927 | M43: =H43/F43 -> 0.086426927 | N43: =SUM(N40:N42) -> 9.1843629e+08 | O43: =SUM(O40:O42) -> 9.5869475e+08
B46: Pendapatan Pelayanan Kapal PELSUS
...

Sheet TRAFIK
AN1: Produksi Pemanduan 2025 | BE1: Produksi RKAP Pemanduan 2026
A2: No | B2: Uraian | C2: Satuan | D2: Realisasi 2024 | E2: RKAP 2025 | F2: 45658 | G2: 45689 | H2: 45717 | I2: 45748 | J2: 45778 | K2: 45809 | L2: Realisasi sd Juni 25 | M2: 45839 | N2: 45870 | O2: 45901 | P2: 45931 | Q2: 45962 | R2: 45992 | S2: Prognosa 2025 SPJM | T2: Usulan Cab Banten | V2: 46023 | W2: 46054 | X2: 46082 | Y2: 46113 | Z2: 46143 | AA2: 46174 | AB2: 46204 | AC2: 46235 | AD2: 46266 | AE2: 46296 | AF2: 46327 | AG2: 46357 | AH2: RKAP 2026 | AI2: RKAP 2026 SPJM | AJ2: USULAN Cab BTN | AK2: Selisih | AN2: No | AO2: Uraian | AP2: Satuan | AQ2: 45658 | AR2: 45689 | AS2: 45717 | AT2: 45748 | AU2: 45778 | AV2: 45809 | AW2: 45839 | AX2: 45870 | AY2: 45901 | AZ2: 45931 | BA2: 45962 | BB2: 45992 | BC2: Prognosa 2025 | BE2: 46023 | BF2: 46054 | BG2: 46082 | BH2: 46113 | BI2: 46143 | BJ2: 46174 | BK2: 46204 | BL2: 46235 | BM2: 46266 | BN2: 46296 | BO2: 46327 | BP2: 46357 | BQ2: RKAP 2026 | BT2: Area | BU2: Layanan | BV2: Satuan | BW2: Realisasi 2024 | BX2: RKAP 2025 | BY2: Prognosa 2025 | BZ2: RKAP 2026 | CA2: Persentase
A3: 1 | B3: Dermaga Umum | C3: Call | D3: 956 | E3: 956 | F3: =F5+F7 -> 32 | G3: =G5+G7 -> 37 | H3: =H5+H7 -> 159 | I3: =I5+I7 -> 39 | J3: =J5+J7 -> 34 | K3: =K5+K7 -> 37 | L3: =SUM(F3:K3) -> 338 | M3: =M5+M7 -> 35 | N3: =N5+N7 -> 34 | O3: =O5+O7 -> 37 | P3: =P5+P7 -> 43 | Q3: =Q5+Q7 -> 37 | R3: =R5+R7 -> 32 | S3: =SUM(L3:R3) -> 556 | T3: =T5+T7 -> 645 | U3: =S3-T3 -> -89 | V3: =V5+V7 -> 38 | W3: =W5+W7 -> 37 | X3: =X5+X7 -> 177 | Y3: =Y5+Y7 -> 36 | Z3: =Z5+Z7 -> 36 | AA3: =AA5+AA7 -> 33 | AB3: =AB5+AB7 -> 52 | AC3: =AC5+AC7 -> 60 | ... AG3: =AG5+AG7 -> 50 | AH3: =SUM(V3:AG3) -> 680 | AI3: =AI5+AI7 -> 584 | AJ3: =AJ5+AJ7 -> 658 | AK3: =AH3-AJ3 -> 22 | AN3: 1 | AO3: Dermaga Umum | AP3: Grk | AQ3: =AQ5+AQ7 -> 64 | AR3: =AR5+AR7 -> 74 | AS3: =AS5+AS7 -> 318 | AT3: =AT5+AT7 -> 78 | AU3: =AU5+AU7 -> 68 | AV3: =AV5+AV7 -> 74 | AW3: =AW5+AW7 -> 70 | AX3: =AX5+AX7 -> 68 | ... BB3: =BB5+BB7 -> 64 | BC3: =SUM(AQ3:BB3) -> 1112 | BE3: =BE5+BE7 -> 76 | BF3: =BF5+BF7 -> 74 | BG3: =BG5+BG7 -> 354 | BH3: =BH5+BH7 -> 72 | BI3: =BI5+BI7 -> 72 | BJ3: =BJ5+BJ7 -> 66 | BK3: =BK5+BK7 -> 104 | BL3: =BL5+BL7 -> 120 | ... BP3: =BP5+BP7 -> 100 | BQ3: =SUM(BE3:BP3) -> 1360 | BW3: b | BX3: c | BY3: d | BZ3: e | CA3: j=e/d
C4: GT | D4: 6684341 | E4: 6684341 | F4: =F6+F8 -> 263773 | G4: =G6+G8 -> 203390 | H4: =H6+H8 -> 1340528 | I4: =I6+I8 -> 352434.49 | J4: =J6+J8 -> 153376.2 | K4: =K6+K8 -> 331503.44 | L4: =SUM(F4:K4) -> 2645005.1 | M4: =M6+M8 -> 170593.35 | N4: =N6+N8 -> 258839.47 | O4: =O6+O8 -> 185360 | P4: =P6+P8 -> 366087.63 | Q4: =Q6+Q8 -> 172938.65 | R4: =R6+R8 -> 274917.8 | S4: =SUM(L4:R4) -> 4073742 | T4: =T6+T8 -> 4454494 | U4: =S4-T4 -> -380751.96 | V4: =V6+V8 -> 228260 | W4: =W6+W8 -> 164061 | X4: =X6+X8 -> 1393196.2 | Y4: =Y6+Y8 -> 318287 | Z4: =Z6+Z8 -> 126855 | AA4: =AA6+AA8 -> 305794 | AB4: =AB6+AB8 -> 185268 | AC4: =AC6+AC8 -> 285324 | ... AG4: =AG6+AG8 -> 288530 | AH4: =SUM(V4:AG4) -> 4035194.2 | AI4: =AI6+AI8 -> 4277430 | AJ4: =AJ6+AJ8 -> 4543584 | AK4: =AH4-AJ4 -> -508389.77 | AP4: GT Grk | AQ4: =AQ6+AQ8 -> 527546 | AR4: =AR6+AR8 -> 406780 | AS4: =AS6+AS8 -> 2681056 | AT4: =AT6+AT8 -> 704868.97 | AU4: =AU6+AU8 -> 306752.4 | AV4: =AV6+AV8 -> 663006.89 | AW4: =AW6+AW8 -> 341186.7 | AX4: =AX6+AX8 -> 517678.94 | ... BB4: =BB6+BB8 -> 549835.6 | BC4: =SUM(AQ4:BB4) -> 8147484.1 | BE4: =BE6+BE8 -> 456520 | BF4: =BF6+BF8 -> 328122 | BG4: =BG6+BG8 -> 2786392.5 | BH4: =BH6+BH8 -> 636574 | BI4: =BI6+BI8 -> 253710 | BJ4: =BJ6+BJ8 -> 611588 | BK4: =BK6+BK8 -> 370536 | BL4: =BL6+BL8 -> 570648 | ... BP4: =BP6+BP8 -> 577060 | BQ4: =SUM(BE4:BP4) -> 8070388.5 | BT4: Derum | BU4: Pandu | BV4: Kpl Grk | BX4: 6.0918612e+09 | BY4: ='PANDU IKPP'!O76 -> 3.108918e+09 | CA4: =BZ4/BY4 -> 0
B5: Kapal International | C5: Call | D5: 176 | E5: 181 | F5: ='PANDU IKPP'!C89 -> 7 | G5: ='PANDU IKPP'!D89 -> 7 | H5: ='PANDU IKPP'!E89 -> 11 | I5: ='PANDU IKPP'!F89 -> 11 | J5: ='PANDU IKPP'!G89 -> 9 | K5: ='PANDU IKPP'!H89 -> 11 | L5: =SUM(F5:K5) -> 56 | M5: ='PANDU IKPP'!I89 -> 11 | N5: ='PANDU IKPP'!J89 -> 8 | O5: ='PANDU IKPP'!K89 -> 10 | P5: ='PANDU IKPP'!L89 -> 13 | Q5: ='PANDU IKPP'!M89 -> 10 | R5: ='PANDU IKPP'!N89 -> 9 | S5: =SUM(L5:R5) -> 117 | T5: 171 | U5: =S5-T5 -> -54 | V5: ='PANDU IKPP'!W89 -> 14 | W5: ='PANDU IKPP'!X89 -> 11 | X5: ='PANDU IKPP'!Y89 -> 6 | Y5: ='PANDU IKPP'!Z89 -> 8 | Z5: ='PANDU IKPP'!AA89 -> 7 | AA5: ='PANDU IKPP'!AB89 -> 7 | AB5: ='PANDU IKPP'!AC89 -> 11 | AC5: ='PANDU IKPP'!AD89 -> 14 | ... AG5: ='PANDU IKPP'!AH89 -> 11 | AH5: =SUM(V5:AG5) -> 120 | AI5: =ROUNDUP(S5*1.05,) -> 123 | AJ5: 175 | AK5: =AH5-AJ5 -> -55 | AM5: =AH5/S5 -> 1.025641 | AO5: Kapal Internatinal | AP5: Grk | AQ5: ='PANDU IKPP'!C95 -> 14 | AR5: ='PANDU IKPP'!D95 -> 14 | AS5: ='PANDU IKPP'!E95 -> 22 | AT5: ='PANDU IKPP'!F95 -> 22 | AU5: ='PANDU IKPP'!G95 -> 18 | AV5: ='PANDU IKPP'!H95 -> 22 | AW5: ='PANDU IKPP'!I95 -> 22 | AX5: ='PANDU IKPP'!J95 -> 16 | ... BB5: ='PANDU IKPP'!N95 -> 18 | BC5: =SUM(AQ5:BB5) -> 234 | BE5: ='PANDU IKPP'!W95 -> 28 | BF5: ='PANDU IKPP'!X95 -> 22 | BG5: ='PANDU IKPP'!Y95 -> 12 | BH5: ='PANDU IKPP'!Z95 -> 16 | BI5: ='PANDU IKPP'!AA95 -> 14 | BJ5: ='PANDU IKPP'!AB95 -> 14 | BK5: ='PANDU IKPP'!AC95 -> 22 | BL5: ='PANDU IKPP'!AD95 -> 28 | ... BP5: ='PANDU IKPP'!AH95 -> 22 | BQ5: =SUM(BE5:BP5) -> 240 | BU5: Tunda | BV5: GT Kpl Grk | BX5: 4.2072104e+10 | BY5: ='TUNDA IKPP'!Q193 -> 2.1797647e+10 | CA5: =BZ5/BY5 -> 0
C6: GT | D6: 3767313 | E6: 3604494 | F6: ='PANDU IKPP'!C90 -> 178208 | G6: ='PANDU IKPP'!D90 -> 95130 | H6: ='PANDU IKPP'!E90 -> 195082 | I6: ='PANDU IKPP'!F90 -> 260667.29 | J6: ='PANDU IKPP'!G90 -> 61990.5 | K6: ='PANDU IKPP'!H90 -> 225244.44 | L6: =SUM(F6:K6) -> 1016322.2 | M6: ='PANDU IKPP'!I90 -> 88988.25 | N6: ='PANDU IKPP'!J90 -> 163603.22 | O6: ='PANDU IKPP'!K90 -> 79456 | P6: ='PANDU IKPP'!L90 -> 267885.33 | Q6: ='PANDU IKPP'!M90 -> 71522.75 | R6: ='PANDU IKPP'!N90 -> 184923.67 | S6: =SUM(L6:R6) -> 1872701.5 | T6: 3386829 | U6: =S6-T6 -> -1514127.5 | V6: ='PANDU IKPP'!W90 -> 182605 | W6: ='PANDU IKPP'!X90 -> 95130 | X6: ='PANDU IKPP'!Y90 -> 195082 | Y6: ='PANDU IKPP'!Z90 -> 260668 | Z6: ='PANDU IKPP'!AA90 -> 61991 | AA6: ='PANDU IKPP'!AB90 -> 225246 | AB6: ='PANDU IKPP'!AC90 -> 88989 | AC6: ='PANDU IKPP'!AD90 -> 163604 | ... AG6: ='PANDU IKPP'!AH90 -> 184924 | AH6: =SUM(V6:AG6) -> 1877104 | AI6: =ROUNDUP(S6*1.05,) -> 1966337 | AJ6: 3454566 | AK6: =AH6-AJ6 -> -1577462 | AM6: =AH6/S6 -> 1.0023509 | AP6: GT Grk | AQ6: ='PANDU IKPP'!C96 -> 356416 | AR6: ='PANDU IKPP'!D96 -> 190260 | AS6: ='PANDU IKPP'!E96 -> 390164 | AT6: ='PANDU IKPP'!F96 -> 521334.57 | AU6: ='PANDU IKPP'!G96 -> 123981 | AV6: ='PANDU IKPP'!H96 -> 450488.89 | AW6: ='PANDU IKPP'!I96 -> 177976.5 | AX6: ='PANDU IKPP'!J96 -> 327206.44 | ... BB6: ='PANDU IKPP'!N96 -> 369847.33 | BC6: =SUM(AQ6:BB6) -> 3745402.9 | BE6: ='PANDU IKPP'!W96 -> 365210 | BF6: ='PANDU IKPP'!X96 -> 190260 | BG6: ='PANDU IKPP'!Y96 -> 390164 | BH6: ='PANDU IKPP'!Z96 -> 521336 | BI6: ='PANDU IKPP'!AA96 -> 123982 | BJ6: ='PANDU IKPP'!AB96 -> 450492 | BK6: ='PANDU IKPP'!AC96 -> 177978 | BL6: ='PANDU IKPP'!AD96 -> 327208 | ... BP6: ='PANDU IKPP'!AH96 -> 369848 | BQ6: =SUM(BE6:BP6) -> 3754208 | BT6: Pelsus | BU6: Pandu | BV6: Kpl Grk | BX6: 2.2944131e+10 | BY6: =#REF! -> #REF! | CA6: =BZ6/BY6 -> #REF!
B7: Kapal Domestik | C7: Call | D7: 691 | E7: 775 | F7: ='PANDU IKPP'!C91 -> 25 | G7: ='PANDU IKPP'!D91 -> 30 | H7: ='PANDU IKPP'!E91 -> 148 | I7: ='PANDU IKPP'!F91 -> 28 | J7: ='PANDU IKPP'!G91 -> 25 | K7: ='PANDU IKPP'!H91 -> 26 | L7: =SUM(F7:K7) -> 282 | M7: ='PANDU IKPP'!I91 -> 24 | N7: ='PANDU IKPP'!J91 -> 26 | O7: ='PANDU IKPP'!K91 -> 27 | P7: ='PANDU IKPP'!L91 -> 30 | Q7: ='PANDU IKPP'!M91 -> 27 | R7: ='PANDU IKPP'!N91 -> 23 | S7: =SUM(L7:R7) -> 439 | T7: 474 | U7: =S7-T7 -> -35 | V7: ='PANDU IKPP'!W91 -> 24 | W7: ='PANDU IKPP'!X91 -> 26 | X7: ='PANDU IKPP'!Y91 -> 171 | Y7: ='PANDU IKPP'!Z91 -> 28 | Z7: ='PANDU IKPP'!AA91 -> 29 | AA7: ='PANDU IKPP'!AB91 -> 26 | AB7: ='PANDU IKPP'!AC91 -> 41 | AC7: ='PANDU IKPP'!AD91 -> 46 | ... AG7: ='PANDU IKPP'!AH91 -> 39 | AH7: =SUM(V7:AG7) -> 560 | AI7: =ROUNDUP(S7*1.05,) -> 461 | AJ7: 483 | AK7: =AH7-AJ7 -> 77 | AM7: =AH7/S7 -> 1.2756264 | AO7: Kapal Domestik | AP7: Grk | AQ7: ='PANDU IKPP'!C97 -> 50 | AR7: ='PANDU IKPP'!D97 -> 60 | AS7: ='PANDU IKPP'!E97 -> 296 | AT7: ='PANDU IKPP'!F97 -> 56 | AU7: ='PANDU IKPP'!G97 -> 50 | AV7: ='PANDU IKPP'!H97 -> 52 | AW7: ='PANDU IKPP'!I97 -> 48 | AX7: ='PANDU IKPP'!J97 -> 52 | ... BB7: ='PANDU IKPP'!N97 -> 46 | BC7: =SUM(AQ7:BB7) -> 878 | BE7: ='PANDU IKPP'!W97 -> 48 | BF7: ='PANDU IKPP'!X97 -> 52 | BG7: ='PANDU IKPP'!Y97 -> 342 | BH7: ='PANDU IKPP'!Z97 -> 56 | BI7: ='PANDU IKPP'!AA97 -> 58 | BJ7: ='PANDU IKPP'!AB97 -> 52 | BK7: ='PANDU IKPP'!AC97 -> 82 | BL7: ='PANDU IKPP'!AD97 -> 92 | ... BP7: ='PANDU IKPP'!AH97 -> 78 | BQ7: =SUM(BE7:BP7) -> 1120 | BU7: Tunda | BV7: GT Kpl Grk | BX7: 1.4604073e+11 | BY7: =#REF! -> #REF! | CA7: =BZ7/BY7 -> #REF!
C8: GT | D8: 2531383 | E8: 3079847 | F8: ='PANDU IKPP'!C92 -> 85565 | G8: ='PANDU IKPP'!D92 -> 108260 | H8: ='PANDU IKPP'!E92 -> 1145446 | I8: ='PANDU IKPP'!F92 -> 91767.2 | J8: ='PANDU IKPP'!G92 -> 91385.7 | K8: ='PANDU IKPP'!H92 -> 106259 | L8: =SUM(F8:K8) -> 1628682.9 | M8: ='PANDU IKPP'!I92 -> 81605.1 | N8: ='PANDU IKPP'!J92 -> 95236.25 | O8: ='PANDU IKPP'!K92 -> 105904 | P8: ='PANDU IKPP'!L92 -> 98202.3 | Q8: ='PANDU IKPP'!M92 -> 101415.9 | R8: ='PANDU IKPP'!N92 -> 89994.133 | S8: =SUM(L8:R8) -> 2201040.6 | T8: 1067665 | U8: =S8-T8 -> 1133375.6 | V8: ='PANDU IKPP'!W92 -> 45655 | W8: ='PANDU IKPP'!X92 -> 68931 | X8: ='PANDU IKPP'!Y92 -> 1198114.2 | Y8: ='PANDU IKPP'!Z92 -> 57619 | Z8: ='PANDU IKPP'!AA92 -> 64864 | AA8: ='PANDU IKPP'!AB92 -> 80548 | AB8: ='PANDU IKPP'!AC92 -> 96279 | AC8: ='PANDU IKPP'!AD92 -> 121720 | ... AG8: ='PANDU IKPP'!AH92 -> 103606 | AH8: =SUM(V8:AG8) -> 2158090.2 | AI8: =ROUNDUP(S8*1.05,) -> 2311093 | AJ8: 1089018 | AK8: =AH8-AJ8 -> 1069072.2 | AM8: =AH8/S8 -> 0.98048634 | AP8: GT Grk | AQ8: ='PANDU IKPP'!C98 -> 171130 | AR8: ='PANDU IKPP'!D98 -> 216520 | AS8: ='PANDU IKPP'!E98 -> 2290892 | AT8: ='PANDU IKPP'!F98 -> 183534.4 | AU8: ='PANDU IKPP'!G98 -> 182771.4 | AV8: ='PANDU IKPP'!H98 -> 212518 | AW8: ='PANDU IKPP'!I98 -> 163210.2 | AX8: ='PANDU IKPP'!J98 -> 190472.5 | ... BB8: ='PANDU IKPP'!N98 -> 179988.27 | BC8: =SUM(AQ8:BB8) -> 4402081.2 | BE8: ='PANDU IKPP'!W98 -> 91310 | BF8: ='PANDU IKPP'!X98 -> 137862 | BG8: ='PANDU IKPP'!Y98 -> 2396228.5 | BH8: ='PANDU IKPP'!Z98 -> 115238 | BI8: ='PANDU IKPP'!AA98 -> 129728 | BJ8: ='PANDU IKPP'!AB98 -> 161096 | BK8: ='PANDU IKPP'!AC98 -> 192558 | BL8: ='PANDU IKPP'!AD98 -> 243440 | ... BP8: ='PANDU IKPP'!AH98 -> 207212 | BQ8: =SUM(BE8:BP8) -> 4316180.5 | BT8: Total | BW8: =SUM(BW4:BW7) -> 0 | BX8: =SUM(BX4:BX7) -> 2.1714883e+11 | BY8: =SUM(BY4:BY7) -> #REF! | BZ8: =SUM(BZ4:BZ7) -> 0 | CA8: =BZ8/BY8 -> #REF!
